<sdf version='1.6'>
  <model name='new_platform'>
    <link name='body'>
    <pose frame=''>0 0 0 0 -0 0</pose>
      <inertial>
        <pose frame=''>0 0 0 0 -0 0</pose>
        <mass>9.294</mass>
        <inertia>
          <ixx>0.3008</ixx>
          <ixy>0.1001</ixy>
          <ixz>-0.2040</ixz>
          <iyy>1.192</iyy>
          <iyz>-0.0603</iyz>
          <izz>0.1011</izz>
        </inertia>
      </inertial>
      <collision name='body_collision'>
        <pose frame=''>0 0 0 0 -0 0</pose>
        <geometry>
          <box>
            <size>0.3563 0.2627 0.1279</size>
          </box>
        </geometry>
        <surface>
          <contact>
            <ode />
          </contact>
          <friction>
            <ode />
          </friction>
        </surface>
      </collision>
      <visual name='body_visual'>
        <pose frame=''>0 0 0 0 -0 0</pose>
        <geometry>
          <box>
            <size>0.3563 0.2627 0.1279</size>
          </box>
           <!-- <mesh>
            <uri>model:///meshes/body.STL</uri>
          </mesh> -->
        </geometry>
        <material>
          <script>
            <name>Gazebo/DarkGrey</name>
            <uri>file://media/materials/scripts/gazebo.material</uri>
          </script>
        </material>
      </visual>
      <gravity>1</gravity>
      <velocity_decay />
    </link>

    <link name='hip0'>
      <!-- <pose relative_to='8'>0 0 0 0 -0 0</pose> -->
      <pose frame=''>0.2263 0.07 0 0 -0 0</pose> <!-- values from spirit -->
      <inertial>
        <pose frame=''>0 0 0 0 -0 0</pose>
        <mass>0.3876</mass>
        <inertia>
          <ixx>0.002176</ixx>
          <ixy>-0.002038</ixy>
          <ixz>0.0004151</ixz>
          <iyy>0.003055</iyy>
          <iyz>-0.0003603</iyz>
          <izz>0.004689</izz>
        </inertia>
      </inertial>
      <collision name='hip0_collision'>
        <pose frame=''>0 0.028 0 1.5708 -0 0</pose>
        <geometry>
          <cylinder>
            <length>0.08</length>
            <radius>0.055</radius>
          </cylinder>
        </geometry>
        <surface>
          <contact>
            <ode />
          </contact>
          <friction>
            <ode />
          </friction>
        </surface>
      </collision>
      <visual name='hip0_visual'>
        <pose frame=''>0 0.028 0 1.5708 -0 0</pose>
        <geometry>
          <cylinder>
            <length>0.08</length>
            <radius>0.055</radius>
          </cylinder>
          <!-- <mesh>
            <uri>model:///meshes/hip.STL</uri>
          </mesh> -->
        </geometry>
        <material>
          <script>
            <name>Gazebo/DarkGrey</name>
            <uri>file://media/materials/scripts/gazebo.material</uri>
          </script>
        </material>
      </visual>
      <gravity>1</gravity>
      <velocity_decay />
    </link>

    <joint name='8' type='revolute'>
      <!-- <pose relative_to='body'>0.2263 0.07 0 0 -0 0</pose> -->
      <child>hip0</child>
      <parent>body</parent>
      <axis>
        <xyz>1 0 0</xyz>
        <limit>
          <lower>-0.707</lower>
          <upper>0.707</upper>
          <effort>40</effort>
          <velocity>30</velocity>
        </limit>
        <dynamics>
          <damping>0</damping>
          <friction>0</friction>
          <spring_reference>0</spring_reference>
          <spring_stiffness>0</spring_stiffness>
        </dynamics>
        <use_parent_model_frame>1</use_parent_model_frame>
      </axis>
    </joint>

    <link name='upper0'>
      <!-- <pose relative_to='0'>0 0 0 0 -0 0</pose> -->
      <pose frame=''>0.2263 0.17098 0 0 -0 0</pose>  <!-- values from spirit -->
      <inertial>
        <pose frame=''>0 0 0 0 -0 0</pose>
        <mass>0.706</mass>
        <inertia>
          <ixx>0.0026851</ixx>
          <ixy>-6.2823e-05</ixy>
          <ixz>-0.0022535</ixz>
          <iyy>0.010059</iyy>
          <iyz>-8.5258e-05</iyz>
          <izz>0.0076466</izz>
        </inertia>
      </inertial>
      <collision name='upper0_collision'>
        <pose frame=''>-0.103 -0.022 0 0 -0 0</pose>
        <geometry>
          <box>
            <size>0.206 0.022 0.055</size>
          </box>
        </geometry>
        <surface>
          <contact>
            <ode />
          </contact>
          <friction>
            <ode />
          </friction>
        </surface>
      </collision>
      <visual name='upper0_visual'>
        <pose frame=''>-0.103 -0.022 0 0 -0 0</pose>
        <geometry>
          <box>
            <size>0.206 0.022 0.055</size>
          </box>
          <!-- <mesh>
            <uri>model:///meshes/upper.STL</uri>
          </mesh> -->
        </geometry>
        <material>
          <script>
            <name>Gazebo/DarkGrey</name>
            <uri>file://media/materials/scripts/gazebo.material</uri>
          </script>
        </material>
      </visual>
      <gravity>1</gravity>
      <velocity_decay />
    </link>

    <joint name='0' type='revolute'>
      <!-- <pose relative_to='hip0'>0 0.10098 0 0 -0 0</pose> -->
      <child>upper0</child>
      <parent>hip0</parent>
      <axis>
        <xyz>0 -1 0</xyz>
        <limit>
          <lower>-6.28319</lower>
          <upper>6.28319</upper>
          <effort>40</effort>
          <velocity>30</velocity>
        </limit>
        <dynamics>
          <damping>0</damping>
          <friction>0</friction>
          <spring_reference>0</spring_reference>
          <spring_stiffness>0</spring_stiffness>
        </dynamics>
        <use_parent_model_frame>1</use_parent_model_frame>
      </axis>
    </joint>

    <link name='lower0'>
      <!-- <pose relative_to='1'>0 0 0 0 -0 0</pose> -->
      <pose frame=''>0.0203 0.17098 0 0 -0 0</pose>  <!-- values from spirit -->
      <inertial>
        <pose frame=''>0.002894 0 0 0 -0 0</pose>
        <mass>0.263</mass>
        <inertia>
          <ixx>0.00096398</ixx>
          <ixy>-3.788e-05</ixy>
          <ixz>1.0791e-05</ixz>
          <iyy>0.00107276</iyy>
          <iyz>0.00017591</iyz>
          <izz>0.00120673</izz>
        </inertia>
      </inertial>
      <collision name='lower0_collision'>
        <pose frame=''>0.103 0 0 0 1.5708 0</pose>
        <geometry>
          <cylinder>
            <length>0.206</length>
            <radius>0.013</radius>
          </cylinder>
        </geometry>
        <surface>
          <contact>
            <ode />
          </contact>
          <friction>
            <ode />
          </friction>
        </surface>
      </collision>
      <visual name='lower0_visual'>
        <pose frame=''>0.103 0 0 0 1.5708 0</pose>
        <geometry>
          <cylinder>
            <length>0.206</length>
            <radius>0.013</radius>
          </cylinder>
          <!-- <mesh>
            <uri>model:///meshes/lower.STL</uri>
          </mesh> -->
        </geometry>
        <material>
          <script>
            <name>Gazebo/DarkGrey</name>
            <uri>file://media/materials/scripts/gazebo.material</uri>
          </script>
        </material>
      </visual>
      <velocity_decay />
      <gravity>1</gravity>
      <velocity_decay />
    </link>

    <joint name='1' type='revolute'>
      <!-- <pose relative_to='upper0'>-0.206 0 0 0 -0 0</pose> -->
      <child>lower0</child>
      <parent>upper0</parent>
      <axis>
        <xyz>0 1 0</xyz>
        <limit>
          <lower>0</lower>
          <upper>3.14159</upper>
          <effort>40</effort>
          <velocity>30</velocity>
        </limit>
        <dynamics>
          <damping>0</damping>
          <friction>0</friction>
          <spring_reference>0</spring_reference>
          <spring_stiffness>0</spring_stiffness>
        </dynamics>
        <use_parent_model_frame>1</use_parent_model_frame>
      </axis>
    </joint>

    <link name='hip1'>
      <!-- <pose relative_to='9'>0 0 0 0 -0 0</pose> -->
      <pose frame=''>-0.2263 0.07 0 0 -0 0</pose>  <!-- values from spirit -->
      <inertial>
        <pose frame=''>0 0 0 0 -0 0</pose>
        <mass>0.3876</mass>
        <inertia>
          <ixx>0.002176</ixx>
          <ixy>-0.002038</ixy>
          <ixz>0.0004151</ixz>
          <iyy>0.003055</iyy>
          <iyz>-0.0003603</iyz>
          <izz>0.004689</izz>
        </inertia>
      </inertial>
      <collision name='hip1_collision'>
        <pose frame=''>0 0.028 0 1.5708 -0 0</pose>
        <geometry>
          <cylinder>
            <length>0.08</length>
            <radius>0.055</radius>
          </cylinder>
        </geometry>
        <surface>
          <contact>
            <ode />
          </contact>
          <friction>
            <ode />
          </friction>
        </surface>
      </collision>
      <visual name='hip1_visual'>
        <pose frame=''>0 0.028 0 1.5708 -0 0</pose>
        <geometry>
          <cylinder>
            <length>0.08</length>
            <radius>0.055</radius>
          </cylinder>
          <!-- <mesh>
            <uri>model:///meshes/hip.STL</uri>
          </mesh> -->
        </geometry>
        <material>
          <script>
            <name>Gazebo/DarkGrey</name>
            <uri>file://media/materials/scripts/gazebo.material</uri>
          </script>
        </material>
      </visual>
      <gravity>1</gravity>
      <velocity_decay />
    </link>

    <joint name='9' type='revolute'>
      <!-- <pose relative_to='body'>-0.2263 0.07 0 0 -0 0</pose> -->
      <child>hip1</child>
      <parent>body</parent>
      <axis>
        <xyz>1 0 0</xyz>
        <limit>
          <lower>-0.707</lower>
          <upper>0.707</upper>
          <effort>40</effort>
          <velocity>30</velocity>
        </limit>
        <dynamics>
          <damping>0</damping>
          <friction>0</friction>
          <spring_reference>0</spring_reference>
          <spring_stiffness>0</spring_stiffness>
        </dynamics>
        <use_parent_model_frame>1</use_parent_model_frame>
      </axis>
    </joint>

    <link name='upper1'>
      <!-- <pose relative_to='2'>0 0 0 0 -0 0</pose> -->
      <pose frame=''>-0.2263 0.17098 0 0 -0 0</pose>
      <inertial>
        <pose frame=''>0 0 0 0 -0 0</pose>
        <mass>0.706</mass>
        <inertia>
          <ixx>0.0026851</ixx>
          <ixy>-6.2823e-05</ixy>
          <ixz>-0.0022535</ixz>
          <iyy>0.010059</iyy>
          <iyz>-8.5258e-05</iyz>
          <izz>0.0076466</izz>
        </inertia>
      </inertial>
      <collision name='upper1_collision'>
        <pose frame=''>-0.103 -0.022 0 0 -0 0</pose>
        <geometry>
          <box>
            <size>0.206 0.022 0.055</size>
          </box>
        </geometry>
        <surface>
          <contact>
            <ode />
          </contact>
          <friction>
            <ode />
          </friction>
        </surface>
      </collision>
      <visual name='upper1_visual'>
        <pose frame=''>-0.103 -0.022 0 0 -0 0</pose>
        <geometry>
          <box>
            <size>0.206 0.022 0.055</size>
          </box>
          <!-- <mesh>
            <uri>model:///meshes/upper.STL</uri>
          </mesh> -->
        </geometry>
        <material>
          <script>
            <name>Gazebo/DarkGrey</name>
            <uri>file://media/materials/scripts/gazebo.material</uri>
          </script>
        </material>
      </visual>
      <gravity>1</gravity>
      <velocity_decay />
    </link>

    <joint name='2' type='revolute'>
      <!-- <pose relative_to='hip1'>0 0.10098 0 0 -0 0</pose> -->
      <child>upper1</child>
      <parent>hip1</parent>
      <axis>
        <xyz>0 -1 0</xyz>
        <limit>
          <lower>-6.28319</lower>
          <upper>6.28319</upper>
          <effort>40</effort>
          <velocity>30</velocity>
        </limit>
        <dynamics>
          <damping>0</damping>
          <friction>0</friction>
          <spring_reference>0</spring_reference>
          <spring_stiffness>0</spring_stiffness>
        </dynamics>
        <use_parent_model_frame>1</use_parent_model_frame>
      </axis>
    </joint>

    <link name='lower1'>
      <!-- <pose relative_to='3'>0 0 0 0 -0 0</pose> -->
      <pose frame=''>-0.4323 0.17098 0 0 -0 0</pose>  <!-- values from spirit -->
      <inertial>
        <pose frame=''>0.002894 0 0 0 -0 0</pose>
        <mass>0.263</mass>
        <inertia>
          <ixx>0.00096398</ixx>
          <ixy>-3.788e-05</ixy>
          <ixz>1.0791e-05</ixz>
          <iyy>0.00107276</iyy>
          <iyz>0.00017591</iyz>
          <izz>0.00120673</izz>
        </inertia>
      </inertial>
      <collision name='lower1_collision'>
        <pose frame=''>0.103 0 0 0 1.5708 0</pose>
        <geometry>
          <cylinder>
            <length>0.206</length>
            <radius>0.013</radius>
          </cylinder>
        </geometry>
        <surface>
          <contact>
            <ode />
          </contact>
          <friction>
            <ode />
          </friction>
        </surface>
      </collision>
      <visual name='lower1_visual'>
        <pose frame=''>0.103 0 0 0 1.5708 0</pose>
        <geometry>
          <cylinder>
            <length>0.206</length>
            <radius>0.013</radius>
          </cylinder>
          <!-- <mesh>
            <uri>model:///meshes/lower.STL</uri>
          </mesh> -->
        </geometry>
        <material>
          <script>
            <name>Gazebo/DarkGrey</name>
            <uri>file://media/materials/scripts/gazebo.material</uri>
          </script>
        </material>
      </visual>
      <velocity_decay />
      <gravity>1</gravity>
      <velocity_decay />
    </link>

    <joint name='3' type='revolute'>
      <!-- <pose relative_to='upper1'>-0.206 0 0 0 -0 0</pose> -->
      <child>lower1</child>
      <parent>upper1</parent>
      <axis>
        <xyz>0 1 0</xyz>
        <limit>
          <lower>0</lower>
          <upper>3.14159</upper>
          <effort>40</effort>
          <velocity>30</velocity>
        </limit>
        <dynamics>
          <damping>0</damping>
          <friction>0</friction>
          <spring_reference>0</spring_reference>
          <spring_stiffness>0</spring_stiffness>
        </dynamics>
        <use_parent_model_frame>1</use_parent_model_frame>
      </axis>
    </joint>
    <static>0</static>

    <link name='hip2'>
      <!-- <pose relative_to='10'>0 0 0 0 -0 0</pose> -->
      <pose frame=''>0.2263 -0.07 0 0 -0 0</pose>  <!-- values from spirit -->
      <inertial>
        <pose frame=''>0 0 0 0 -0 0</pose>
        <mass>0.3876</mass>
        <inertia>
          <ixx>0.002176</ixx>
          <ixy>-0.002038</ixy>
          <ixz>0.0004151</ixz>
          <iyy>0.003055</iyy>
          <iyz>-0.0003603</iyz>
          <izz>0.004689</izz>
        </inertia>
      </inertial>
      <collision name='hip2_collision'>
        <pose frame=''>0 -0.028 0 1.5708 -0 0</pose>
        <geometry>
          <cylinder>
            <length>0.08</length>
            <radius>0.055</radius>
          </cylinder>
        </geometry>
        <surface>
          <contact>
            <ode />
          </contact>
          <friction>
            <ode />
          </friction>
        </surface>
      </collision>
      <visual name='hip2_visual'>
        <pose frame=''>0 -0.028 0 1.5708 -0 0</pose>
        <geometry>
          <cylinder>
            <length>0.08</length>
            <radius>0.055</radius>
          </cylinder>
          <!-- <mesh>
            <uri>model:///meshes/hip.STL</uri>
          </mesh> -->
        </geometry>
        <material>
          <script>
            <name>Gazebo/DarkGrey</name>
            <uri>file://media/materials/scripts/gazebo.material</uri>
          </script>
        </material>
      </visual>
      <gravity>1</gravity>
      <velocity_decay />
    </link>

    <joint name='10' type='revolute'>
      <!-- <pose relative_to='body'>0.2263 -0.07 0 0 -0 0</pose> -->
      <child>hip2</child>
      <parent>body</parent>
      <axis>
        <xyz>1 0 0</xyz>
        <limit>
          <lower>-0.707</lower>
          <upper>0.707</upper>
          <effort>40</effort>
          <velocity>30</velocity>
        </limit>
        <dynamics>
          <damping>0</damping>
          <friction>0</friction>
          <spring_reference>0</spring_reference>
          <spring_stiffness>0</spring_stiffness>
        </dynamics>
        <use_parent_model_frame>1</use_parent_model_frame>
      </axis>
    </joint>

    <link name='upper2'>
      <!-- <pose relative_to='4'>0 0 0 0 -0 0</pose> -->
      <pose frame=''>0.2263 -0.17098 0 0 -0 0</pose>
      <inertial>
        <pose frame=''>0 0 0 0 -0 0</pose>
        <mass>0.706</mass>
        <inertia>
          <ixx>0.0026851</ixx>
          <ixy>-6.2823e-05</ixy>
          <ixz>-0.0022535</ixz>
          <iyy>0.010059</iyy>
          <iyz>-8.5258e-05</iyz>
          <izz>0.0076466</izz>
        </inertia>
      </inertial>
      <collision name='upper2_collision'>
        <pose frame=''>-0.103 0.022 0 0 -0 0</pose>
        <geometry>
          <box>
            <size>0.206 0.022 0.055</size>
          </box>
        </geometry>
        <surface>
          <contact>
            <ode />
          </contact>
          <friction>
            <ode />
          </friction>
        </surface>
      </collision>
      <visual name='upper2_visual'>
        <pose frame=''>-0.103 0.022 0 0 -0 0</pose>
        <geometry>
          <box>
            <size>0.206 0.022 0.055</size>
          </box>
          <!-- <mesh>
            <uri>model:///meshes/upper.STL</uri>
          </mesh> -->
        </geometry>
        <material>
          <script>
            <name>Gazebo/DarkGrey</name>
            <uri>file://media/materials/scripts/gazebo.material</uri>
          </script>
        </material>
      </visual>
      <gravity>1</gravity>
      <velocity_decay />
    </link>
    
    <joint name='4' type='revolute'>
      <!-- <pose relative_to='hip2'>0 -0.10098 0 0 -0 0</pose> -->
      <child>upper2</child>
      <parent>hip2</parent>
      <axis>
        <xyz>0 -1 0</xyz>
        <limit>
          <lower>-6.28319</lower>
          <upper>6.28319</upper>
          <effort>40</effort>
          <velocity>30</velocity>
        </limit>
        <dynamics>
          <damping>0</damping>
          <friction>0</friction>
          <spring_reference>0</spring_reference>
          <spring_stiffness>0</spring_stiffness>
        </dynamics>
        <use_parent_model_frame>1</use_parent_model_frame>
      </axis>
    </joint>

    <link name='lower2'>
      <!-- <pose relative_to='5'>0 0 0 0 -0 0</pose> -->
      <pose frame=''>0.0203 -0.17098 0 0 -0 0</pose>  <!-- values from spirit -->
      <inertial>
        <pose frame=''>0.002894 0 0 0 -0 0</pose>
        <mass>0.263</mass>
        <inertia>
          <ixx>0.00096398</ixx>
          <ixy>-3.788e-05</ixy>
          <ixz>1.0791e-05</ixz>
          <iyy>0.00107276</iyy>
          <iyz>0.00017591</iyz>
          <izz>0.00120673</izz>
        </inertia>
      </inertial>
      <collision name='lower2_collision'>
        <pose frame=''>0.103 0 0 0 1.5708 0</pose>
        <geometry>
          <cylinder>
            <length>0.206</length>
            <radius>0.013</radius>
          </cylinder>
        </geometry>
        <surface>
          <contact>
            <ode />
          </contact>
          <friction>
            <ode />
          </friction>
        </surface>
      </collision>
      <visual name='lower2_visual'>
        <pose frame=''>0.103 0 0 0 1.5708 0</pose>
        <geometry>
          <cylinder>
            <length>0.206</length>
            <radius>0.013</radius>
          </cylinder>
          <!-- <mesh>
            <uri>model:///meshes/lower.STL</uri>
          </mesh> -->
        </geometry>
        <material>
          <script>
            <name>Gazebo/DarkGrey</name>
            <uri>file://media/materials/scripts/gazebo.material</uri>
          </script>
        </material>
      </visual>
      <velocity_decay />
      <gravity>1</gravity>
      <velocity_decay />
    </link>

    <joint name='5' type='revolute'>
      <!-- <pose relative_to='upper2'>-0.206 0 0 0 -0 0</pose> -->
      <child>lower2</child>
      <parent>upper2</parent>
      <axis>
        <xyz>0 1 0</xyz>
        <limit>
          <lower>0</lower>
          <upper>3.14159</upper>
          <effort>40</effort>
          <velocity>30</velocity>
        </limit>
        <dynamics>
          <damping>0</damping>
          <friction>0</friction>
          <spring_reference>0</spring_reference>
          <spring_stiffness>0</spring_stiffness>
        </dynamics>
        <use_parent_model_frame>1</use_parent_model_frame>
      </axis>
    </joint>

    <link name='hip3'>
      <!-- <pose relative_to='11'>0 0 0 0 -0 0</pose> -->
      <pose frame=''>-0.2263 -0.07 0 0 -0 0</pose>  <!-- values from spirit -->
      <inertial>
        <pose>0 0 0 0 -0 0</pose>
        <mass>0.3876</mass>
        <inertia>
          <ixx>0.002176</ixx>
          <ixy>-0.002038</ixy>
          <ixz>0.0004151</ixz>
          <iyy>0.003055</iyy>
          <iyz>-0.0003603</iyz>
          <izz>0.004689</izz>
        </inertia>
      </inertial>
      <collision name='hip3_collision'>
        <pose frame=''>0 -0.028 0 1.5708 -0 0</pose>
        <geometry>
          <cylinder>
            <length>0.08</length>
            <radius>0.055</radius>
          </cylinder>
        </geometry>
        <surface>
          <contact>
            <ode />
          </contact>
          <friction>
            <ode />
          </friction>
        </surface>
      </collision>
      <visual name='hip3_visual'>
        <pose frame=''>0 -0.028 0 1.5708 -0 0</pose>
        <geometry>
          <cylinder>
            <length>0.08</length>
            <radius>0.055</radius>
          </cylinder>
          <!-- <mesh>
            <uri>model:///meshes/hip.STL</uri>
          </mesh> -->
        </geometry>
        <material>
          <script>
            <name>Gazebo/DarkGrey</name>
            <uri>file://media/materials/scripts/gazebo.material</uri>
          </script>
        </material>
      </visual>
      <gravity>1</gravity>
      <velocity_decay />
    </link>

    <joint name='11' type='revolute'>
      <!-- <pose relative_to='body'>-0.2263 -0.07 0 0 -0 0</pose> -->
      <child>hip3</child>
      <parent>body</parent>
      <axis>
        <xyz>1 0 0</xyz>
        <limit>
          <lower>-0.707</lower>
          <upper>0.707</upper>
          <effort>40</effort>
          <velocity>30</velocity>
        </limit>
        <dynamics>
          <damping>0</damping>
          <friction>0</friction>
          <spring_reference>0</spring_reference>
          <spring_stiffness>0</spring_stiffness>
        </dynamics>
        <use_parent_model_frame>1</use_parent_model_frame>
      </axis>
    </joint>

    <link name='upper3'>
      <!-- <pose relative_to='6'>0 0 0 0 -0 0</pose> -->
      <pose frame=''>-0.2263 -0.17098 0 0 -0 0</pose>  <!-- values from spirit -->
      <inertial>
        <pose frame=''>0 0 0 0 -0 0</pose>
        <mass>0.706</mass>
        <inertia>
          <ixx>0.0026851</ixx>
          <ixy>-6.2823e-05</ixy>
          <ixz>-0.0022535</ixz>
          <iyy>0.010059</iyy>
          <iyz>-8.5258e-05</iyz>
          <izz>0.0076466</izz>
        </inertia>
      </inertial>
      <collision name='upper3_collision'>
        <pose frame=''>-0.103 0.022 0 0 -0 0</pose>
        <geometry>
          <box>
            <size>0.206 0.022 0.055</size>
          </box>
        </geometry>
        <surface>
          <contact>
            <ode />
          </contact>
          <friction>
            <ode />
          </friction>
        </surface>
      </collision>
      <visual name='upper3_visual'>
        <pose frame=''>-0.103 0.022 0 0 -0 0</pose>
        <geometry>
          <box>
            <size>0.206 0.022 0.055</size>
          </box>
          <!-- <mesh>
            <uri>model:///meshes/upper.STL</uri>
          </mesh> -->
        </geometry>
        <material>
          <script>
            <name>Gazebo/DarkGrey</name>
            <uri>file://media/materials/scripts/gazebo.material</uri>
          </script>
        </material>
      </visual>
      <gravity>1</gravity>
      <velocity_decay />
    </link>
    
    <joint name='6' type='revolute'>
      <!-- <pose relative_to='hip3'>0 -0.10098 0 0 -0 0</pose> -->
      <child>upper3</child>
      <parent>hip3</parent>
      <axis>
        <xyz>0 -1 0</xyz>
        <limit>
          <lower>-6.28319</lower>
          <upper>6.28319</upper>
          <effort>40</effort>
          <velocity>30</velocity>
        </limit>
        <dynamics>
          <damping>0</damping>
          <friction>0</friction>
          <spring_reference>0</spring_reference>
          <spring_stiffness>0</spring_stiffness>
        </dynamics>
        <use_parent_model_frame>1</use_parent_model_frame>
      </axis>
    </joint>
    
    <link name='lower3'>
      <!-- <pose relative_to='7'>0 0 0 0 -0 0</pose> -->
      <pose frame=''>-0.4323 -0.17098 0 0 -0 0</pose>  <!-- values from spirit-->
      <inertial>
        <pose frame=''>0.002894 0 0 0 -0 0</pose>
        <mass>0.263</mass>
        <inertia>
          <ixx>0.00096398</ixx>
          <ixy>-3.788e-05</ixy>
          <ixz>1.0791e-05</ixz>
          <iyy>0.00107276</iyy>
          <iyz>0.00017591</iyz>
          <izz>0.00120673</izz>
        </inertia>
      </inertial>
      <collision name='lower3_collision'>
        <pose frame=''>0.103 0 0 0 1.5708 0</pose>
        <geometry>
          <cylinder>
            <length>0.206</length>
            <radius>0.013</radius>
          </cylinder>
        </geometry>
        <surface>
          <contact>
            <ode />
          </contact>
          <friction>
            <ode />
          </friction>
        </surface>
      </collision>
      <visual name='lower3_visual'>
        <pose frame=''>0.103 0 0 0 1.5708 0</pose>
        <geometry>
          <cylinder>
            <length>0.206</length>
            <radius>0.013</radius>
          </cylinder>
          <!-- <mesh>
            <uri>model:///meshes/lower.STL</uri>
          </mesh> -->
        </geometry>
        <material>
          <script>
            <name>Gazebo/DarkGrey</name>
            <uri>file://media/materials/scripts/gazebo.material</uri>
          </script>
        </material>
      </visual>
      <velocity_decay />
      <gravity>1</gravity>
      <velocity_decay />
    </link>

    <joint name='7' type='revolute'>
      <!-- <pose relative_to='upper3'>-0.206 0 0 0 -0 0</pose> -->
      <child>lower3</child>
      <parent>upper3</parent>
      <axis>
        <xyz>0 1 0</xyz>
        <limit>
          <lower>0</lower>
          <upper>3.14159</upper>
          <effort>40</effort>
          <velocity>30</velocity>
        </limit>
        <dynamics>
          <damping>0</damping>
          <friction>0</friction>
          <spring_reference>0</spring_reference>
          <spring_stiffness>0</spring_stiffness>
        </dynamics>
        <use_parent_model_frame>1</use_parent_model_frame>
      </axis>
    </joint>
    
    <link name='toe0'>
      <pose frame=''>0.2263 0.17098 0 0 -0 0</pose>
      <inertial>
        <pose frame=''>0 0 0 0 -0 0</pose>
        <mass>0.015</mass>
        <inertia>
          <ixx>0.000025</ixx>
          <ixy>0</ixy>
          <ixz>0</ixz>
          <iyy>0.000025</iyy>
          <iyz>0</iyz>
          <izz>0.000025</izz>
        </inertia>
      </inertial>
      <collision name='toe0_collision'>
        <pose frame=''>0 0 0 0 -0 0</pose>
        <geometry>
          <sphere>
            <radius>0.02</radius>
          </sphere>
        </geometry>
        <surface>
          <bounce>
            <restitution_coefficient>0</restitution_coefficient>
            <threshold>1e+06</threshold>
          </bounce>
          <friction>
            <ode>
              <mu>0.5</mu>
              <mu2>0.5</mu2>
            </ode>
            <bullet>
              <rolling_friction>0.3</rolling_friction>
              <friction2>50</friction2>
            </bullet>
          </friction>
          <contact>
            <bullet>
              <kp>30000</kp>
              <kd>1000</kd>
              <split_impulse>1</split_impulse>
              <split_impulse_penetration_threshold>-0.01</split_impulse_penetration_threshold>
            </bullet>
            <ode>
              <kp>30000</kp>
              <kd>1000</kd>
            </ode>
          </contact>
        </surface>
      </collision>
      <sensor name="toe0_contact" type="contact">
        <plugin name="toe0_plugin" filename="libgazebo_ros_bumper.so">
          <alwaysOn>true</alwaysOn>
          <updateRate>500</updateRate>
          <bumperTopicName>gazebo/toe0_contact_state</bumperTopicName>
          <frameName>world</frameName>
        </plugin>
        <contact>
          <collision>toe0_collision</collision>
        </contact>
        <update_rate>500</update_rate>
      </sensor>
      <visual name='toe0_visual'>
        <pose frame=''>0 0 0 0 -0 0</pose>
        <geometry>
          <sphere>
            <radius>0.02</radius>
          </sphere>
        </geometry>
        <material>
          <script>
            <name>Gazebo/Black</name>
            <uri>file://media/materials/scripts/gazebo.material</uri>
          </script>
        </material>
      </visual>
      <gravity>1</gravity>
      <velocity_decay />
    </link>
    <joint name='jtoe0' type='fixed'>
      <child>toe0</child>
      <parent>lower0</parent>
    </joint>

    <link name='toe1'>
      <pose frame=''>-0.2263 0.17098 0 0 -0 0</pose>
      <inertial>
        <pose frame=''>0 0 0 0 -0 0</pose>
        <mass>0.015</mass>
        <inertia>
          <ixx>0.000025</ixx>
          <ixy>0</ixy>
          <ixz>0</ixz>
          <iyy>0.000025</iyy>
          <iyz>0</iyz>
          <izz>0.000025</izz>
        </inertia>
      </inertial>
      <collision name='toe1_collision'>
        <pose frame=''>0 0 0 0 -0 0</pose>
        <geometry>
          <sphere>
            <radius>0.02</radius>
          </sphere>
        </geometry>
        <surface>
          <bounce>
            <restitution_coefficient>0</restitution_coefficient>
            <threshold>1e+06</threshold>
          </bounce>
          <friction>
            <ode>
              <mu>0.5</mu>
              <mu2>0.5</mu2>
            </ode>
            <bullet>
              <rolling_friction>0.3</rolling_friction>
              <friction2>50</friction2>
            </bullet>
          </friction>
          <contact>
            <bullet>
              <kp>30000</kp>
              <kd>1000</kd>
              <split_impulse>1</split_impulse>
              <split_impulse_penetration_threshold>-0.01</split_impulse_penetration_threshold>
            </bullet>
            <ode>
              <kp>30000</kp>
              <kd>1000</kd>
            </ode>
          </contact>
        </surface>
      </collision>
      <sensor name="toe1_contact" type="contact">
        <plugin name="toe1_plugin" filename="libgazebo_ros_bumper.so">
          <alwaysOn>true</alwaysOn>
          <updateRate>500</updateRate>
          <bumperTopicName>gazebo/toe1_contact_state</bumperTopicName>
          <frameName>world</frameName>
        </plugin>
        <contact>
          <collision>toe1_collision</collision>
        </contact>
        <update_rate>500</update_rate>
      </sensor>
      <visual name='toe1_visual'>
        <pose frame=''>0 0 0 0 -0 0</pose>
        <geometry>
          <sphere>
            <radius>0.02</radius>
          </sphere>
        </geometry>
        <material>
          <script>
            <name>Gazebo/Black</name>
            <uri>file://media/materials/scripts/gazebo.material</uri>
          </script>
        </material>
      </visual>
      <gravity>1</gravity>
      <velocity_decay />
    </link>
    <joint name='jtoe1' type='fixed'>
      <child>toe1</child>
      <parent>lower1</parent>
    </joint>

    <link name='toe2'>
      <pose frame=''>0.2263 -0.17098 0 0 -0 0</pose>
      <inertial>
        <pose frame=''>0 0 0 0 -0 0</pose>
        <mass>0.015</mass>
        <inertia>
          <ixx>0.000025</ixx>
          <ixy>0</ixy>
          <ixz>0</ixz>
          <iyy>0.000025</iyy>
          <iyz>0</iyz>
          <izz>0.000025</izz>
        </inertia>
      </inertial>
      <collision name='toe2_collision'>
        <pose frame=''>0 0 0 0 -0 0</pose>
        <geometry>
          <sphere>
            <radius>0.02</radius>
          </sphere>
        </geometry>
        <surface>
          <bounce>
            <restitution_coefficient>0</restitution_coefficient>
            <threshold>1e+06</threshold>
          </bounce>
          <friction>
            <ode>
              <mu>0.5</mu>
              <mu2>0.5</mu2>
            </ode>
            <bullet>
              <rolling_friction>0.3</rolling_friction>
              <friction2>50</friction2>
            </bullet>
          </friction>
          <contact>
            <bullet>
              <kp>30000</kp>
              <kd>1000</kd>
              <split_impulse>1</split_impulse>
              <split_impulse_penetration_threshold>-0.01</split_impulse_penetration_threshold>
            </bullet>
            <ode>
              <kp>30000</kp>
              <kd>1000</kd>
            </ode>
          </contact>
        </surface>
      </collision>
      <sensor name="toe2_contact" type="contact">
        <plugin name="toe2_plugin" filename="libgazebo_ros_bumper.so">
          <alwaysOn>true</alwaysOn>
          <updateRate>500</updateRate>
          <bumperTopicName>gazebo/toe2_contact_state</bumperTopicName>
          <frameName>world</frameName>
        </plugin>
        <contact>
          <collision>toe2_collision</collision>
        </contact>
        <update_rate>500</update_rate>
      </sensor>
      <visual name='toe2_visual'>
        <pose frame=''>0 0 0 0 -0 0</pose>
        <geometry>
          <sphere>
            <radius>0.02</radius>
          </sphere>
        </geometry>
        <material>
          <script>
            <name>Gazebo/Black</name>
            <uri>file://media/materials/scripts/gazebo.material</uri>
          </script>
        </material>
      </visual>
      <gravity>1</gravity>
      <velocity_decay />
    </link>
    <joint name='jtoe2' type='fixed'>
      <child>toe2</child>
      <parent>lower2</parent>
    </joint>

    <link name='toe3'>
      <pose frame=''>-0.2263 -0.17098 0 0 -0 0</pose>
      <inertial>
        <pose frame=''>0 0 0 0 -0 0</pose>
        <mass>0.015</mass>
        <inertia>
          <ixx>0.000025</ixx>
          <ixy>0</ixy>
          <ixz>0</ixz>
          <iyy>0.000025</iyy>
          <iyz>0</iyz>
          <izz>0.000025</izz>
        </inertia>
      </inertial>
      <collision name='toe3_collision'>
        <pose frame=''>0 0 0 0 -0 0</pose>
        <geometry>
          <sphere>
            <radius>0.02</radius>
          </sphere>
        </geometry>
        <surface>
          <bounce>
            <restitution_coefficient>0</restitution_coefficient>
            <threshold>1e+06</threshold>
          </bounce>
          <friction>
            <ode>
              <mu>0.5</mu>
              <mu2>0.5</mu2>
            </ode>
            <bullet>
              <rolling_friction>0.3</rolling_friction>
              <friction2>50</friction2>
            </bullet>
          </friction>
          <contact>
            <bullet>
              <kp>30000</kp>
              <kd>1000</kd>
              <split_impulse>1</split_impulse>
              <split_impulse_penetration_threshold>-0.01</split_impulse_penetration_threshold>
            </bullet>
            <ode>
              <kp>30000</kp>
              <kd>1000</kd>
            </ode>
          </contact>
        </surface>
      </collision>
      <sensor name="toe3_contact" type="contact">
        <plugin name="toe3_plugin" filename="libgazebo_ros_bumper.so">
          <alwaysOn>true</alwaysOn>
          <updateRate>500</updateRate>
          <bumperTopicName>gazebo/toe3_contact_state</bumperTopicName>
          <frameName>world</frameName>
        </plugin>
        <contact>
          <collision>toe3_collision</collision>
        </contact>
        <update_rate>500</update_rate>
      </sensor>
      <visual name='toe3_visual'>
        <pose frame=''>0 0 0 0 -0 0</pose>
        <geometry>
          <sphere>
            <radius>0.02</radius>
          </sphere>
        </geometry>
        <material>
          <script>
            <name>Gazebo/Black</name>
            <uri>file://media/materials/scripts/gazebo.material</uri>
          </script>
        </material>
      </visual>
      <gravity>1</gravity>
      <velocity_decay />
    </link>
    <joint name='jtoe3' type='fixed'>
      <child>toe3</child>
      <parent>lower3</parent>
    </joint>

    <include>
      <uri>model://cmu_text</uri>
      <pose>0 0 0 0 0 0</pose>
    </include>

    <joint name="cmu_text" type="fixed">
      <child>cmu_text::text</child>
      <parent>body</parent>
    </joint>

    <!-- Publish imu sensor readings -->
    <include>
      <uri>model://imu</uri>
      <pose>0 0 0 0 0 0 </pose>
    </include>
    <joint name="imu_joint" type="fixed">
      <child>imu::link</child>
      <parent>body</parent>
    </joint>
    <!-- Setup ros control -->
    <plugin name='gazebo_ros_control' filename='libgazebo_ros_control.so'>
      <controlPeriod>0.002</controlPeriod>
    </plugin>
    <!-- Publish ground truth state data -->
    <plugin filename="libground_truth_estimator.so" name="ground_truth_estimator">
      <updateRateHZ>500.0</updateRateHZ>
    </plugin>

  </model>
</sdf>
