<?xml version="1.0" encoding="utf-8"?>
<!-- This URDF was automatically created by SolidWorks to URDF Exporter! Originally created by Stephen Brawner (brawner@gmail.com) 
     Commit Version: 1.6.0-4-g7f85cfe  Build Version: 1.6.7995.38578
     For more information, please see http://wiki.ros.org/sw_urdf_exporter -->
<robot name="cyberdog_description">
  <material name="black">
    <color rgba="0.0 0.0 0.0 1.0"/>
  </material>
  <material name="blue">
    <color rgba="0.0 0.0 0.8 1.0"/>
  </material>
  <material name="green">
    <color rgba="0.0 0.8 0.0 1.0"/>
  </material>
  <material name="grey">
    <color rgba="0.2 0.2 0.2 1.0"/>
  </material>
  <material name="silver">
    <color rgba="0.913725490196 0.913725490196 0.847058823529 1.0"/>
  </material>
  <material name="orange">
    <color rgba="1.0 0.423529411765 0.0392156862745 1.0"/>
  </material>
  <material name="brown">
    <color rgba="0.870588235294 0.811764705882 0.764705882353 1.0"/>
  </material>
  <material name="red">
    <color rgba="0.8 0.0 0.0 1.0"/>
  </material>
  <material name="white">
    <color rgba="1.0 1.0 1.0 1.0"/>
  </material>
  <!-- ros_control plugin -->
  <gazebo>
    <plugin filename="libgazebo_ros_control.so" name="gazebo_ros_control">
      <robotSimType>gazebo_ros_control/DefaultRobotHWSim</robotSimType>
    </plugin>
    <plugin filename="libground_truth_estimator.so" name="ground_truth_estimator">
      <updateRateHZ>500.0</updateRateHZ>
    </plugin>
  </gazebo>
  <!-- Show the trajectory of trunk center. -->
  <!-- <gazebo>
    <plugin filename="libLinkPlot3DPlugin.so" name="3dplotbody">
      <frequency>10</frequency>
      <plot>
        <link>body</link>
        <pose>0 0 0 0 0 0</pose>
        <material>Gazebo/Yellow</material>
      </plot>
    </plugin>
  </gazebo> -->
  <!-- Show the trajectory of foot. You can add another trajectory about another foot. -->
  <!-- <gazebo>
    <plugin filename="libLinkPlot3DPlugin.so" name="3dplot">
      <frequency>1000</frequency>
      <plot>
        <link>lower2</link>
        <pose>0 0 -0.217 0 0 0</pose>
        <material>Gazebo/Yellow</material>
      </plot>
    </plugin>
  </gazebo> -->
  <gazebo>
    <plugin filename="libgazebo_ros_force.so" name="gazebo_ros_force">
      <bodyName>trunk</bodyName>
      <topicName>/apply_force/trunk</topicName>
    </plugin>
  </gazebo>
  <gazebo reference="imu_link">
    <gravity>true</gravity>
    <sensor name="imu_sensor" type="imu">
      <always_on>true</always_on>
      <update_rate>1000</update_rate>
      <visualize>true</visualize>
      <topic>__default_topic__</topic>
      <plugin filename="libgazebo_ros_imu_sensor.so" name="imu_plugin">
        <topicName>trunk_imu</topicName>
        <bodyName>imu_link</bodyName>
        <updateRateHZ>1000.0</updateRateHZ>
        <gaussianNoise>0.0</gaussianNoise>
        <xyzOffset>0 0 0</xyzOffset>
        <rpyOffset>0 0 0</rpyOffset>
        <frameName>imu_link</frameName>
      </plugin>
      <pose>0 0 0 0 0 0</pose>
    </sensor>
  </gazebo>
  <!-- Foot contacts. -->
  <!-- <gazebo reference="lower2">
    <sensor name="toe2_contact" type="contact">
      <update_rate>100</update_rate>
      <plugin filename="libunitreeFootContactPlugin.so" name="contactPlugin"/>
      <contact>
        <collision>lower2_fixed_joint_lump__toe2_collision_1</collision>
      </contact>
    </sensor>
  </gazebo>
  <gazebo reference="lower0">
    <sensor name="toe0_contact" type="contact">
      <update_rate>100</update_rate>
      <plugin filename="libunitreeFootContactPlugin.so" name="contactPlugin"/>
      <contact>
        <collision>lower0_fixed_joint_lump__toe0_collision_1</collision>
      </contact>
    </sensor>
  </gazebo>
  <gazebo reference="lower3">
    <sensor name="toe3_contact" type="contact">
      <update_rate>100</update_rate>
      <plugin filename="libunitreeFootContactPlugin.so" name="contactPlugin"/>
      <contact>
        <collision>lower3_fixed_joint_lump__toe3_collision_1</collision>
      </contact>
    </sensor>
  </gazebo>
  <gazebo reference="lower1">
    <sensor name="toe1_contact" type="contact">
      <update_rate>100</update_rate>
      <plugin filename="libunitreeFootContactPlugin.so" name="contactPlugin"/>
      <contact>
        <collision>lower1_fixed_joint_lump__toe1_collision_1</collision>
      </contact>
    </sensor>
  </gazebo> -->
  <gazebo reference="toe0">
    <sensor name="toe0_contact" type="contact">
      <plugin filename="libgazebo_ros_bumper.so" name="toe0_plugin">
        <alwaysOn>true</alwaysOn>
        <updateRate>500</updateRate>
        <bumperTopicName>gazebo/toe0_contact_state</bumperTopicName>
        <frameName>world</frameName>
      </plugin>
      <contact>
        <collision>toe0_collision</collision>
      </contact>
      <update_rate>500</update_rate>
    </sensor>
  </gazebo>
  <gazebo reference="toe1">
    <sensor name="toe1_contact" type="contact">
      <plugin filename="libgazebo_ros_bumper.so" name="toe1_plugin">
        <alwaysOn>true</alwaysOn>
        <updateRate>500</updateRate>
        <bumperTopicName>gazebo/toe1_contact_state</bumperTopicName>
        <frameName>world</frameName>
      </plugin>
      <contact>
        <collision>toe1_collision</collision>
      </contact>
      <update_rate>500</update_rate>
    </sensor>
  </gazebo>
  <gazebo reference="toe2">
    <sensor name="toe2_contact" type="contact">
      <plugin filename="libgazebo_ros_bumper.so" name="toe2_plugin">
        <alwaysOn>true</alwaysOn>
        <updateRate>500</updateRate>
        <bumperTopicName>gazebo/toe2_contact_state</bumperTopicName>
        <frameName>world</frameName>
      </plugin>
      <contact>
        <collision>toe2_collision</collision>
      </contact>
      <update_rate>500</update_rate>
    </sensor>
  </gazebo>
  <gazebo reference="toe3">
    <sensor name="toe3_contact" type="contact">
      <plugin filename="libgazebo_ros_bumper.so" name="toe3_plugin">
        <alwaysOn>true</alwaysOn>
        <updateRate>500</updateRate>
        <bumperTopicName>gazebo/toe3_contact_state</bumperTopicName>
        <frameName>world</frameName>
      </plugin>
      <contact>
        <collision>toe3_collision</collision>
      </contact>
      <update_rate>500</update_rate>
    </sensor>
  </gazebo>
  <!-- Visualization of Foot contacts. -->
  <!-- <gazebo reference="toe2">
    <visual>
      <plugin filename="libunitreeDrawForcePlugin.so" name="drawForcePlugin">
        <topicName>toe2_contact</topicName>
      </plugin>
    </visual>
  </gazebo>
  <gazebo reference="toe0">
    <visual>
      <plugin filename="libunitreeDrawForcePlugin.so" name="drawForcePlugin">
        <topicName>toe0_contact</topicName>
      </plugin>
    </visual>
  </gazebo>
  <gazebo reference="toe3">
    <visual>
      <plugin filename="libunitreeDrawForcePlugin.so" name="drawForcePlugin">
        <topicName>toe3_contact</topicName>
      </plugin>
    </visual>
  </gazebo>
  <gazebo reference="toe1">
    <visual>
      <plugin filename="libunitreeDrawForcePlugin.so" name="drawForcePlugin">
        <topicName>toe1_contact</topicName>
      </plugin>
    </visual>
  </gazebo> -->
  <gazebo reference="body">
    <material>Gazebo/Green</material>
    <turnGravityOff>false</turnGravityOff>
  </gazebo>
  <gazebo reference="trunk">
    <mu1>0.2</mu1>
    <mu2>0.2</mu2>
    <kp value="1000000.0"/>
    <kd value="1.0"/>
  </gazebo>
  <gazebo reference="imu_link">
    <mu1>0.2</mu1>
    <mu2>0.2</mu2>
    <material>Gazebo/Red</material>
  </gazebo>
  <!-- FR leg -->
  <gazebo reference="hip2">
    <mu1>0.2</mu1>
    <mu2>0.2</mu2>
    <material>Gazebo/DarkGrey</material>
  </gazebo>
  <gazebo reference="upper2">
    <mu1>0.2</mu1>
    <mu2>0.2</mu2>
    <self_collide>1</self_collide>
    <material>Gazebo/DarkGrey</material>
    <kp value="1000000.0"/>
    <kd value="1.0"/>
  </gazebo>
  <gazebo reference="lower2">
    <mu1>0.2</mu1>
    <mu2>0.2</mu2>
    <self_collide>1</self_collide>
  </gazebo>
  <gazebo reference="toe2">
    <mu1>0.6</mu1>
    <mu2>0.6</mu2>
    <self_collide>1</self_collide>
    <material>Gazebo/DarkGrey</material>
    <kp value="1000000.0"/>
    <kd value="1.0"/>
  </gazebo>
  <!-- FL leg -->
  <gazebo reference="hip0">
    <mu1>0.2</mu1>
    <mu2>0.2</mu2>
    <material>Gazebo/DarkGrey</material>
  </gazebo>
  <gazebo reference="upper0">
    <mu1>0.2</mu1>
    <mu2>0.2</mu2>
    <self_collide>1</self_collide>
    <material>Gazebo/DarkGrey</material>
    <kp value="1000000.0"/>
    <kd value="1.0"/>
  </gazebo>
  <gazebo reference="lower0">
    <mu1>0.2</mu1>
    <mu2>0.2</mu2>
    <self_collide>1</self_collide>
  </gazebo>
  <gazebo reference="toe0">
    <mu1>0.6</mu1>
    <mu2>0.6</mu2>
    <self_collide>1</self_collide>
    <material>Gazebo/DarkGrey</material>
    <kp value="1000000.0"/>
    <kd value="1.0"/>
  </gazebo>
  <!-- RR leg -->
  <gazebo reference="hip3">
    <mu1>0.2</mu1>
    <mu2>0.2</mu2>
    <material>Gazebo/DarkGrey</material>
  </gazebo>
  <gazebo reference="upper3">
    <mu1>0.2</mu1>
    <mu2>0.2</mu2>
    <self_collide>1</self_collide>
    <material>Gazebo/DarkGrey</material>
    <kp value="1000000.0"/>
    <kd value="1.0"/>
  </gazebo>
  <gazebo reference="lower3">
    <mu1>0.2</mu1>
    <mu2>0.2</mu2>
    <self_collide>1</self_collide>
  </gazebo>
  <gazebo reference="toe3">
    <mu1>0.6</mu1>
    <mu2>0.6</mu2>
    <self_collide>1</self_collide>
    <material>Gazebo/DarkGrey</material>
    <kp value="1000000.0"/>
    <kd value="1.0"/>
  </gazebo>
  <!-- RL leg -->
  <gazebo reference="hip1">
    <mu1>0.2</mu1>
    <mu2>0.2</mu2>
    <material>Gazebo/DarkGrey</material>
  </gazebo>
  <gazebo reference="upper1">
    <mu1>0.2</mu1>
    <mu2>0.2</mu2>
    <self_collide>1</self_collide>
    <material>Gazebo/DarkGrey</material>
    <kp value="1000000.0"/>
    <kd value="1.0"/>
  </gazebo>
  <gazebo reference="lower1">
    <mu1>0.2</mu1>
    <mu2>0.2</mu2>
    <self_collide>1</self_collide>
  </gazebo>
  <gazebo reference="toe1">
    <mu1>0.6</mu1>
    <mu2>0.6</mu2>
    <self_collide>1</self_collide>
    <material>Gazebo/DarkGrey</material>
    <kp value="1000000.0"/>
    <kd value="1.0"/>
  </gazebo>

  <!-- 悬挂 -->
  <!-- <link name="world"/>
  <joint name="body_static_joint" type="fixed">
      <origin rpy="0 0 0" xyz="0 0 0"/>
      <parent link="world"/>
      <child link="body"/>
  </joint> -->

  <link name="body">
    <visual>
      <origin rpy="0 0 0" xyz="0 0 0"/>
      <geometry>
        <box size="0.001 0.001 0.001"/>
      </geometry>
    </visual>
  </link>
  <joint name="floating_base" type="fixed">
    <origin rpy="0 0 0" xyz="0 0 0"/>
    <parent link="body"/>
    <child link="trunk"/>
  </joint>
  <link name="trunk">
    <inertial>
      <origin
        xyz="0 0 0"
        rpy="0 0 0" />
      <mass value="7.18" />
      <inertia
        ixx="0.032051"
        ixy="-0.00023217"
        ixz="0.002728"
        iyy="0.13707"
        iyz="5.6623E-05"
        izz="0.14946" />
    </inertial>
    <visual>
      <origin
        xyz="0 0 0"
        rpy="0 0 0" />
      <geometry>
        <mesh filename="package://cyberdog_description/meshes/body.STL" />
      </geometry>
      <material name="">
        <color rgba="1 1 1 1" />
      </material>
    </visual>
    <collision>
      <origin
        xyz="0 0 0"
        rpy="0 0 0" />
      <geometry>
        <mesh filename="package://cyberdog_description/meshes/body.STL" />
      </geometry>
    </collision>
  </link>

  <joint name="imu_joint" type="fixed">
    <parent link="trunk"/>
    <child link="imu_link"/>
    <origin rpy="0 0 0" xyz="0 0 0"/>
  </joint>
  <link name="imu_link">
    <!-- <inertial>
      <mass value="0.001"/>
      <origin rpy="0 0 0" xyz="0 0 0"/>
      <inertia ixx="0.0001" ixy="0" ixz="0" iyy="0.0001" iyz="0" izz="0.0001"/>
    </inertial>
    <visual>
      <origin rpy="0 0 0" xyz="0 0 0"/>
      <geometry>
        <box size="0.001 0.001 0.001"/>
      </geometry>
      <material name="red"/>
    </visual>
    <collision>
      <origin rpy="0 0 0" xyz="0 0 0"/>
      <geometry>
        <box size=".001 .001 .001"/>
      </geometry>
    </collision> -->
  </link>

  <link name="hip0">
    <inertial>
      <origin
        xyz="0 0.053575 0"
        rpy="0 0 0" />
      <mass value="0.509" />
      <inertia
        ixx="0.00038097"
        ixy="1.2523E-05"
        ixz="-1.1653E-05"
        iyy="0.00069383"
        iyz="5.071E-06"
        izz="0.00047336" />
    </inertial>
    <visual>
      <origin
        xyz="0 0 0"
        rpy="0 0 0" />
      <geometry>
        <mesh filename="package://cyberdog_description/meshes/link_abad_fl.STL" />
      </geometry>
      <material name="">
        <color rgba="1 1 1 1" />
      </material>
    </visual>
    <collision>
      <origin
        xyz="0 0 0"
        rpy="0 0 0" />
      <geometry>
        <mesh filename="package://cyberdog_description/meshes/link_abad_fl.STL" />
      </geometry>
    </collision>
  </link>
  <joint
    name="8"
    type="revolute">
    <origin
      xyz="0.23536 0.05 0"
      rpy="0 0 0" />
    <parent link="trunk" />
    <child link="hip0" />
    <axis xyz="1 0 0" />
    <limit
      lower="-0.75"
      upper="0.75"
      effort="17"
      velocity="12" />
    <dynamics
      damping="0.01"
      friction="0.2" />
  </joint>
  <link name="upper0">
    <inertial>
      <origin
        xyz="0 0 -0.1"
        rpy="0 0 0" />
      <mass value="0.664" />
      <inertia
        ixx="0.0033376"
        ixy="-7.150375E-07"
        ixz="-0.00019282"
        iyy="0.0026385"
        iyz="-9.3033E-06"
        izz="0.0013093" />
    </inertial>
    <visual>
      <origin
        xyz="0 0 0"
        rpy="0 0 0" />
      <geometry>
        <mesh filename="package://cyberdog_description/meshes/link_hip_fl.STL" />
      </geometry>
      <material name="">
        <color rgba="1 1 1 1" />
      </material>
    </visual>
    <collision>
      <origin
        xyz="0 0 0"
        rpy="0 0 0" />
      <geometry>
        <mesh filename="package://cyberdog_description/meshes/link_hip_fl.STL" />
      </geometry>
    </collision>
  </link>
  <joint
    name="0"
    type="revolute">
    <origin
      xyz="0 0.10715 0"
      rpy="0 0 0" />
    <parent link="hip0" />
    <child link="upper0" />
    <axis xyz="0 1 0" />
    <limit
      lower="-1.257"
      upper="4.363"
      effort="24"
      velocity="12" />
    <dynamics
      damping="0.01"
      friction="0.2" />
  </joint>
  <link name="lower0">
    <inertial>
      <origin
        xyz="0 0 -0.11439"
        rpy="0 0 0" />
      <mass value="0.114" />
      <inertia
        ixx="0.0014553"
        ixy="-3.2376E-08"
        ixz="8.3885E-05"
        iyy="0.0021522"
        iyz="5.1259E-07"
        izz="0.00070545" />
    </inertial>
    <visual>
      <origin
        xyz="0 0 0"
        rpy="0 0 0" />
      <geometry>
        <mesh filename="package://cyberdog_description/meshes/link_knee_fl.STL" />
      </geometry>
      <material name="">
        <color rgba="1 1 1 1" />
      </material>
    </visual>
    <collision>
      <origin
        xyz="0 0 0"
        rpy="0 0 0" />
      <geometry>
        <mesh filename="package://cyberdog_description/meshes/link_knee_fl.STL" />
      </geometry>
    </collision>
  </link>
  <joint
    name="1"
    type="revolute">
    <origin
      xyz="0 0 -0.2"
      rpy="0 0 0" />
    <parent link="upper0" />
    <child link="lower0" />
    <axis xyz="0 1 0" />
    <limit
      lower="-2.478"
      upper="-0.506"
      effort="24"
      velocity="12" />
    <dynamics
      damping="0.01"
      friction="0.2" />
  </joint>
  <joint name="jtoe0" type="fixed">
    <origin rpy="0 0 0" xyz="0 0 -0.217"/>
    <parent link="lower0"/>
    <child link="toe0"/>
  </joint>
  <link name="toe0">
    <visual>
      <origin rpy="0 0 0" xyz="0 0 0"/>
      <geometry>
        <sphere radius="0.022"/>
      </geometry>
      <material name="grey"/>
    </visual>
    <collision>
      <origin rpy="0 0 0" xyz="0 0 0"/>
      <geometry>
        <sphere radius="0.022"/>
      </geometry>
    </collision>
    <inertial>
      <mass value="0.026"/>
      <inertia ixx="0.0" ixy="0.0" ixz="0.0" iyy="0.0" iyz="0.0" izz="0.0"/>
    </inertial>
  </link>

  <transmission name="transmission_8">
    <type>transmission_interface/SimpleTransmission</type>
    <joint name="8">
      <hardwareInterface>hardware_interface/EffortJointInterface</hardwareInterface>
    </joint>
    <actuator name="motor_8">
      <hardwareInterface>hardware_interface/EffortJointInterface</hardwareInterface>
      <mechanicalReduction>1</mechanicalReduction>
    </actuator>
  </transmission>
  <transmission name="transmission_0">
    <type>transmission_interface/SimpleTransmission</type>
    <joint name="0">
      <hardwareInterface>hardware_interface/EffortJointInterface</hardwareInterface>
    </joint>
    <actuator name="motor_0">
      <hardwareInterface>hardware_interface/EffortJointInterface</hardwareInterface>
      <mechanicalReduction>1</mechanicalReduction>
    </actuator>
  </transmission>
  <transmission name="transmission_1">
    <type>transmission_interface/SimpleTransmission</type>
    <joint name="1">
      <hardwareInterface>hardware_interface/EffortJointInterface</hardwareInterface>
    </joint>
    <actuator name="motor_1">
      <hardwareInterface>hardware_interface/EffortJointInterface</hardwareInterface>
      <mechanicalReduction>1</mechanicalReduction>
    </actuator>
  </transmission>

  <link name="hip1">
    <inertial>
      <origin
        xyz="0 0.053575 0"
        rpy="0 0 0" />
      <mass value="0.509" />
      <inertia
        ixx="0.00038097"
        ixy="1.2523E-05"
        ixz="-1.1653E-05"
        iyy="0.00069383"
        iyz="5.071E-06"
        izz="0.00047336" />
    </inertial>
    <visual>
      <origin
        xyz="0 0 0"
        rpy="0 0 0" />
      <geometry>
        <mesh filename="package://cyberdog_description/meshes/link_abad_bl.STL" />
      </geometry>
      <material name="">
        <color rgba="1 1 1 1" />
      </material>
    </visual>
    <collision>
      <origin
        xyz="0 0 0"
        rpy="0 0 0" />
      <geometry>
        <mesh filename="package://cyberdog_description/meshes/link_abad_bl.STL" />
      </geometry>
    </collision>
  </link>
  <joint
    name="9"
    type="revolute">
    <origin
      xyz="-0.23536 0.05 0"
      rpy="0 0 0" />
    <parent link="trunk" />
    <child link="hip1" />
    <axis xyz="1 0 0" />
    <limit
      lower="-0.75"
      upper="0.75"
      effort="17"
      velocity="12" />
    <dynamics
      damping="0.01"
      friction="0.2" />
  </joint>
  <link name="upper1">
    <inertial>
      <origin
        xyz="0 0 -0.1"
        rpy="0 0 0" />
      <mass value="0.664" />
      <inertia
        ixx="0.0033376"
        ixy="-7.1504E-07"
        ixz="-0.00019282"
        iyy="0.0026385"
        iyz="-9.3033E-06"
        izz="0.0013093" />
    </inertial>
    <visual>
      <origin
        xyz="0 0 0"
        rpy="0 0 0" />
      <geometry>
        <mesh filename="package://cyberdog_description/meshes/link_hip_bl.STL" />
      </geometry>
      <material name="">
        <color rgba="1 1 1 1" />
      </material>
    </visual>
    <collision>
      <origin
        xyz="0 0 0"
        rpy="0 0 0" />
      <geometry>
        <mesh filename="package://cyberdog_description/meshes/link_hip_bl.STL" />
      </geometry>
    </collision>
  </link>
  <joint
    name="2"
    type="revolute">
    <origin
      xyz="0 0.10715 0"
      rpy="0 0 0" />
    <parent link="hip1" />
    <child link="upper1" />
    <axis xyz="0 1 0" />
    <limit
      lower="-2.01"
      upper="3.49"
      effort="24"
      velocity="12" />
    <dynamics
      damping="0.01"
      friction="0.2" />
  </joint>
  <link name="lower1">
    <inertial>
      <origin
        xyz="0 0 -0.11439"
        rpy="0 0 0" />
      <mass value="0.114" />
      <inertia
        ixx="0.0014553"
        ixy="-3.2376E-08"
        ixz="8.3885E-05"
        iyy="0.0021522"
        iyz="5.1259E-07"
        izz="0.00070545" />
    </inertial>
    <visual>
      <origin
        xyz="0 0 0"
        rpy="0 0 0" />
      <geometry>
        <mesh filename="package://cyberdog_description/meshes/link_knee_bl.STL" />
      </geometry>
      <material name="">
        <color rgba="1 1 1 1" />
      </material>
    </visual>
    <collision>
      <origin
        xyz="0 0 0"
        rpy="0 0 0" />
      <geometry>
        <mesh filename="package://cyberdog_description/meshes/link_knee_bl.STL" />
      </geometry>
    </collision>
  </link>
  <joint
    name="3"
    type="revolute">
    <origin
      xyz="0 0 -0.2"
      rpy="0 0 0" />
    <parent link="upper1" />
    <child link="lower1" />
    <axis xyz="0 1 0" />
    <limit
      lower="-2.478"
      upper="-0.506"
      effort="24"
      velocity="12" />
    <dynamics
      damping="0.01"
      friction="0.2" />
  </joint>
  <joint name="jtoe1" type="fixed">
    <origin rpy="0 0 0" xyz="0 0 -0.217"/>
    <parent link="lower1"/>
    <child link="toe1"/>
  </joint>
  <link name="toe1">
    <visual>
      <origin rpy="0 0 0" xyz="0 0 0"/>
      <geometry>
        <sphere radius="0.022"/>
      </geometry>
      <material name="grey"/>
    </visual>
    <collision>
      <origin rpy="0 0 0" xyz="0 0 0"/>
      <geometry>
        <sphere radius="0.022"/>
      </geometry>
    </collision>
    <inertial>
      <mass value="0.026"/>
      <inertia ixx="0.0" ixy="0.0" ixz="0.0" iyy="0.0" iyz="0.0" izz="0.0"/>
    </inertial>
  </link>

  <transmission name="transmission_9">
    <type>transmission_interface/SimpleTransmission</type>
    <joint name="9">
      <hardwareInterface>hardware_interface/EffortJointInterface</hardwareInterface>
    </joint>
    <actuator name="motor_9">
      <hardwareInterface>hardware_interface/EffortJointInterface</hardwareInterface>
      <mechanicalReduction>1</mechanicalReduction>
    </actuator>
  </transmission>
  <transmission name="transmission_2">
    <type>transmission_interface/SimpleTransmission</type>
    <joint name="2">
      <hardwareInterface>hardware_interface/EffortJointInterface</hardwareInterface>
    </joint>
    <actuator name="motor_2">
      <hardwareInterface>hardware_interface/EffortJointInterface</hardwareInterface>
      <mechanicalReduction>1</mechanicalReduction>
    </actuator>
  </transmission>
  <transmission name="transmission_3">
    <type>transmission_interface/SimpleTransmission</type>
    <joint name="3">
      <hardwareInterface>hardware_interface/EffortJointInterface</hardwareInterface>
    </joint>
    <actuator name="motor_3">
      <hardwareInterface>hardware_interface/EffortJointInterface</hardwareInterface>
      <mechanicalReduction>1</mechanicalReduction>
    </actuator>
  </transmission>

  <link name="hip2">
    <inertial>
      <origin
        xyz="0 -0.053575 0"
        rpy="0 0 0" />
      <mass value="0.509" />
      <inertia
        ixx="0.00038097"
        ixy="1.2523E-05"
        ixz="-1.1653E-05"
        iyy="0.00069383"
        iyz="5.071E-06"
        izz="0.00047336" />
    </inertial>
    <visual>
      <origin
        xyz="0 0 0"
        rpy="0 0 0" />
      <geometry>
        <mesh filename="package://cyberdog_description/meshes/link_abad_fr.STL" />
      </geometry>
      <material name="">
        <color rgba="1 1 1 1" />
      </material>
    </visual>
    <collision>
      <origin
        xyz="0 0 0"
        rpy="0 0 0" />
      <geometry>
        <mesh filename="package://cyberdog_description/meshes/link_abad_fr.STL" />
      </geometry>
    </collision>
  </link>
  <joint
    name="10"
    type="revolute">
    <origin
      xyz="0.23536 -0.05 0"
      rpy="0 0 0" />
    <parent link="trunk" />
    <child link="hip2" />
    <axis xyz="1 0 0" />
    <limit
      lower="-0.75"
      upper="0.75"
      effort="17"
      velocity="12" />
    <dynamics
      damping="0.01"
      friction="0.2" />
  </joint>
  <link name="upper2">
    <inertial>
      <origin
        xyz="0 0 -0.1"
        rpy="0 0 0" />
      <mass value="0.664" />
      <inertia
        ixx="0.0033376"
        ixy="-7.1504E-07"
        ixz="-0.00019282"
        iyy="0.0026385"
        iyz="-9.3033E-06"
        izz="0.0013093" />
    </inertial>
    <visual>
      <origin
        xyz="0 0 0"
        rpy="0 0 0" />
      <geometry>
        <mesh filename="package://cyberdog_description/meshes/link_hip_fr.STL" />
      </geometry>
      <material name="">
        <color rgba="1 1 1 1" />
      </material>
    </visual>
    <collision>
      <origin
        xyz="0 0 0"
        rpy="0 0 0" />
      <geometry>
        <mesh filename="package://cyberdog_description/meshes/link_hip_fr.STL" />
      </geometry>
    </collision>
  </link>
  <joint
    name="4"
    type="revolute">
    <origin
      xyz="0 -0.10715 0"
      rpy="0 0 0" />
    <parent link="hip2" />
    <child link="upper2" />
    <axis xyz="0 1 0" />
    <limit
      lower="-1.257"
      upper="4.363"
      effort="24"
      velocity="12" />
    <dynamics
      damping="0.01"
      friction="0.2" />
  </joint>
  <link name="lower2">
    <inertial>
      <origin
        xyz="0 0 -0.11439"
        rpy="0 0 0" />
      <mass value="0.114" />
      <inertia
        ixx="0.0014553"
        ixy="-3.2376E-08"
        ixz="8.3885E-05"
        iyy="0.0021522"
        iyz="5.1259E-07"
        izz="0.00070545" />
    </inertial>
    <visual>
      <origin
        xyz="0 0 0"
        rpy="0 0 0" />
      <geometry>
        <mesh filename="package://cyberdog_description/meshes/link_knee_fr.STL" />
      </geometry>
      <material name="">
        <color rgba="1 1 1 1" />
      </material>
    </visual>
    <collision>
      <origin
        xyz="0 0 0"
        rpy="0 0 0" />
      <geometry>
        <mesh filename="package://cyberdog_description/meshes/link_knee_fr.STL" />
      </geometry>
    </collision>
  </link>
  <joint
    name="5"
    type="revolute">
    <origin
      xyz="0 0 -0.2"
      rpy="0 0 0" />
    <parent link="upper2" />
    <child link="lower2" />
    <axis xyz="0 1 0" />
    <limit
      lower="-2.478"
      upper="-0.506"
      effort="24"
      velocity="12" />
    <dynamics
      damping="0.01"
      friction="0.2" />
  </joint>
  <joint name="jtoe2" type="fixed">
    <origin rpy="0 0 0" xyz="0 0 -0.217"/>
    <parent link="lower2"/>
    <child link="toe2"/>
  </joint>
  <link name="toe2">
    <visual>
      <origin rpy="0 0 0" xyz="0 0 0"/>
      <geometry>
        <sphere radius="0.022"/>
      </geometry>
      <material name="grey"/>
    </visual>
    <collision>
      <origin rpy="0 0 0" xyz="0 0 0"/>
      <geometry>
        <sphere radius="0.022"/>
      </geometry>
    </collision>
    <inertial>
      <mass value="0.026"/>
      <inertia ixx="0.0" ixy="0.0" ixz="0.0" iyy="0.0" iyz="0.0" izz="0.0"/>
    </inertial>
  </link>

  <transmission name="transmission_10">
    <type>transmission_interface/SimpleTransmission</type>
    <joint name="10">
      <hardwareInterface>hardware_interface/EffortJointInterface</hardwareInterface>
    </joint>
    <actuator name="motor_10">
      <hardwareInterface>hardware_interface/EffortJointInterface</hardwareInterface>
      <mechanicalReduction>1</mechanicalReduction>
    </actuator>
  </transmission>
  <transmission name="transmission_4">
    <type>transmission_interface/SimpleTransmission</type>
    <joint name="4">
      <hardwareInterface>hardware_interface/EffortJointInterface</hardwareInterface>
    </joint>
    <actuator name="motor_4">
      <hardwareInterface>hardware_interface/EffortJointInterface</hardwareInterface>
      <mechanicalReduction>1</mechanicalReduction>
    </actuator>
  </transmission>
  <transmission name="transmission_5">
    <type>transmission_interface/SimpleTransmission</type>
    <joint name="5">
      <hardwareInterface>hardware_interface/EffortJointInterface</hardwareInterface>
    </joint>
    <actuator name="motor_5">
      <hardwareInterface>hardware_interface/EffortJointInterface</hardwareInterface>
      <mechanicalReduction>1</mechanicalReduction>
    </actuator>
  </transmission>

  <link name="hip3">
    <inertial>
      <origin
        xyz="0 -0.053575 0"
        rpy="0 0 0" />
      <mass value="0.509" />
      <inertia
        ixx="0.00038097"
        ixy="1.2523E-05"
        ixz="-1.1653E-05"
        iyy="0.00069383"
        iyz="5.071E-06"
        izz="0.00047336" />
    </inertial>
    <visual>
      <origin
        xyz="0 0 0"
        rpy="0 0 0" />
      <geometry>
        <mesh filename="package://cyberdog_description/meshes/link_abad_br.STL" />
      </geometry>
      <material name="">
        <color rgba="1 1 1 1" />
      </material>
    </visual>
    <collision>
      <origin
        xyz="0 0 0"
        rpy="0 0 0" />
      <geometry>
        <mesh filename="package://cyberdog_description/meshes/link_abad_br.STL" />
      </geometry>
    </collision>
  </link>
  <joint
    name="11"
    type="revolute">
    <origin
      xyz="-0.23536 -0.05 0"
      rpy="0 0 0" />
    <parent link="trunk" />
    <child link="hip3" />
    <axis xyz="1 0 0" />
    <limit
      lower="-0.75"
      upper="0.75"
      effort="17"
      velocity="12" />
    <dynamics
      damping="0.01"
      friction="0.2" />
  </joint>
  <link name="upper3">
    <inertial>
      <origin
        xyz="0 0 -0.1"
        rpy="0 0 0" />
      <mass value="0.664" />
      <inertia
        ixx="0.0033376"
        ixy="-7.150375E-07"
        ixz="-0.00019282"
        iyy="0.0026385"
        iyz="-9.3033E-06"
        izz="0.0013093" />
    </inertial>
    <visual>
      <origin
        xyz="0 0 0"
        rpy="0 0 0" />
      <geometry>
        <mesh filename="package://cyberdog_description/meshes/link_hip_br.STL" />
      </geometry>
      <material name="">
        <color rgba="1 1 1 1" />
      </material>
    </visual>
    <collision>
      <origin
        xyz="0 0 0"
        rpy="0 0 0" />
      <geometry>
        <mesh filename="package://cyberdog_description/meshes/link_hip_br.STL" />
      </geometry>
    </collision>
  </link>
  <joint
    name="6"
    type="revolute">
    <origin
      xyz="0 -0.10715 0"
      rpy="0 0 0" />
    <parent link="hip3" />
    <child link="upper3" />
    <axis xyz="0 1 0" />
    <limit
      lower="-2.01"
      upper="3.49"
      effort="24"
      velocity="12" />
    <dynamics
      damping="0.01"
      friction="0.2" />
  </joint>
  <link name="lower3">
    <inertial>
      <origin
        xyz="0 0 -0.11439"
        rpy="0 0 0" />
      <mass value="0.114" />
      <inertia
        ixx="0.0014553"
        ixy="-3.2376E-08"
        ixz="8.3885E-05"
        iyy="0.0021522"
        iyz="5.1259E-07"
        izz="0.00070545" />
    </inertial>
    <visual>
      <origin
        xyz="0 0 0"
        rpy="0 0 0" />
      <geometry>
        <mesh filename="package://cyberdog_description/meshes/link_knee_br.STL" />
      </geometry>
      <material name="">
        <color rgba="1 1 1 1" />
      </material>
    </visual>
    <collision>
      <origin
        xyz="0 0 0"
        rpy="0 0 0" />
      <geometry>
        <mesh filename="package://cyberdog_description/meshes/link_knee_br.STL" />
      </geometry>
    </collision>
  </link>
  <joint
    name="7"
    type="revolute">
    <origin
      xyz="0 0 -0.2"
      rpy="0 0 0" />
    <parent link="upper3" />
    <child link="lower3" />
    <axis xyz="0 1 0" />
    <limit
      lower="-2.478"
      upper="-0.506"
      effort="24"
      velocity="12" />
    <dynamics
      damping="0.01"
      friction="0.2" />
  </joint>
  <joint name="jtoe3" type="fixed">
    <origin rpy="0 0 0" xyz="0 0 -0.217"/>
    <parent link="lower3"/>
    <child link="toe3"/>
  </joint>
  <link name="toe3">
    <visual>
      <origin rpy="0 0 0" xyz="0 0 0"/>
      <geometry>
        <sphere radius="0.022"/>
      </geometry>
      <material name="grey"/>
    </visual>
    <collision>
      <origin rpy="0 0 0" xyz="0 0 0"/>
      <geometry>
        <sphere radius="0.022"/>
      </geometry>
    </collision>
    <inertial>
      <mass value="0.026"/>
      <inertia ixx="0.0" ixy="0.0" ixz="0.0" iyy="0.0" iyz="0.0" izz="0.0"/>
    </inertial>
  </link>

  <transmission name="transmission_11">
    <type>transmission_interface/SimpleTransmission</type>
    <joint name="11">
      <hardwareInterface>hardware_interface/EffortJointInterface</hardwareInterface>
    </joint>
    <actuator name="motor_11">
      <hardwareInterface>hardware_interface/EffortJointInterface</hardwareInterface>
      <mechanicalReduction>1</mechanicalReduction>
    </actuator>
  </transmission>
  <transmission name="transmission_6">
    <type>transmission_interface/SimpleTransmission</type>
    <joint name="6">
      <hardwareInterface>hardware_interface/EffortJointInterface</hardwareInterface>
    </joint>
    <actuator name="motor_6">
      <hardwareInterface>hardware_interface/EffortJointInterface</hardwareInterface>
      <mechanicalReduction>1</mechanicalReduction>
    </actuator>
  </transmission>
  <transmission name="transmission_7">
    <type>transmission_interface/SimpleTransmission</type>
    <joint name="7">
      <hardwareInterface>hardware_interface/EffortJointInterface</hardwareInterface>
    </joint>
    <actuator name="motor_7">
      <hardwareInterface>hardware_interface/EffortJointInterface</hardwareInterface>
      <mechanicalReduction>1</mechanicalReduction>
    </actuator>
  </transmission>

  <gazebo reference='jtoe0'>
    <preserveFixedJoint>true</preserveFixedJoint>
  </gazebo>
  <gazebo reference='jtoe1'>
    <preserveFixedJoint>true</preserveFixedJoint>
  </gazebo>
  <gazebo reference='jtoe2'>
    <preserveFixedJoint>true</preserveFixedJoint>
  </gazebo>
  <gazebo reference='jtoe3'>
    <preserveFixedJoint>true</preserveFixedJoint>
  </gazebo>

</robot>