<sdf version='1.7'>
  <model name='ylo2'>
    <link name='trunk'>
      <pose relative_to='floating_base_joint'>0 0 0 0 -0 0</pose>
      <inertial>
        <pose>0.019994 0.001939 0 0 -0 0</pose>
        <mass>3.129</mass>
        <inertia>
          <ixx>0.01595</ixx>
          <ixy>-0.000133239</ixy>
          <ixz>-0.0002403</ixz>
          <iyy>0.0416814</iyy>
          <iyz>1.5299e-05</iyz>
          <izz>0.0475204</izz>
        </inertia>
      </inertial>
      <collision name='trunk_collision'>
        <pose>0 0 0 0 -0 0</pose>
        <geometry>
          <mesh>
            <scale>1 1 1</scale>
            <uri>model://ylo2_description/meshes/body/covers_collision.stl</uri>
          </mesh>
        </geometry>
      </collision>
      <collision name='trunk_imu_collision_1'>
        <pose>0 0 0 0 -0 0</pose>
        <geometry>
          <box>
            <size>0.001 0.001 0.001</size>
          </box>
        </geometry>
      </collision>
      <visual name='trunk_visual'>
        <pose>0 0 0 0 -0 0</pose>
        <geometry>
          <mesh>
            <scale>1 1 1</scale>
            <uri>model://ylo2_description/meshes/body/textured/ylo2_textured_body.dae</uri>
          </mesh>
        </geometry>
      </visual>
      <visual name='trunk_fixed_joint_lump__D435_visual_1'>
        <pose>0 0.004 0 0 -0 0</pose>
        <geometry>
          <mesh>
            <scale>1 1 1</scale>
            <uri>model://ylo2_description/meshes/body/textured/ylo2_d435_textured.dae</uri>
          </mesh>
        </geometry>
      </visual>
      <visual name='trunk_fixed_joint_lump__T265_visual_2'>
        <pose>0.001 0.0025 0 0 -0 0</pose>
        <geometry>
          <mesh>
            <scale>1 1.06 1.04</scale>
            <uri>model://ylo2_description/meshes/body/textured/ylo2_t265_textured.dae</uri>
          </mesh>
        </geometry>
      </visual>
      <visual name='trunk_fixed_joint_lump__abad_motors_visual_3'>
        <pose>0 0 0 0 -0 0</pose>
        <geometry>
          <mesh>
            <scale>1 1 1</scale>
            <uri>model://ylo2_description/meshes/body/textured/ylo2_textured_abad_motors.dae</uri>
          </mesh>
        </geometry>
      </visual>
      <visual name='trunk_fixed_joint_lump__accessories_visual_4'>
        <pose>0 0 0 0 -0 0</pose>
        <geometry>
          <mesh>
            <scale>1 1 1</scale>
            <uri>model://ylo2_description/meshes/body/textured/accessories.dae</uri>
          </mesh>
        </geometry>
      </visual>
      <visual name='trunk_fixed_joint_lump__battery_visual_5'>
        <pose>0 0 0 0 -0 0</pose>
        <geometry>
          <mesh>
            <scale>1 1 1</scale>
            <uri>model://ylo2_description/meshes/body/battery.stl</uri>
          </mesh>
        </geometry>
      </visual>
      <visual name='trunk_fixed_joint_lump__covers_visual_6'>
        <pose>0 0 0 0 -0 0</pose>
        <geometry>
          <mesh>
            <scale>1 1 1</scale>
            <uri>model://ylo2_description/meshes/body/textured/ylo2_textured_cover.dae</uri>
          </mesh>
        </geometry>
      </visual>
      <visual name='trunk_imu_visual_7'>
        <pose>0 0 0 0 -0 0</pose>
        <geometry>
          <box>
            <size>0.001 0.001 0.001</size>
          </box>
        </geometry>
      </visual>
    </link>
    <joint name='lf_haa_joint' type='revolute'>
      <pose relative_to='trunk'>0.1745 0.0632 0.023 0 -0 0</pose>
      <parent>trunk</parent>
      <child>lf_hip</child>
      <axis>
        <xyz>1 0 0</xyz>
        <limit>
          <lower>-1.22173</lower>
          <upper>1.22173</upper>
          <effort>14</effort>
          <velocity>20</velocity>
        </limit>
        <dynamics>
          <damping>0</damping>
          <friction>0</friction>
          <spring_reference>0</spring_reference>
          <spring_stiffness>0</spring_stiffness>
        </dynamics>
      </axis>
    </joint>
    <link name='lf_hip'>
      <pose relative_to='lf_haa_joint'>0 0 0 0 -0 0</pose>
      <inertial>
        <pose>-0.011957 0.000306 0.000366 0 -0 0</pose>
        <mass>0.599</mass>
        <inertia>
          <ixx>0.0004159</ixx>
          <ixy>4.253e-06</ixy>
          <ixz>3.68e-07</ixz>
          <iyy>0.0007108</iyy>
          <iyz>2.15e-07</iyz>
          <izz>0.0004707</izz>
        </inertia>
      </inertial>
      <visual name='lf_hip_visual'>
        <pose>-0.06 0 0 0 -0 0</pose>
        <geometry>
          <mesh>
            <scale>1 1 1</scale>
            <uri>model://ylo2_description/meshes/leg/textured/ylo2texturedhip.dae</uri>
          </mesh>
        </geometry>
      </visual>
    </link>
    <joint name='lf_hfe_joint' type='revolute'>
      <pose relative_to='lf_hip'>0 0.092 0 0 -0 0</pose>
      <parent>lf_hip</parent>
      <child>lf_upperleg</child>
      <axis>
        <xyz>0 1 0</xyz>
        <limit>
          <effort>14</effort>
          <velocity>20</velocity>
          <lower>-1e+16</lower>
          <upper>1e+16</upper>
        </limit>
        <dynamics>
          <damping>0</damping>
          <friction>0</friction>
          <spring_reference>0</spring_reference>
          <spring_stiffness>0</spring_stiffness>
        </dynamics>
      </axis>
    </joint>
    <link name='lf_upperleg'>
      <pose relative_to='lf_hfe_joint'>0 0 0 0 -0 0</pose>
      <inertial>
        <pose>-0.000684 -0.010999 -0.035487 0 -0 0</pose>
        <mass>1.08</mass>
        <inertia>
          <ixx>0.0056668</ixx>
          <ixy>3.597e-06</ixy>
          <ixz>0.000491446</ixz>
          <iyy>0.00584723</iyy>
          <iyz>1.0086e-05</iyz>
          <izz>0.000369811</izz>
        </inertia>
      </inertial>
      <collision name='lf_upperleg_collision'>
        <pose>0 -0.0732 0 0 -0 0</pose>
        <geometry>
          <mesh>
            <scale>1 1 1</scale>
            <uri>model://ylo2_description/meshes/leg/fl_upper_leg_collision.stl</uri>
          </mesh>
        </geometry>
      </collision>
      <visual name='lf_upperleg_visual'>
        <pose>0 -0.0732 0 0 -0 0</pose>
        <geometry>
          <mesh>
            <scale>1 1 1</scale>
            <uri>model://ylo2_description/meshes/leg/textured/ylo2_textured_upper_leg.dae</uri>
          </mesh>
        </geometry>
      </visual>
    </link>
    <joint name='lf_kfe_joint' type='revolute'>
      <pose relative_to='lf_upperleg'>0 -0.001 -0.215427 0 -0 0</pose>
      <parent>lf_upperleg</parent>
      <child>lf_lowerleg</child>
      <axis>
        <xyz>0 1 0</xyz>
        <limit>
          <lower>-2.77507</lower>
          <upper>-0.645772</upper>
          <effort>14</effort>
          <velocity>15</velocity>
        </limit>
        <dynamics>
          <damping>0</damping>
          <friction>0</friction>
          <spring_reference>0</spring_reference>
          <spring_stiffness>0</spring_stiffness>
        </dynamics>
      </axis>
    </joint>
    <link name='lf_lowerleg'>
      <pose relative_to='lf_kfe_joint'>0 0 0 0 -0 0</pose>
      <inertial>
        <pose>-0.00206 0.000163 -0.118564 0 -0 0</pose>
        <mass>0.253</mass>
        <inertia>
          <ixx>0.00300928</ixx>
          <ixy>-1.58263e-07</ixy>
          <ixz>-6.5362e-05</ixz>
          <iyy>0.0030222</iyy>
          <iyz>-1.0116e-06</iyz>
          <izz>4.62038e-05</izz>
        </inertia>
      </inertial>
      <collision name='lf_lowerleg_collision'>
        <pose>0 0.001 0 0 -0 0</pose>
        <geometry>
          <mesh>
            <scale>1 -1 1</scale>
            <uri>model://ylo2_description/meshes/leg/fl_lower_leg_collision.stl</uri>
          </mesh>
        </geometry>
      </collision>
      <collision name='lf_lowerleg_fixed_joint_lump__lf_foot_collision_1'>
        <pose>0.009 0.002 -0.160819 0 -0 0</pose>
        <geometry>
          <mesh>
            <scale>1 1 1</scale>
            <uri>model://ylo2_description/meshes/leg/fl_foot_collision.stl</uri>
          </mesh>
        </geometry>
      </collision>
      <visual name='lf_lowerleg_visual'>
        <pose>0 0.001 0 0 -0 0</pose>
        <geometry>
          <mesh>
            <scale>1 1 1</scale>
            <uri>model://ylo2_description/meshes/leg/textured/lower_leg.dae</uri>
          </mesh>
        </geometry>
      </visual>
      <visual name='lf_lowerleg_fixed_joint_lump__lf_foot_visual_1'>
        <pose>0.009 0.002 -0.160819 0 -0 0</pose>
        <geometry>
          <mesh>
            <scale>1 1 1</scale>
            <uri>model://ylo2_description/meshes/leg/fl_foot.dae</uri>
          </mesh>
        </geometry>
      </visual>
    </link>
    <joint name='lh_haa_joint' type='revolute'>
      <pose relative_to='trunk'>-0.2125 0.0632 0.023 0 -0 0</pose>
      <parent>trunk</parent>
      <child>lh_hip</child>
      <axis>
        <xyz>1 0 0</xyz>
        <limit>
          <lower>-1.22173</lower>
          <upper>1.22173</upper>
          <effort>14</effort>
          <velocity>20</velocity>
        </limit>
        <dynamics>
          <damping>0</damping>
          <friction>0</friction>
          <spring_reference>0</spring_reference>
          <spring_stiffness>0</spring_stiffness>
        </dynamics>
      </axis>
    </joint>
    <link name='lh_hip'>
      <pose relative_to='lh_haa_joint'>0 0 0 0 -0 0</pose>
      <inertial>
        <pose>0.011957 0.000306 0.000366 0 -0 0</pose>
        <mass>0.599</mass>
        <inertia>
          <ixx>0.0004159</ixx>
          <ixy>-4.253e-06</ixy>
          <ixz>-3.68e-07</ixz>
          <iyy>0.0007108</iyy>
          <iyz>2.15e-07</iyz>
          <izz>0.0004707</izz>
        </inertia>
      </inertial>
      <visual name='lh_hip_visual'>
        <pose>0.06 0 0 3.14159 0 3.14159</pose>
        <geometry>
          <mesh>
            <scale>1 1 1</scale>
            <uri>model://ylo2_description/meshes/leg/textured/ylo2texturedhip.dae</uri>
          </mesh>
        </geometry>
      </visual>
    </link>
    <joint name='lh_hfe_joint' type='revolute'>
      <pose relative_to='lh_hip'>0 0.092 0 0 -0 0</pose>
      <parent>lh_hip</parent>
      <child>lh_upperleg</child>
      <axis>
        <xyz>0 1 0</xyz>
        <limit>
          <effort>14</effort>
          <velocity>20</velocity>
          <lower>-1e+16</lower>
          <upper>1e+16</upper>
        </limit>
        <dynamics>
          <damping>0</damping>
          <friction>0</friction>
          <spring_reference>0</spring_reference>
          <spring_stiffness>0</spring_stiffness>
        </dynamics>
      </axis>
    </joint>
    <link name='lh_upperleg'>
      <pose relative_to='lh_hfe_joint'>0 0 0 0 -0 0</pose>
      <inertial>
        <pose>-0.000684 -0.010999 -0.035487 0 -0 0</pose>
        <mass>1.08</mass>
        <inertia>
          <ixx>0.0056668</ixx>
          <ixy>3.597e-06</ixy>
          <ixz>0.000491446</ixz>
          <iyy>0.00584723</iyy>
          <iyz>1.0086e-05</iyz>
          <izz>0.000369811</izz>
        </inertia>
      </inertial>
      <collision name='lh_upperleg_collision'>
        <pose>0 -0.0732 0 0 -0 0</pose>
        <geometry>
          <mesh>
            <scale>1 1 1</scale>
            <uri>model://ylo2_description/meshes/leg/fl_upper_leg_collision.stl</uri>
          </mesh>
        </geometry>
      </collision>
      <visual name='lh_upperleg_visual'>
        <pose>0 -0.0732 0 0 -0 0</pose>
        <geometry>
          <mesh>
            <scale>1 1 1</scale>
            <uri>model://ylo2_description/meshes/leg/textured/ylo2_textured_upper_leg.dae</uri>
          </mesh>
        </geometry>
      </visual>
    </link>
    <joint name='lh_kfe_joint' type='revolute'>
      <pose relative_to='lh_upperleg'>0 -0.001 -0.215427 0 -0 0</pose>
      <parent>lh_upperleg</parent>
      <child>lh_lowerleg</child>
      <axis>
        <xyz>0 1 0</xyz>
        <limit>
          <lower>-2.77507</lower>
          <upper>-0.645772</upper>
          <effort>14</effort>
          <velocity>15</velocity>
        </limit>
        <dynamics>
          <damping>0</damping>
          <friction>0</friction>
          <spring_reference>0</spring_reference>
          <spring_stiffness>0</spring_stiffness>
        </dynamics>
      </axis>
    </joint>
    <link name='lh_lowerleg'>
      <pose relative_to='lh_kfe_joint'>0 0 0 0 -0 0</pose>
      <inertial>
        <pose>-0.00206 0.000163 -0.118564 0 -0 0</pose>
        <mass>0.253</mass>
        <inertia>
          <ixx>0.00300928</ixx>
          <ixy>-1.58263e-07</ixy>
          <ixz>-6.5362e-05</ixz>
          <iyy>0.0030222</iyy>
          <iyz>-1.0116e-06</iyz>
          <izz>4.62038e-05</izz>
        </inertia>
      </inertial>
      <collision name='lh_lowerleg_collision'>
        <pose>0 0.001 0 0 -0 0</pose>
        <geometry>
          <mesh>
            <scale>1 -1 1</scale>
            <uri>model://ylo2_description/meshes/leg/fl_lower_leg_collision.stl</uri>
          </mesh>
        </geometry>
      </collision>
      <collision name='lh_lowerleg_fixed_joint_lump__lh_foot_collision_1'>
        <pose>0.009 0.002 -0.160819 0 -0 0</pose>
        <geometry>
          <mesh>
            <scale>1 1 1</scale>
            <uri>model://ylo2_description/meshes/leg/fl_foot_collision.stl</uri>
          </mesh>
        </geometry>
      </collision>
      <visual name='lh_lowerleg_visual'>
        <pose>0 0.001 0 0 -0 0</pose>
        <geometry>
          <mesh>
            <scale>1 1 1</scale>
            <uri>model://ylo2_description/meshes/leg/textured/lower_leg.dae</uri>
          </mesh>
        </geometry>
      </visual>
      <visual name='lh_lowerleg_fixed_joint_lump__lh_foot_visual_1'>
        <pose>0.009 0.002 -0.160819 0 -0 0</pose>
        <geometry>
          <mesh>
            <scale>1 1 1</scale>
            <uri>model://ylo2_description/meshes/leg/fl_foot.dae</uri>
          </mesh>
        </geometry>
      </visual>
    </link>
    <joint name='rf_haa_joint' type='revolute'>
      <pose relative_to='trunk'>0.1745 -0.0512 0.023 0 -0 0</pose>
      <parent>trunk</parent>
      <child>rf_hip</child>
      <axis>
        <xyz>1 0 0</xyz>
        <limit>
          <lower>-1.22173</lower>
          <upper>1.22173</upper>
          <effort>14</effort>
          <velocity>20</velocity>
        </limit>
        <dynamics>
          <damping>0</damping>
          <friction>0</friction>
          <spring_reference>0</spring_reference>
          <spring_stiffness>0</spring_stiffness>
        </dynamics>
      </axis>
    </joint>
    <link name='rf_hip'>
      <pose relative_to='rf_haa_joint'>0 0 0 0 -0 0</pose>
      <inertial>
        <pose>-0.011957 -0.000306 0.000366 0 -0 0</pose>
        <mass>0.599</mass>
        <inertia>
          <ixx>0.0004159</ixx>
          <ixy>-4.253e-06</ixy>
          <ixz>3.68e-07</ixz>
          <iyy>0.0007108</iyy>
          <iyz>-2.15e-07</iyz>
          <izz>0.0004707</izz>
        </inertia>
      </inertial>
      <visual name='rf_hip_visual'>
        <pose>-0.06 0 0 3.14159 -0 0</pose>
        <geometry>
          <mesh>
            <scale>1 1 1</scale>
            <uri>model://ylo2_description/meshes/leg/textured/ylo2texturedhip.dae</uri>
          </mesh>
        </geometry>
      </visual>
    </link>
    <joint name='rf_hfe_joint' type='revolute'>
      <pose relative_to='rf_hip'>0 -0.092 0 0 -0 0</pose>
      <parent>rf_hip</parent>
      <child>rf_upperleg</child>
      <axis>
        <xyz>0 1 0</xyz>
        <limit>
          <effort>14</effort>
          <velocity>20</velocity>
          <lower>-1e+16</lower>
          <upper>1e+16</upper>
        </limit>
        <dynamics>
          <damping>0</damping>
          <friction>0</friction>
          <spring_reference>0</spring_reference>
          <spring_stiffness>0</spring_stiffness>
        </dynamics>
      </axis>
    </joint>
    <link name='rf_upperleg'>
      <pose relative_to='rf_hfe_joint'>0 0 0 0 -0 0</pose>
      <inertial>
        <pose>-0.000684 0.010999 -0.035487 0 -0 0</pose>
        <mass>1.08</mass>
        <inertia>
          <ixx>0.0056668</ixx>
          <ixy>-3.597e-06</ixy>
          <ixz>0.000491446</ixz>
          <iyy>0.00584723</iyy>
          <iyz>-1.0086e-05</iyz>
          <izz>0.000369811</izz>
        </inertia>
      </inertial>
      <collision name='rf_upperleg_collision'>
        <pose>0 0.0732 0 0 -0 0</pose>
        <geometry>
          <mesh>
            <scale>1 -1 1</scale>
            <uri>model://ylo2_description/meshes/leg/fl_upper_leg_collision.stl</uri>
          </mesh>
        </geometry>
      </collision>
      <visual name='rf_upperleg_visual'>
        <pose>0 0.0732 0 0 -0 0</pose>
        <geometry>
          <mesh>
            <scale>1 -1 1</scale>
            <uri>model://ylo2_description/meshes/leg/textured/ylo2_textured_upper_leg.dae</uri>
          </mesh>
        </geometry>
      </visual>
    </link>
    <joint name='rf_kfe_joint' type='revolute'>
      <pose relative_to='rf_upperleg'>0 -0.001 -0.215427 0 -0 0</pose>
      <parent>rf_upperleg</parent>
      <child>rf_lowerleg</child>
      <axis>
        <xyz>0 1 0</xyz>
        <limit>
          <lower>-2.77507</lower>
          <upper>-0.645772</upper>
          <effort>14</effort>
          <velocity>15</velocity>
        </limit>
        <dynamics>
          <damping>0</damping>
          <friction>0</friction>
          <spring_reference>0</spring_reference>
          <spring_stiffness>0</spring_stiffness>
        </dynamics>
      </axis>
    </joint>
    <link name='rf_lowerleg'>
      <pose relative_to='rf_kfe_joint'>0 0 0 0 -0 0</pose>
      <inertial>
        <pose>-0.00206 0.000163 -0.118564 0 -0 0</pose>
        <mass>0.253</mass>
        <inertia>
          <ixx>0.00300928</ixx>
          <ixy>-1.58263e-07</ixy>
          <ixz>-6.5362e-05</ixz>
          <iyy>0.0030222</iyy>
          <iyz>-1.0116e-06</iyz>
          <izz>4.62038e-05</izz>
        </inertia>
      </inertial>
      <collision name='rf_lowerleg_collision'>
        <pose>0 -0.001 0 0 -0 0</pose>
        <geometry>
          <mesh>
            <scale>1 -1 1</scale>
            <uri>model://ylo2_description/meshes/leg/fl_lower_leg_collision.stl</uri>
          </mesh>
        </geometry>
      </collision>
      <collision name='rf_lowerleg_fixed_joint_lump__rf_foot_collision_1'>
        <pose>0.009 0 -0.160819 0 -0 0</pose>
        <geometry>
          <mesh>
            <scale>1 1 1</scale>
            <uri>model://ylo2_description/meshes/leg/fl_foot_collision.stl</uri>
          </mesh>
        </geometry>
      </collision>
      <visual name='rf_lowerleg_visual'>
        <pose>0 -0.001 0 0 -0 0</pose>
        <geometry>
          <mesh>
            <scale>1 1 1</scale>
            <uri>model://ylo2_description/meshes/leg/textured/lower_leg.dae</uri>
          </mesh>
        </geometry>
      </visual>
      <visual name='rf_lowerleg_fixed_joint_lump__rf_foot_visual_1'>
        <pose>0.009 0 -0.160819 0 -0 0</pose>
        <geometry>
          <mesh>
            <scale>1 1 1</scale>
            <uri>model://ylo2_description/meshes/leg/fl_foot.dae</uri>
          </mesh>
        </geometry>
      </visual>
    </link>
    <joint name='rh_haa_joint' type='revolute'>
      <pose relative_to='trunk'>-0.2125 -0.0512 0.023 0 -0 0</pose>
      <parent>trunk</parent>
      <child>rh_hip</child>
      <axis>
        <xyz>1 0 0</xyz>
        <limit>
          <lower>-1.22173</lower>
          <upper>1.22173</upper>
          <effort>14</effort>
          <velocity>20</velocity>
        </limit>
        <dynamics>
          <damping>0</damping>
          <friction>0</friction>
          <spring_reference>0</spring_reference>
          <spring_stiffness>0</spring_stiffness>
        </dynamics>
      </axis>
    </joint>
    <link name='rh_hip'>
      <pose relative_to='rh_haa_joint'>0 0 0 0 -0 0</pose>
      <inertial>
        <pose>0.011957 -0.000306 0.000366 0 -0 0</pose>
        <mass>0.599</mass>
        <inertia>
          <ixx>0.0004159</ixx>
          <ixy>4.253e-06</ixy>
          <ixz>-3.68e-07</ixz>
          <iyy>0.0007108</iyy>
          <iyz>-2.15e-07</iyz>
          <izz>0.0004707</izz>
        </inertia>
      </inertial>
      <visual name='rh_hip_visual'>
        <pose>0.06 0 0 -0 0 3.14159</pose>
        <geometry>
          <mesh>
            <scale>1 1 1</scale>
            <uri>model://ylo2_description/meshes/leg/textured/ylo2texturedhip.dae</uri>
          </mesh>
        </geometry>
      </visual>
    </link>
    <joint name='rh_hfe_joint' type='revolute'>
      <pose relative_to='rh_hip'>0 -0.092 0 0 -0 0</pose>
      <parent>rh_hip</parent>
      <child>rh_upperleg</child>
      <axis>
        <xyz>0 1 0</xyz>
        <limit>
          <effort>14</effort>
          <velocity>20</velocity>
          <lower>-1e+16</lower>
          <upper>1e+16</upper>
        </limit>
        <dynamics>
          <damping>0</damping>
          <friction>0</friction>
          <spring_reference>0</spring_reference>
          <spring_stiffness>0</spring_stiffness>
        </dynamics>
      </axis>
    </joint>
    <link name='rh_upperleg'>
      <pose relative_to='rh_hfe_joint'>0 0 0 0 -0 0</pose>
      <inertial>
        <pose>-0.000684 0.010999 -0.035487 0 -0 0</pose>
        <mass>1.08</mass>
        <inertia>
          <ixx>0.0056668</ixx>
          <ixy>-3.597e-06</ixy>
          <ixz>0.000491446</ixz>
          <iyy>0.00584723</iyy>
          <iyz>-1.0086e-05</iyz>
          <izz>0.000369811</izz>
        </inertia>
      </inertial>
      <collision name='rh_upperleg_collision'>
        <pose>0 0.0732 0 0 -0 0</pose>
        <geometry>
          <mesh>
            <scale>1 -1 1</scale>
            <uri>model://ylo2_description/meshes/leg/fl_upper_leg_collision.stl</uri>
          </mesh>
        </geometry>
      </collision>
      <visual name='rh_upperleg_visual'>
        <pose>0 0.0732 0 0 -0 0</pose>
        <geometry>
          <mesh>
            <scale>1 -1 1</scale>
            <uri>model://ylo2_description/meshes/leg/textured/ylo2_textured_upper_leg.dae</uri>
          </mesh>
        </geometry>
      </visual>
    </link>
    <joint name='rh_kfe_joint' type='revolute'>
      <pose relative_to='rh_upperleg'>0 -0.001 -0.215427 0 -0 0</pose>
      <parent>rh_upperleg</parent>
      <child>rh_lowerleg</child>
      <axis>
        <xyz>0 1 0</xyz>
        <limit>
          <lower>-2.77507</lower>
          <upper>-0.645772</upper>
          <effort>14</effort>
          <velocity>15</velocity>
        </limit>
        <dynamics>
          <damping>0</damping>
          <friction>0</friction>
          <spring_reference>0</spring_reference>
          <spring_stiffness>0</spring_stiffness>
        </dynamics>
      </axis>
    </joint>
    <link name='rh_lowerleg'>
      <pose relative_to='rh_kfe_joint'>0 0 0 0 -0 0</pose>
      <inertial>
        <pose>-0.00206 0.000163 -0.118564 0 -0 0</pose>
        <mass>0.253</mass>
        <inertia>
          <ixx>0.00300928</ixx>
          <ixy>-1.58263e-07</ixy>
          <ixz>-6.5362e-05</ixz>
          <iyy>0.0030222</iyy>
          <iyz>-1.0116e-06</iyz>
          <izz>4.62038e-05</izz>
        </inertia>
      </inertial>
      <collision name='rh_lowerleg_collision'>
        <pose>0 -0.001 0 0 -0 0</pose>
        <geometry>
          <mesh>
            <scale>1 -1 1</scale>
            <uri>model://ylo2_description/meshes/leg/fl_lower_leg_collision.stl</uri>
          </mesh>
        </geometry>
      </collision>
      <collision name='rh_lowerleg_fixed_joint_lump__rh_foot_collision_1'>
        <pose>0.009 0 -0.160819 0 -0 0</pose>
        <geometry>
          <mesh>
            <scale>1 1 1</scale>
            <uri>model://ylo2_description/meshes/leg/fl_foot_collision.stl</uri>
          </mesh>
        </geometry>
      </collision>
      <visual name='rh_lowerleg_visual'>
        <pose>0 -0.001 0 0 -0 0</pose>
        <geometry>
          <mesh>
            <scale>1 1 1</scale>
            <uri>model://ylo2_description/meshes/leg/textured/lower_leg.dae</uri>
          </mesh>
        </geometry>
      </visual>
      <visual name='rh_lowerleg_fixed_joint_lump__rh_foot_visual_1'>
        <pose>0.009 0 -0.160819 0 -0 0</pose>
        <geometry>
          <mesh>
            <scale>1 1 1</scale>
            <uri>model://ylo2_description/meshes/leg/fl_foot.dae</uri>
          </mesh>
        </geometry>
      </visual>
    </link>
    <frame name='D435_joint' attached_to='trunk'>
      <pose>0 0 0 0 -0 0</pose>
    </frame>
    <frame name='D435' attached_to='D435_joint'/>
    <frame name='T265_joint' attached_to='trunk'>
      <pose>0 0 0 0 -0 0</pose>
    </frame>
    <frame name='T265' attached_to='T265_joint'/>
    <frame name='abad_motors_joint' attached_to='trunk'>
      <pose>0 0 0 0 -0 0</pose>
    </frame>
    <frame name='abad_motors' attached_to='abad_motors_joint'/>
    <frame name='accessories_joint' attached_to='trunk'>
      <pose>0 0 0 0 -0 0</pose>
    </frame>
    <frame name='accessories' attached_to='accessories_joint'/>
    <frame name='battery_joint' attached_to='trunk'>
      <pose>0 0 0 0 -0 0</pose>
    </frame>
    <frame name='battery' attached_to='battery_joint'/>
    <frame name='covers_joint' attached_to='trunk'>
      <pose>0 0 0 0 -0 0</pose>
    </frame>
    <frame name='covers' attached_to='covers_joint'/>
    <frame name='imu_joint' attached_to='trunk'>
      <pose>0 0 0 0 -0 0</pose>
    </frame>
    <frame name='trunk_imu' attached_to='imu_joint'/>
    <frame name='lf_foot_fixed' attached_to='lf_lowerleg'>
      <pose>0 0 -0.229819 0 -0 0</pose>
    </frame>
    <frame name='lf_foot' attached_to='lf_foot_fixed'/>
    <frame name='lh_foot_fixed' attached_to='lh_lowerleg'>
      <pose>0 0 -0.229819 0 -0 0</pose>
    </frame>
    <frame name='lh_foot' attached_to='lh_foot_fixed'/>
    <frame name='rf_foot_fixed' attached_to='rf_lowerleg'>
      <pose>0 0 -0.229819 0 -0 0</pose>
    </frame>
    <frame name='rf_foot' attached_to='rf_foot_fixed'/>
    <frame name='rh_foot_fixed' attached_to='rh_lowerleg'>
      <pose>0 0 -0.229819 0 -0 0</pose>
    </frame>
    <frame name='rh_foot' attached_to='rh_foot_fixed'/>
  </model>
</sdf>
