<sdf version='1.6'>
  <model name='ylo2_description'>
    <link name='body'>
      <inertial>
        <pose>0.0325 0.007369 0.033157 0 -0 0</pose>
        <mass>4.077</mass>
        <inertia>
          <ixx>0.0199227</ixx>
          <ixy>-3.01296e-05</ixy>
          <ixz>-0.000376678</ixz>
          <iyy>0.078297</iyy>
          <iyz>-1.27744e-05</iyz>
          <izz>0.0842236</izz>
        </inertia>
      </inertial>
      <collision name='body_fixed_joint_lump__trunk_collision'>
        <pose>-0.02 0.003 0.024 0 -0 0</pose>
        <geometry>
          <box>
            <size>0.26 0.18 0.14</size>
          </box>
        </geometry>
        <surface>
          <contact>
            <ode>
              <kp>1e+06</kp>
              <kd>1</kd>
            </ode>
          </contact>
          <friction>
            <ode>
              <mu>0.2</mu>
              <mu2>0.2</mu2>
            </ode>
          </friction>
        </surface>
      </collision>
      <collision name='body_fixed_joint_lump__imu_link_collision_1'>
        <pose>0 0 0 0 -0 0</pose>
        <geometry>
          <box>
            <size>0.001 0.001 0.001</size>
          </box>
        </geometry>
        <surface>
          <contact>
            <ode/>
          </contact>
          <friction>
            <ode>
              <mu>0.2</mu>
              <mu2>0.2</mu2>
            </ode>
          </friction>
        </surface>
      </collision>
      <visual name='body_visual'>
        <pose>0 0 0 0 -0 0</pose>
        <geometry>
          <box>
            <size>0.001 0.001 0.001</size>
          </box>
        </geometry>
        <material>
          <script>
            <name>Gazebo/Green</name>
            <uri>file://media/materials/scripts/gazebo.material</uri>
          </script>
        </material>
      </visual>
      <visual name='body_visual_visual_1'>
        <pose>0 0 0 0 -0 0</pose>
        <geometry>
          <mesh>
            <scale>1 1 1</scale>
            <uri>model://ylo2_description/meshes/body/textured/ylo2_textured_body.dae</uri>
          </mesh>
        </geometry>
        <material>
          <script>
            <name>Gazebo/Green</name>
            <uri>file://media/materials/scripts/gazebo.material</uri>
          </script>
        </material>
      </visual>
      <visual name='body_fixed_joint_lump__abad_motors_visual_2'>
        <pose>0 0 0 0 -0 0</pose>
        <geometry>
          <mesh>
            <scale>1 1 1</scale>
            <uri>model://ylo2_description/meshes/body/textured/ylo2_textured_abad_motors.dae</uri>
          </mesh>
        </geometry>
      </visual>
      <visual name='body_fixed_joint_lump__accessories_visual_3'>
        <pose>0 0 0 0 -0 0</pose>
        <geometry>
          <mesh>
            <scale>1 1 1</scale>
            <uri>model://ylo2_description/meshes/body/textured/accessories.dae</uri>
          </mesh>
        </geometry>
      </visual>
      <visual name='body_fixed_joint_lump__battery_visual_4'>
        <pose>0 0 0 0 -0 0</pose>
        <geometry>
          <mesh>
            <scale>1 1 1</scale>
            <uri>model://ylo2_description/meshes/body/battery.stl</uri>
          </mesh>
        </geometry>
      </visual>
      <visual name='body_fixed_joint_lump__covers_visual_5'>
        <pose>0 0 0 0 -0 0</pose>
        <geometry>
          <mesh>
            <scale>1 1 1</scale>
            <uri>model://ylo2_description/meshes/body/textured/ylo2_textured_cover.dae</uri>
          </mesh>
        </geometry>
      </visual>
      <visual name='body_fixed_joint_lump__d435_visual_6'>
        <pose>0 0.003 0 0 -0 0</pose>
        <geometry>
          <mesh>
            <scale>1 1 1</scale>
            <uri>model://ylo2_description/meshes/body/textured/ylo2_d435_textured.dae</uri>
          </mesh>
        </geometry>
      </visual>
      <visual name='body_fixed_joint_lump__imu_link_visual_7'>
        <pose>0 0 0 0 -0 0</pose>
        <geometry>
          <box>
            <size>0.001 0.001 0.001</size>
          </box>
        </geometry>
        <material>
          <script>
            <name>Gazebo/Red</name>
            <uri>file://media/materials/scripts/gazebo.material</uri>
          </script>
        </material>
      </visual>
      <visual name='body_fixed_joint_lump__t265_visual_8'>
        <pose>0.002 0.0025 0 0 -0 0</pose>
        <geometry>
          <mesh>
            <scale>1 1.06 1.04</scale>
            <uri>model://ylo2_description/meshes/body/textured/ylo2_t265_textured.dae</uri>
          </mesh>
        </geometry>
      </visual>
      <gravity>1</gravity>
      <gravity>1</gravity>
      <sensor name='imu_sensor' type='imu'>
        <always_on>1</always_on>
        <update_rate>1000</update_rate>
        <visualize>1</visualize>
        <topic>__default_topic__</topic>
        <plugin name='imu_plugin' filename='libgazebo_ros_imu_sensor.so'>
          <topicName>trunk_imu</topicName>
          <bodyName>imu_link</bodyName>
          <updateRateHZ>1000.0</updateRateHZ>
          <gaussianNoise>0.0</gaussianNoise>
          <xyzOffset>0 0 0</xyzOffset>
          <rpyOffset>0 0 0</rpyOffset>
          <frameName>imu_link</frameName>
        </plugin>
        <pose>0 0 0 0 -0 0</pose>
      </sensor>
    </link>


    <link name='hip2'>
      <pose frame=''>0.1805 -0.047 0 0 -0 0</pose>
      <inertial>
        <pose frame=''>-0.011957 0.000306 0.000366 0 -0 0</pose>
        <mass>0.599</mass>
        <inertia>
          <ixx>0.0004159</ixx>
          <ixy>0.000004253</ixy>
          <ixz>0.000000368</ixz>
          <iyy>0.0007108</iyy>
          <iyz>0.000000215</iyz>
          <izz>0.0004707</izz>
        </inertia>
      </inertial>
      <collision name='hip2_collision_collision'>
        <pose frame=''>0 0 0 1.5708 -0 0</pose>
        <geometry>
          <cylinder>
            <length>0.04</length>
            <radius>0.046</radius>
          </cylinder>
        </geometry>
        <surface>
          <contact>
            <ode/>
          </contact>
          <friction>
            <ode>
              <mu>0.5</mu>
              <mu2>0.5</mu2>
            </ode>
          </friction>
        </surface>
      </collision>
      <visual name='hip2_visual_visual'>
        <pose frame=''>0 0 0 -3.14159 -0 0</pose>
        <geometry>
          <mesh>
            <scale>1 1 1</scale>
            <uri>model://ylo2_description/meshes/leg/textured/ylo2texturedhip.dae</uri>
          </mesh>
        </geometry>
        <material>
          <script>
            <name>Gazebo/DarkGrey</name>
            <uri>file://media/materials/scripts/gazebo.material</uri>
          </script>
        </material>
      </visual>
      <gravity>1</gravity>
      <velocity_decay/>
    </link>


    <joint name='10' type='revolute'>
      <child>hip2</child>
      <parent>body</parent>
      <axis>
        <xyz>1 0 0</xyz>
        <limit>
          <lower>-0.802851</lower>
          <upper>0.802851</upper>
          <effort>33.5</effort>
          <velocity>21</velocity>
        </limit>
        <dynamics>
          <damping>0</damping>
          <friction>0</friction>
          <spring_reference>0</spring_reference>
          <spring_stiffness>0</spring_stiffness>
        </dynamics>
        <use_parent_model_frame>0</use_parent_model_frame>
      </axis>
    </joint>


    <link name='upper2'>
      <pose frame=''>0.1805 -0.1308 0 3.14159 1.57079 3.14159</pose>
      <inertial>
        <pose frame=''>-0.000684 -0.010999 -0.035487 0 -0 0</pose>
        <mass>1.080</mass>
        <inertia>
          <ixx>0.005666803</ixx>
          <ixy>0.000003597</ixy>
          <ixz>0.000491446</ixz>
          <iyy>0.005847229</iyy>
          <iyz>0.000010086</iyz>
          <izz>0.000369811</izz>
        </inertia>
      </inertial>
      <collision name='upper2_collision_collision'>
        <pose frame=''>0 0 -0.1 3.14159 1.57079 3.14159</pose>
        <geometry>
          <box>
            <size>0.2 0.0245 0.034</size>
          </box>
        </geometry>
        <surface>
          <contact>
            <ode>
              <kp>1e+06</kp>
              <kd>1</kd>
            </ode>
          </contact>
          <friction>
            <ode>
              <mu>0.5</mu>
              <mu2>0.5</mu2>
            </ode>
          </friction>
        </surface>
      </collision>
      <visual name='upper2_visual_visual'>
        <pose frame=''>0 0 0 0 -0 0</pose>
        <geometry>
          <mesh>
            <scale>1 1 1</scale>
            <uri>model://ylo2_description/meshes/leg/textured/ylo2_textured_upper_leg.dae</uri>
          </mesh>
        </geometry>
        <material>
          <script>
            <name>Gazebo/DarkGrey</name>
            <uri>file://media/materials/scripts/gazebo.material</uri>
          </script>
        </material>
      </visual>
      <gravity>1</gravity>
      <velocity_decay/>
      <self_collide>0</self_collide>
    </link>


    <joint name='4' type='revolute'>
      <child>upper2</child>
      <parent>hip2</parent>
      <axis>
        <xyz>0 -1 0</xyz>
        <limit>
          <lower>-6.28319</lower>
          <upper>6.28319</upper>
          <effort>33.5</effort>
          <velocity>21</velocity>
        </limit>
        <dynamics>
          <damping>0</damping>
          <friction>0</friction>
          <spring_reference>0</spring_reference>
          <spring_stiffness>0</spring_stiffness>
        </dynamics>
        <use_parent_model_frame>0</use_parent_model_frame>
      </axis>
    </joint>


    <link name='lower2'>
      <pose frame=''>-0.0195 -0.1308 -0 3.14159 -1.57079 3.14159</pose>
      <inertial>
        <pose frame=''>0.000252 0.000194 -0.05192 0 -0 0</pose>
        <mass>0.265</mass>
        <inertia>
          <ixx>0.0004583</ixx>
          <ixy>-0.000000095</ixy>
          <ixz>0.000026512</ixz>
          <iyy>0.0004675</iyy>
          <iyz>0.000000277</iyz>
          <izz>0.000029145</izz>
        </inertia>
      </inertial>
      <collision name='lower2_collision_collision'>
        <pose frame=''>0 0 -0.1 3.14159 1.57079 3.14159</pose>
        <geometry>
          <box>
            <size>0.2 0.016 0.016</size>
          </box>
        </geometry>
        <surface>
          <contact>
            <ode/>
          </contact>
          <friction>
            <ode>
              <mu>0.5</mu>
              <mu2>0.5</mu2>
            </ode>
          </friction>
        </surface>
      </collision>
      <visual name='lower2_visual_visual'>
        <pose frame=''>0 0 0 0 -0 0</pose>
        <geometry>
          <mesh>
            <scale>1 1 1</scale>
            <uri>model://ylo2_description/meshes/leg/fl_lower_leg_collision.stl</uri>
          </mesh>
        </geometry>
        <material>
          <script>
            <uri>__default__</uri>
            <name>__default__</name>
          </script>
        </material>
      </visual>
      <gravity>1</gravity>
      <velocity_decay/>
      <self_collide>0</self_collide>
    </link>


    <joint name='5' type='revolute'>
      <child>lower2</child>
      <parent>upper2</parent>
      <axis>
        <xyz>0 1 0</xyz>
        <limit>
          <lower>-6.28319</lower>
          <upper>6.28319</upper>
          <effort>33.5</effort>
          <velocity>21</velocity>
        </limit>
        <dynamics>
          <damping>0</damping>
          <friction>0</friction>
          <spring_reference>0</spring_reference>
          <spring_stiffness>0</spring_stiffness>
        </dynamics>
        <use_parent_model_frame>0</use_parent_model_frame>
      </axis>
    </joint>


    <link name='toe2'>
      <pose frame=''>0.1805 -0.1308 0 3.14159 -1.57079 3.14159</pose>
      <inertial>
        <pose frame=''>-0.007246 0.000092 -0.038267 0 -0 0</pose>
        <mass>0.078</mass>
        <inertia>
          <ixx>0.000029902</ixx>
          <ixy>-0.000000022</ixy>
          <ixz>-0.000004427</ixz>
          <iyy>0.000030583</iyy>
          <iyz>-0.000000099</iyz>
          <izz>0.000014025</izz>
        </inertia>
      </inertial>
      <collision name='toe2_collision_collision'>
        <pose frame=''>0 0 0 0 -0 0</pose>
        <geometry>
          <sphere>
            <radius>0.02</radius>
          </sphere>
        </geometry>
        <surface>
          <contact>
            <ode>
              <kp>1e+06</kp>
              <kd>1</kd>
            </ode>
          </contact>
          <friction>
            <ode>
              <mu>0.6</mu>
              <mu2>0.6</mu2>
            </ode>
          </friction>
        </surface>
      </collision>
      <visual name='toe2_visual_visual'>
        <pose frame=''>0 0 0 0 -0 0</pose>
        <geometry>
          <sphere>
            <radius>0.01</radius>
          </sphere>
        </geometry>
        <material>
          <script>
            <name>Gazebo/DarkGrey</name>
            <uri>file://media/materials/scripts/gazebo.material</uri>
          </script>
        </material>
      </visual>
      <velocity_decay/>
      <sensor name='toe2_contact' type='contact'>
        <plugin name='toe2_plugin' filename='libgazebo_ros_bumper.so'>
          <alwaysOn>1</alwaysOn>
          <updateRate>500</updateRate>
          <bumperTopicName>gazebo/toe2_contact_state</bumperTopicName>
          <frameName>world</frameName>
        </plugin>
        <contact>
          <collision>toe2_collision</collision>
          <topic>__default_topic__</topic>
        </contact>
        <update_rate>500</update_rate>
      </sensor>
      <gravity>1</gravity>
      <velocity_decay/>
      <self_collide>0</self_collide>
    </link>


    <joint name='jtoe2' type='fixed'>
      <child>toe2</child>
      <parent>lower2</parent>
      <axis>
        <dynamics>
          <spring_reference>0</spring_reference>
          <spring_stiffness>0</spring_stiffness>
        </dynamics>
        <xyz>0 0 1</xyz>
        <use_parent_model_frame>0</use_parent_model_frame>
        <limit>
          <lower>-1e+16</lower>
          <upper>1e+16</upper>
        </limit>
      </axis>
      <physics>
        <ode>
          <limit>
            <cfm>0</cfm>
            <erp>0.2</erp>
          </limit>
        </ode>
      </physics>
    </joint>


    <link name='hip3'>
      <pose frame=''>-0.1805 -0.047 0 0 -0 0</pose>
      <inertial>
        <pose frame=''>-0.011957 0.000306 0.000366 0 -0 0</pose>
        <mass>0.599</mass>
        <inertia>
          <ixx>0.0004159</ixx>
          <ixy>0.000004253</ixy>
          <ixz>0.000000368</ixz>
          <iyy>0.0007108</iyy>
          <iyz>0.000000215</iyz>
          <izz>0.0004707</izz>
        </inertia>
      </inertial>
      <collision name='hip3_collision_collision'>
        <pose frame=''>0 0 0 1.5708 -0 0</pose>
        <geometry>
          <cylinder>
            <length>0.04</length>
            <radius>0.046</radius>
          </cylinder>
        </geometry>
        <surface>
          <contact>
            <ode/>
          </contact>
          <friction>
            <ode>
              <mu>0.5</mu>
              <mu2>0.5</mu2>
            </ode>
          </friction>
        </surface>
      </collision>
      <visual name='hip3_visual_visual'>
        <pose frame=''>0 0 0 0 -0 3.14159</pose>
        <geometry>
          <mesh>
            <scale>1 1 1</scale>
            <uri>model://ylo2_description/meshes/leg/textured/ylo2texturedhip.dae</uri>
          </mesh>
        </geometry>
        <material>
          <script>
            <name>Gazebo/DarkGrey</name>
            <uri>file://media/materials/scripts/gazebo.material</uri>
          </script>
        </material>
      </visual>
      <gravity>1</gravity>
      <velocity_decay/>
    </link>


    <joint name='11' type='revolute'>
      <child>hip3</child>
      <parent>body</parent>
      <axis>
        <xyz>1 0 0</xyz>
        <limit>
          <lower>-0.802851</lower>
          <upper>0.802851</upper>
          <effort>33.5</effort>
          <velocity>21</velocity>
        </limit>
        <dynamics>
          <damping>0</damping>
          <friction>0</friction>
          <spring_reference>0</spring_reference>
          <spring_stiffness>0</spring_stiffness>
        </dynamics>
        <use_parent_model_frame>0</use_parent_model_frame>
      </axis>
    </joint>


    <link name='upper3'>
      <pose frame=''>-0.1805 -0.1308 0 3.14159 1.57079 3.14159</pose>
      <inertial>
        <pose frame=''>-0.000684 -0.010999 -0.035487 0 -0 0</pose>
        <mass>1.080</mass>
        <inertia>
          <ixx>0.005666803</ixx>
          <ixy>0.000003597</ixy>
          <ixz>0.000491446</ixz>
          <iyy>0.005847229</iyy>
          <iyz>0.000010086</iyz>
          <izz>0.000369811</izz>
        </inertia>
      </inertial>
      <collision name='upper3_collision_collision'>
        <pose frame=''>0 0 -0.1 3.14159 1.57079 3.14159</pose>
        <geometry>
          <box>
            <size>0.2 0.0245 0.034</size>
          </box>
        </geometry>
        <surface>
          <contact>
            <ode>
              <kp>1e+06</kp>
              <kd>1</kd>
            </ode>
          </contact>
          <friction>
            <ode>
              <mu>0.5</mu>
              <mu2>0.5</mu2>
            </ode>
          </friction>
        </surface>
      </collision>
      <visual name='upper3_visual_visual'>
        <pose frame=''>0 0 0 0 -0 0</pose>
        <geometry>
          <mesh>
            <scale>1 1 1</scale>
            <uri>model://ylo2_description/meshes/leg/textured/ylo2_textured_upper_leg.dae</uri>
          </mesh>
        </geometry>
        <material>
          <script>
            <name>Gazebo/DarkGrey</name>
            <uri>file://media/materials/scripts/gazebo.material</uri>
          </script>
        </material>
      </visual>
      <gravity>1</gravity>
      <velocity_decay/>
      <self_collide>0</self_collide>
    </link>


    <joint name='6' type='revolute'>
      <child>upper3</child>
      <parent>hip3</parent>
      <axis>
        <xyz>0 -1 0</xyz>
        <limit>
          <lower>-6.28319</lower>
          <upper>6.28319</upper>
          <effort>33.5</effort>
          <velocity>21</velocity>
        </limit>
        <dynamics>
          <damping>0</damping>
          <friction>0</friction>
          <spring_reference>0</spring_reference>
          <spring_stiffness>0</spring_stiffness>
        </dynamics>
        <use_parent_model_frame>0</use_parent_model_frame>
      </axis>
    </joint>


    <link name='lower3'>
      <pose frame=''>-0.3805 -0.1308 -0 3.14159 -1.57079 3.14159</pose>
      <inertial>
        <pose frame=''>0.000252 0.000194 -0.05192 0 -0 0</pose>
        <mass>0.265</mass>
        <inertia>
          <ixx>0.0004583</ixx>
          <ixy>-0.000000095</ixy>
          <ixz>0.000026512</ixz>
          <iyy>0.0004675</iyy>
          <iyz>0.000000277</iyz>
          <izz>0.000029145</izz>
        </inertia>
      </inertial>
      <collision name='lower3_collision_collision'>
        <pose frame=''>0 0 -0.1 3.14159 1.57079 3.14159</pose>
        <geometry>
          <box>
            <size>0.2 0.016 0.016</size>
          </box>
        </geometry>
        <surface>
          <contact>
            <ode/>
          </contact>
          <friction>
            <ode>
              <mu>0.5</mu>
              <mu2>0.5</mu2>
            </ode>
          </friction>
        </surface>
      </collision>
      <visual name='lower3_visual_visual'>
        <pose frame=''>0 0 0 0 -0 0</pose>
        <geometry>
          <mesh>
            <scale>1 1 1</scale>
            <uri>model://ylo2_description/meshes/leg/fl_foot.dae</uri>
          </mesh>
        </geometry>
        <material>
          <script>
            <uri>__default__</uri>
            <name>__default__</name>
          </script>
        </material>
      </visual>
      <gravity>1</gravity>
      <velocity_decay/>
      <self_collide>0</self_collide>
    </link>


    <joint name='7' type='revolute'>
      <child>lower3</child>
      <parent>upper3</parent>
      <axis>
        <xyz>0 1 0</xyz>
        <limit>
          <lower>-6.28319</lower>
          <upper>6.28319</upper>
          <effort>33.5</effort>
          <velocity>21</velocity>
        </limit>
        <dynamics>
          <damping>0</damping>
          <friction>0</friction>
          <spring_reference>0</spring_reference>
          <spring_stiffness>0</spring_stiffness>
        </dynamics>
        <use_parent_model_frame>0</use_parent_model_frame>
      </axis>
    </joint>


    <link name='toe3'>
      <pose frame=''>-0.1805 -0.1308 0 3.14159 -1.57079 3.14159</pose>
      <inertial>
        <pose frame=''>-0.007246 0.000092 -0.038267 0 -0 0</pose>
        <mass>0.078</mass>
        <inertia>
          <ixx>0.000029902</ixx>
          <ixy>-0.000000022</ixy>
          <ixz>-0.000004427</ixz>
          <iyy>0.000030583</iyy>
          <iyz>-0.000000099</iyz>
          <izz>0.000014025</izz>
        </inertia>
      </inertial>
      <collision name='toe3_collision_collision'>
        <pose frame=''>0 0 0 0 -0 0</pose>
        <geometry>
          <sphere>
            <radius>0.02</radius>
          </sphere>
        </geometry>
        <surface>
          <contact>
            <ode>
              <kp>1e+06</kp>
              <kd>1</kd>
            </ode>
          </contact>
          <friction>
            <ode>
              <mu>0.6</mu>
              <mu2>0.6</mu2>
            </ode>
          </friction>
        </surface>
      </collision>
      <visual name='toe3_visual_visual'>
        <pose frame=''>0 0 0 0 -0 0</pose>
        <geometry>
          <sphere>
            <radius>0.01</radius>
          </sphere>
        </geometry>
        <material>
          <script>
            <name>Gazebo/DarkGrey</name>
            <uri>file://media/materials/scripts/gazebo.material</uri>
          </script>
        </material>
      </visual>
      <velocity_decay/>
      <sensor name='toe3_contact' type='contact'>
        <plugin name='toe3_plugin' filename='libgazebo_ros_bumper.so'>
          <alwaysOn>1</alwaysOn>
          <updateRate>500</updateRate>
          <bumperTopicName>gazebo/toe3_contact_state</bumperTopicName>
          <frameName>world</frameName>
        </plugin>
        <contact>
          <collision>toe3_collision</collision>
          <topic>__default_topic__</topic>
        </contact>
        <update_rate>500</update_rate>
      </sensor>
      <gravity>1</gravity>
      <velocity_decay/>
      <self_collide>0</self_collide>
    </link>


    <joint name='jtoe3' type='fixed'>
      <child>toe3</child>
      <parent>lower3</parent>
      <axis>
        <dynamics>
          <spring_reference>0</spring_reference>
          <spring_stiffness>0</spring_stiffness>
        </dynamics>
        <xyz>0 0 1</xyz>
        <use_parent_model_frame>0</use_parent_model_frame>
        <limit>
          <lower>-1e+16</lower>
          <upper>1e+16</upper>
        </limit>
      </axis>
      <physics>
        <ode>
          <limit>
            <cfm>0</cfm>
            <erp>0.2</erp>
          </limit>
        </ode>
      </physics>
    </joint>


    <link name='hip0'>
      <pose frame=''>0.1805 0.047 0 0 -0 0</pose>
      <inertial>
        <pose frame=''>-0.011957 0.000306 0.000366 0 -0 0</pose>
        <mass>0.599</mass>
        <inertia>
          <ixx>0.0004159</ixx>
          <ixy>0.000004253</ixy>
          <ixz>0.000000368</ixz>
          <iyy>0.0007108</iyy>
          <iyz>0.000000215</iyz>
          <izz>0.0004707</izz>
        </inertia>
      </inertial>
      <collision name='hip0_collision_collision'>
        <pose frame=''>0 0 0 1.5708 -0 0</pose>
        <geometry>
          <cylinder>
            <length>0.04</length>
            <radius>0.046</radius>
          </cylinder>
        </geometry>
        <surface>
          <contact>
            <ode/>
          </contact>
          <friction>
            <ode>
              <mu>0.5</mu>
              <mu2>0.5</mu2>
            </ode>
          </friction>
        </surface>
      </collision>
      <visual name='hip0_visual_visual'>
        <pose frame=''>0 0 0 0 -0 0</pose>
        <geometry>
          <mesh>
            <scale>1 1 1</scale>
            <uri>model://ylo2_description/meshes/leg/textured/ylo2texturedhip.dae</uri>
          </mesh>
        </geometry>
        <material>
          <script>
            <name>Gazebo/DarkGrey</name>
            <uri>file://media/materials/scripts/gazebo.material</uri>
          </script>
        </material>
      </visual>
      <gravity>1</gravity>
      <velocity_decay/>
    </link>

    
    <joint name='8' type='revolute'>
      <child>hip0</child>
      <parent>body</parent>
      <axis>
        <xyz>1 0 0</xyz>
        <limit>
          <lower>-0.802851</lower>
          <upper>0.802851</upper>
          <effort>33.5</effort>
          <velocity>21</velocity>
        </limit>
        <dynamics>
          <damping>0</damping>
          <friction>0</friction>
          <spring_reference>0</spring_reference>
          <spring_stiffness>0</spring_stiffness>
        </dynamics>
        <use_parent_model_frame>0</use_parent_model_frame>
      </axis>
    </joint>


    <link name='upper0'>
      <pose frame=''>0.1805 0.1308 0 3.14159 1.57079 3.14159</pose>
      <inertial>
        <pose frame=''>-0.000684 -0.010999 -0.035487 0 -0 0</pose>
        <mass>1.080</mass>
        <inertia>
          <ixx>0.005666803</ixx>
          <ixy>0.000003597</ixy>
          <ixz>0.000491446</ixz>
          <iyy>0.005847229</iyy>
          <iyz>0.000010086</iyz>
          <izz>0.000369811</izz>
        </inertia>
      </inertial>
      <collision name='upper0_collision_collision'>
        <pose frame=''>0 0 -0.1 3.14159 1.57079 3.14159</pose>
        <geometry>
          <box>
            <size>0.2 0.0245 0.034</size>
          </box>
        </geometry>
        <surface>
          <contact>
            <ode>
              <kp>1e+06</kp>
              <kd>1</kd>
            </ode>
          </contact>
          <friction>
            <ode>
              <mu>0.5</mu>
              <mu2>0.5</mu2>
            </ode>
          </friction>
        </surface>
      </collision>
      <visual name='upper0_visual_visual'>
        <pose frame=''>0 0 0 0 -0 0</pose>
        <geometry>
          <mesh>
            <scale>1 1 1</scale>
            <uri>model://ylo2_description/meshes/leg/textured/ylo2_textured_upper_leg.dae</uri>
          </mesh>
        </geometry>
        <material>
          <script>
            <name>Gazebo/DarkGrey</name>
            <uri>file://media/materials/scripts/gazebo.material</uri>
          </script>
        </material>
      </visual>
      <gravity>1</gravity>
      <velocity_decay/>
      <self_collide>0</self_collide>
    </link>


    <joint name='0' type='revolute'>
      <child>upper0</child>
      <parent>hip0</parent>
      <axis>
        <xyz>0 -1 0</xyz>
        <limit>
          <lower>-6.28319</lower>
          <upper>6.28319</upper>
          <effort>33.5</effort>
          <velocity>21</velocity>
        </limit>
        <dynamics>
          <damping>0</damping>
          <friction>0</friction>
          <spring_reference>0</spring_reference>
          <spring_stiffness>0</spring_stiffness>
        </dynamics>
        <use_parent_model_frame>0</use_parent_model_frame>
      </axis>
    </joint>


    <link name='lower0'>
      <pose frame=''>-0.0195 0.1308 -0 3.14159 -1.57079 3.14159</pose>
      <inertial>
        <pose frame=''>0.000252 0.000194 -0.05192 0 -0 0</pose>
        <mass>0.265</mass>
        <inertia>
          <ixx>0.0004583</ixx>
          <ixy>-0.000000095</ixy>
          <ixz>0.000026512</ixz>
          <iyy>0.0004675</iyy>
          <iyz>0.000000277</iyz>
          <izz>0.000029145</izz>
        </inertia>
      </inertial>
      <collision name='lower0_collision_collision'>
        <pose frame=''>0 0 -0.1 3.14159 1.57079 3.14159</pose>
        <geometry>
          <box>
            <size>0.2 0.016 0.016</size>
          </box>
        </geometry>
        <surface>
          <contact>
            <ode/>
          </contact>
          <friction>
            <ode>
              <mu>0.5</mu>
              <mu2>0.5</mu2>
            </ode>
          </friction>
        </surface>
      </collision>
      <visual name='lower0_visual_visual'>
        <pose frame=''>0 0 0 0 -0 0</pose>
        <geometry>
          <mesh>
            <scale>1 1 1</scale>
            <uri>model://ylo2_description/meshes/leg/fl_foot.dae</uri>
          </mesh>
        </geometry>
        <material>
          <script>
            <uri>__default__</uri>
            <name>__default__</name>
          </script>
        </material>
      </visual>
      <gravity>1</gravity>
      <velocity_decay/>
      <self_collide>0</self_collide>
    </link>


    <joint name='1' type='revolute'>
      <child>lower0</child>
      <parent>upper0</parent>
      <axis>
        <xyz>0 1 0</xyz>
        <limit>
          <lower>-6.28319</lower>
          <upper>6.28319</upper>
          <effort>33.5</effort>
          <velocity>21</velocity>
        </limit>
        <dynamics>
          <damping>0</damping>
          <friction>0</friction>
          <spring_reference>0</spring_reference>
          <spring_stiffness>0</spring_stiffness>
        </dynamics>
        <use_parent_model_frame>0</use_parent_model_frame>
      </axis>
    </joint>


    <link name='toe0'>
      <pose frame=''>0.1805 0.1308 0 3.14159 -1.57079 3.14159</pose>
      <inertial>
        <pose frame=''>-0.007246 0.000092 -0.038267 0 -0 0</pose>
        <mass>0.078</mass>
        <inertia>
          <ixx>0.000029902</ixx>
          <ixy>-0.000000022</ixy>
          <ixz>-0.000004427</ixz>
          <iyy>0.000030583</iyy>
          <iyz>-0.000000099</iyz>
          <izz>0.000014025</izz>
        </inertia>
      </inertial>
      <collision name='toe0_collision_collision'>
        <pose frame=''>0 0 0 0 -0 0</pose>
        <geometry>
          <sphere>
            <radius>0.02</radius>
          </sphere>
        </geometry>
        <surface>
          <contact>
            <ode>
              <kp>1e+06</kp>
              <kd>1</kd>
            </ode>
          </contact>
          <friction>
            <ode>
              <mu>0.6</mu>
              <mu2>0.6</mu2>
            </ode>
          </friction>
        </surface>
      </collision>
      <visual name='toe0_visual_visual'>
        <pose frame=''>0 0 0 0 -0 0</pose>
        <geometry>
          <sphere>
            <radius>0.01</radius>
          </sphere>
        </geometry>
        <material>
          <script>
            <name>Gazebo/DarkGrey</name>
            <uri>file://media/materials/scripts/gazebo.material</uri>
          </script>
        </material>
      </visual>
      <velocity_decay/>
      <sensor name='toe0_contact' type='contact'>
        <plugin name='toe0_plugin' filename='libgazebo_ros_bumper.so'>
          <alwaysOn>1</alwaysOn>
          <updateRate>500</updateRate>
          <bumperTopicName>gazebo/toe0_contact_state</bumperTopicName>
          <frameName>world</frameName>
        </plugin>
        <contact>
          <collision>toe0_collision</collision>
          <topic>__default_topic__</topic>
        </contact>
        <update_rate>500</update_rate>
      </sensor>
      <gravity>1</gravity>
      <velocity_decay/>
      <self_collide>0</self_collide>
    </link>


    <joint name='jtoe0' type='fixed'>
      <child>toe0</child>
      <parent>lower0</parent>
      <axis>
        <dynamics>
          <spring_reference>0</spring_reference>
          <spring_stiffness>0</spring_stiffness>
        </dynamics>
        <xyz>0 0 1</xyz>
        <use_parent_model_frame>0</use_parent_model_frame>
        <limit>
          <lower>-1e+16</lower>
          <upper>1e+16</upper>
        </limit>
      </axis>
      <physics>
        <ode>
          <limit>
            <cfm>0</cfm>
            <erp>0.2</erp>
          </limit>
        </ode>
      </physics>
    </joint>


    <link name='hip1'>
      <pose frame=''>-0.1805 0.047 0 0 -0 0</pose>
      <inertial>
        <pose frame=''>-0.011957 0.000306 0.000366 0 -0 0</pose>
        <mass>0.599</mass>
        <inertia>
          <ixx>0.0004159</ixx>
          <ixy>0.000004253</ixy>
          <ixz>0.000000368</ixz>
          <iyy>0.0007108</iyy>
          <iyz>0.000000215</iyz>
          <izz>0.0004707</izz>
        </inertia>
      </inertial>
      <collision name='hip1_collision_collision'>
        <pose frame=''>0 0 0 1.5708 -0 0</pose>
        <geometry>
          <cylinder>
            <length>0.04</length>
            <radius>0.046</radius>
          </cylinder>
        </geometry>
        <surface>
          <contact>
            <ode/>
          </contact>
          <friction>
            <ode>
              <mu>0.5</mu>
              <mu2>0.5</mu2>
            </ode>
          </friction>
        </surface>
      </collision>
      <visual name='hip1_visual_visual'>
        <pose frame=''>0 0 0 3.14159 -0 3.14159</pose>
        <geometry>
          <mesh>
            <scale>1 1 1</scale>
            <uri>model://ylo2_description/meshes/leg/textured/ylo2texturedhip.dae</uri>
          </mesh>
        </geometry>
        <material>
          <script>
            <name>Gazebo/DarkGrey</name>
            <uri>file://media/materials/scripts/gazebo.material</uri>
          </script>
        </material>
      </visual>
      <gravity>1</gravity>
      <velocity_decay/>
    </link>


    <joint name='9' type='revolute'>
      <child>hip1</child>
      <parent>body</parent>
      <axis>
        <xyz>1 0 0</xyz>
        <limit>
          <lower>-0.802851</lower>
          <upper>0.802851</upper>
          <effort>33.5</effort>
          <velocity>21</velocity>
        </limit>
        <dynamics>
          <damping>0</damping>
          <friction>0</friction>
          <spring_reference>0</spring_reference>
          <spring_stiffness>0</spring_stiffness>
        </dynamics>
        <use_parent_model_frame>0</use_parent_model_frame>
      </axis>
    </joint>


    <link name='upper1'>
      <pose frame=''>-0.1805 0.1308 0 3.14159 1.57079 3.14159</pose>
      <inertial>
        <pose frame=''>-0.000684 -0.010999 -0.035487 0 -0 0</pose>
        <mass>1.080</mass>
        <inertia>
          <ixx>0.005666803</ixx>
          <ixy>0.000003597</ixy>
          <ixz>0.000491446</ixz>
          <iyy>0.005847229</iyy>
          <iyz>0.000010086</iyz>
          <izz>0.000369811</izz>
        </inertia>
      </inertial>
      <collision name='upper1_collision_collision'>
        <pose frame=''>0 0 -0.1 3.14159 1.57079 3.14159</pose>
        <geometry>
          <box>
            <size>0.2 0.0245 0.034</size>
          </box>
        </geometry>
        <surface>
          <contact>
            <ode>
              <kp>1e+06</kp>
              <kd>1</kd>
            </ode>
          </contact>
          <friction>
            <ode>
              <mu>0.5</mu>
              <mu2>0.5</mu2>
            </ode>
          </friction>
        </surface>
      </collision>
      <visual name='upper1_visual_visual'>
        <pose frame=''>0 0 0 0 -0 0</pose>
        <geometry>
          <mesh>
            <scale>1 1 1</scale>
            <uri>model://ylo2_description/meshes/leg/textured/ylo2_textured_upper_leg.dae</uri>
          </mesh>
        </geometry>
        <material>
          <script>
            <name>Gazebo/DarkGrey</name>
            <uri>file://media/materials/scripts/gazebo.material</uri>
          </script>
        </material>
      </visual>
      <gravity>1</gravity>
      <velocity_decay/>
      <self_collide>0</self_collide>
    </link>


    <joint name='2' type='revolute'>
      <child>upper1</child>
      <parent>hip1</parent>
      <axis>
        <xyz>0 -1 0</xyz>
        <limit>
          <lower>-6.28319</lower>
          <upper>6.28319</upper>
          <effort>33.5</effort>
          <velocity>21</velocity>
        </limit>
        <dynamics>
          <damping>0</damping>
          <friction>0</friction>
          <spring_reference>0</spring_reference>
          <spring_stiffness>0</spring_stiffness>
        </dynamics>
        <use_parent_model_frame>0</use_parent_model_frame>
      </axis>
    </joint>


    <link name='lower1'>
      <pose frame=''>-0.3805 0.1308 -0 3.14159 -1.57079 3.14159</pose>
      <inertial>
        <pose frame=''>0.000252 0.000194 -0.05192 0 -0 0</pose>
        <mass>0.265</mass>
        <inertia>
          <ixx>0.0004583</ixx>
          <ixy>-0.000000095</ixy>
          <ixz>0.000026512</ixz>
          <iyy>0.0004675</iyy>
          <iyz>0.000000277</iyz>
          <izz>0.000029145</izz>
        </inertia>
      </inertial>
      <collision name='lower1_collision_collision'>
        <pose frame=''>0 0 -0.1 3.14159 1.57079 3.14159</pose>
        <geometry>
          <box>
            <size>0.2 0.016 0.016</size>
          </box>
        </geometry>
        <surface>
          <contact>
            <ode/>
          </contact>
          <friction>
            <ode>
              <mu>0.5</mu>
              <mu2>0.5</mu2>
            </ode>
          </friction>
        </surface>
      </collision>
      <visual name='lower1_visual_visual'>
        <pose frame=''>0 0 0 0 -0 0</pose>
        <geometry>
          <mesh>
            <scale>1 1 1</scale>
            <uri>model://ylo2_description/meshes/leg/fl_foot.dae</uri>
          </mesh>
        </geometry>
        <material>
          <script>
            <uri>__default__</uri>
            <name>__default__</name>
          </script>
        </material>
      </visual>
      <gravity>1</gravity>
      <velocity_decay/>
      <self_collide>0</self_collide>
    </link>


    <joint name='3' type='revolute'>
      <child>lower1</child>
      <parent>upper1</parent>
      <axis>
        <xyz>0 1 0</xyz>
        <limit>
          <lower>-6.28319</lower>
          <upper>6.28319</upper>
          <effort>33.5</effort>
          <velocity>21</velocity>
        </limit>
        <dynamics>
          <damping>0</damping>
          <friction>0</friction>
          <spring_reference>0</spring_reference>
          <spring_stiffness>0</spring_stiffness>
        </dynamics>
        <use_parent_model_frame>0</use_parent_model_frame>
      </axis>
    </joint>


    <link name='toe1'>
      <pose frame=''>-0.1805 0.1308 0 3.14159 -1.57079 3.14159</pose>
      <inertial>
        <pose frame=''>-0.007246 0.000092 -0.038267 0 -0 0</pose>
        <mass>0.078</mass>
        <inertia>
          <ixx>0.000029902</ixx>
          <ixy>-0.000000022</ixy>
          <ixz>-0.000004427</ixz>
          <iyy>0.000030583</iyy>
          <iyz>-0.000000099</iyz>
          <izz>0.000014025</izz>
        </inertia>
      </inertial>
      <collision name='toe1_collision_collision'>
        <pose frame=''>0 0 0 0 -0 0</pose>
        <geometry>
          <sphere>
            <radius>0.02</radius>
          </sphere>
        </geometry>
        <surface>
          <contact>
            <ode>
              <kp>1e+06</kp>
              <kd>1</kd>
            </ode>
          </contact>
          <friction>
            <ode>
              <mu>0.6</mu>
              <mu2>0.6</mu2>
            </ode>
          </friction>
        </surface>
      </collision>
      <visual name='toe1_visual_visual'>
        <pose frame=''>0 0 0 0 -0 0</pose>
        <geometry>
          <sphere>
            <radius>0.01</radius>
          </sphere>
        </geometry>
        <material>
          <script>
            <name>Gazebo/DarkGrey</name>
            <uri>file://media/materials/scripts/gazebo.material</uri>
          </script>
        </material>
      </visual>
      <velocity_decay/>
      <sensor name='toe1_contact' type='contact'>
        <plugin name='toe1_plugin' filename='libgazebo_ros_bumper.so'>
          <alwaysOn>1</alwaysOn>
          <updateRate>500</updateRate>
          <bumperTopicName>gazebo/toe1_contact_state</bumperTopicName>
          <frameName>world</frameName>
        </plugin>
        <contact>
          <collision>toe1_collision</collision>
          <topic>__default_topic__</topic>
        </contact>
        <update_rate>500</update_rate>
      </sensor>
      <gravity>1</gravity>
      <velocity_decay/>
      <self_collide>0</self_collide>
    </link>


    <joint name='jtoe1' type='fixed'>
      <child>toe1</child>
      <parent>lower1</parent>
      <axis>
        <dynamics>
          <spring_reference>0</spring_reference>
          <spring_stiffness>0</spring_stiffness>
        </dynamics>
        <xyz>0 0 1</xyz>
        <use_parent_model_frame>0</use_parent_model_frame>
        <limit>
          <lower>-1e+16</lower>
          <upper>1e+16</upper>
        </limit>
      </axis>
      <physics>
        <ode>
          <limit>
            <cfm>0</cfm>
            <erp>0.2</erp>
          </limit>
        </ode>
      </physics>
    </joint>


    <plugin name='gazebo_ros_control' filename='libgazebo_ros_control.so'>
      <robotSimType>gazebo_ros_control/DefaultRobotHWSim</robotSimType>
    </plugin>
    <plugin name='ground_truth_estimator' filename='libground_truth_estimator.so'>
      <updateRateHZ>500.0</updateRateHZ>
    </plugin>
    <static>0</static>
    <plugin name='gazebo_ros_force' filename='libgazebo_ros_force.so'>
      <topicName>/apply_force/trunk</topicName>
      <bodyName>body</bodyName>
      <xyzOffset>0 0 0</xyzOffset>
      <rpyOffset>0 -0 0</rpyOffset>
    </plugin>
  </model>
</sdf>
