<?xml version='1.0'?>

<!-- 
MIT License (modified)

Copyright (c) 2018 The Trustees of the University of Pennsylvania
Authors:
Vasileios Vasilopoulos <vvasilo@seas.upenn.edu>

Permission is hereby granted, free of charge, to any person obtaining a copy
of this **file** (the "Software"), to deal
in the Software without restriction, including without limitation the rights
to use, copy, modify, merge, publish, distribute, sublicense, and/or sell
copies of the Software, and to permit persons to whom the Software is
furnished to do so, subject to the following conditions:

The above copyright notice and this permission notice shall be included in all
copies or substantial portions of the Software.

THE SOFTWARE IS PROVIDED "AS IS", WITHOUT WARRANTY OF ANY KIND, EXPRESS OR
IMPLIED, INCLUDING BUT NOT LIMITED TO THE WARRANTIES OF MERCHANTABILITY,
FITNESS FOR A PARTICULAR PURPOSE AND NONINFRINGEMENT. IN NO EVENT SHALL THE
AUTHORS OR COPYRIGHT HOLDERS BE LIABLE FOR ANY CLAIM, DAMAGES OR OTHER
LIABILITY, WHETHER IN AN ACTION OF CONTRACT, TORT OR OTHERWISE, ARISING FROM,
OUT OF OR IN CONNECTION WITH THE SOFTWARE OR THE USE OR OTHER DEALINGS IN THE
SOFTWARE. 
-->

<sdf version='1.6'>
  <model name='cart_rail'>
    <link name='cart_main'>
      <pose frame=''>0 0 0.125 0 -0 0</pose>
      <inertial>
        <mass>6</mass>
        <inertia>
          <ixx>0.1013</ixx>
          <ixy>0</ixy>
          <ixz>0</ixz>
          <iyy>0.18005</iyy>
          <iyz>0</iyz>
          <izz>0.28125</izz>
        </inertia>
        <pose frame=''>0 0 0.3 0 -0 0</pose>
      </inertial>
      <gravity>1</gravity>
      <self_collide>0</self_collide>
      <kinematic>0</kinematic>

      <visual name='base_visual'>
        <pose frame=''>0 0 0 0 -0 0</pose>
        <geometry>
          <box>
            <size>0.6 0.45 0.01</size>
          </box>
        </geometry>
        <material>
          <lighting>1</lighting>
          <script>
            <uri>file://media/materials/scripts/gazebo.material</uri>
            <name>Gazebo/Black</name>
          </script>
        </material>
        <cast_shadows>1</cast_shadows>
        <transparency>0</transparency>
      </visual>
      <collision name='base_collision'>
        <laser_retro>0</laser_retro>
        <max_contacts>10</max_contacts>
        <pose frame=''>0 0 0 0 -0 0</pose>
        <geometry>
          <box>
            <size>0.6 0.45 0.01</size>
          </box>
        </geometry>
        <surface>
          <friction>
            <ode>
              <mu>1</mu>
              <mu2>1</mu2>
              <fdir1>0 0 0</fdir1>
              <slip1>0</slip1>
              <slip2>0</slip2>
            </ode>
            <torsional>
              <coefficient>1</coefficient>
              <patch_radius>0</patch_radius>
              <surface_radius>0</surface_radius>
              <use_patch_radius>1</use_patch_radius>
              <ode>
                <slip>0</slip>
              </ode>
            </torsional>
          </friction>
          <bounce>
            <restitution_coefficient>0</restitution_coefficient>
            <threshold>1e+06</threshold>
          </bounce>
        </surface>
      </collision>

      <visual name='bump_visual'>
        <pose frame=''>0 0 0.06 0 -0 0</pose>
        <geometry>
          <box>
            <size>0.23 0.35 0.04</size>
          </box>
        </geometry>
        <material>
          <lighting>1</lighting>
          <script>
            <uri>file://media/materials/scripts/gazebo.material</uri>
            <name>Gazebo/Black</name>
          </script>
        </material>
        <cast_shadows>1</cast_shadows>
        <transparency>0</transparency>
      </visual>
      <collision name='bump_collision'>
        <laser_retro>0</laser_retro>
        <max_contacts>10</max_contacts>
        <pose frame=''>0 0 0.06 0 -0 0</pose>
        <geometry>
          <box>
            <size>0.23 0.35 0.04</size>
          </box>
        </geometry>
        <surface>
          <friction>
            <ode>
              <mu>1</mu>
              <mu2>1</mu2>
              <fdir1>0 0 0</fdir1>
              <slip1>0</slip1>
              <slip2>0</slip2>
            </ode>
            <torsional>
              <coefficient>1</coefficient>
              <patch_radius>0</patch_radius>
              <surface_radius>0</surface_radius>
              <use_patch_radius>1</use_patch_radius>
              <ode>
                <slip>0</slip>
              </ode>
            </torsional>
          </friction>
          <bounce>
            <restitution_coefficient>0</restitution_coefficient>
            <threshold>1e+06</threshold>
          </bounce>
        </surface>
      </collision>

      <visual name='top_visual'>
        <pose frame=''>0 0 0.39 0 -0 0</pose>
        <geometry>
          <box>
            <size>0.6 0.45 0.01</size>
          </box>
        </geometry>
        <material>
          <lighting>1</lighting>
          <script>
            <uri>file://media/materials/scripts/gazebo.material</uri>
            <name>Gazebo/Black</name>
          </script>
        </material>
        <cast_shadows>1</cast_shadows>
        <transparency>0</transparency>
      </visual>
      <collision name='top_collision'>
        <laser_retro>0</laser_retro>
        <max_contacts>10</max_contacts>
        <pose frame=''>0 0 0.39 0 -0 0</pose>
        <geometry>
          <box>
            <size>0.6 0.45 0.01</size>
          </box>
        </geometry>
        <surface>
          <friction>
            <ode>
              <mu>1</mu>
              <mu2>1</mu2>
              <fdir1>0 0 0</fdir1>
              <slip1>0</slip1>
              <slip2>0</slip2>
            </ode>
            <torsional>
              <coefficient>1</coefficient>
              <patch_radius>0</patch_radius>
              <surface_radius>0</surface_radius>
              <use_patch_radius>1</use_patch_radius>
              <ode>
                <slip>0</slip>
              </ode>
            </torsional>
          </friction>
          <bounce>
            <restitution_coefficient>0</restitution_coefficient>
            <threshold>1e+06</threshold>
          </bounce>
        </surface>
      </collision>

      <visual name='bottom_front_visual'>
        <pose frame=''>0 0.22 0.04 0 -0 0</pose>
        <geometry>
          <box>
            <size>0.6 0.01 0.07</size>
          </box>
        </geometry>
        <material>
          <lighting>1</lighting>
          <script>
            <uri>file://media/materials/scripts/gazebo.material</uri>
            <name>Gazebo/Black</name>
          </script>
        </material>
        <cast_shadows>1</cast_shadows>
        <transparency>0</transparency>
      </visual>
      <collision name='bottom_front_collision'>
        <laser_retro>0</laser_retro>
        <max_contacts>10</max_contacts>
        <pose frame=''>0 0.22 0.04 0 -0 0</pose>
        <geometry>
          <box>
            <size>0.6 0.01 0.07</size>
          </box>
        </geometry>
        <surface>
          <friction>
            <ode>
              <mu>1</mu>
              <mu2>1</mu2>
              <fdir1>0 0 0</fdir1>
              <slip1>0</slip1>
              <slip2>0</slip2>
            </ode>
            <torsional>
              <coefficient>1</coefficient>
              <patch_radius>0</patch_radius>
              <surface_radius>0</surface_radius>
              <use_patch_radius>1</use_patch_radius>
              <ode>
                <slip>0</slip>
              </ode>
            </torsional>
          </friction>
          <bounce>
            <restitution_coefficient>0</restitution_coefficient>
            <threshold>1e+06</threshold>
          </bounce>
        </surface>
      </collision>

      <visual name='bottom_back_visual'>
        <pose frame=''>0 -0.22 0.04 0 -0 0</pose>
        <geometry>
          <box>
            <size>0.6 0.01 0.07</size>
          </box>
        </geometry>
        <material>
          <lighting>1</lighting>
          <script>
            <uri>file://media/materials/scripts/gazebo.material</uri>
            <name>Gazebo/Black</name>
          </script>
        </material>
        <cast_shadows>1</cast_shadows>
        <transparency>0</transparency>
      </visual>
      <collision name='bottom_back_collision'>
        <laser_retro>0</laser_retro>
        <max_contacts>10</max_contacts>
        <pose frame=''>0 -0.22 0.04 0 -0 0</pose>
        <geometry>
          <box>
            <size>0.6 0.01 0.07</size>
          </box>
        </geometry>
        <surface>
          <friction>
            <ode>
              <mu>1</mu>
              <mu2>1</mu2>
              <fdir1>0 0 0</fdir1>
              <slip1>0</slip1>
              <slip2>0</slip2>
            </ode>
            <torsional>
              <coefficient>1</coefficient>
              <patch_radius>0</patch_radius>
              <surface_radius>0</surface_radius>
              <use_patch_radius>1</use_patch_radius>
              <ode>
                <slip>0</slip>
              </ode>
            </torsional>
          </friction>
          <bounce>
            <restitution_coefficient>0</restitution_coefficient>
            <threshold>1e+06</threshold>
          </bounce>
        </surface>
      </collision>

      <visual name='bottom_right_visual'>
        <pose frame=''>0.295 0 0.04 0 -0 0</pose>
        <geometry>
          <box>
            <size>0.01 0.43 0.07</size>
          </box>
        </geometry>
        <material>
          <lighting>1</lighting>
          <script>
            <uri>file://media/materials/scripts/gazebo.material</uri>
            <name>Gazebo/Black</name>
          </script>
        </material>
        <cast_shadows>1</cast_shadows>
        <transparency>0</transparency>
      </visual>
      <collision name='bottom_right_collision'>
        <laser_retro>0</laser_retro>
        <max_contacts>10</max_contacts>
        <pose frame=''>0.295 0 0.04 0 -0 0</pose>
        <geometry>
          <box>
            <size>0.01 0.43 0.07</size>
          </box>
        </geometry>
        <surface>
          <friction>
            <ode>
              <mu>1</mu>
              <mu2>1</mu2>
              <fdir1>0 0 0</fdir1>
              <slip1>0</slip1>
              <slip2>0</slip2>
            </ode>
            <torsional>
              <coefficient>1</coefficient>
              <patch_radius>0</patch_radius>
              <surface_radius>0</surface_radius>
              <use_patch_radius>1</use_patch_radius>
              <ode>
                <slip>0</slip>
              </ode>
            </torsional>
          </friction>
          <bounce>
            <restitution_coefficient>0</restitution_coefficient>
            <threshold>1e+06</threshold>
          </bounce>
        </surface>
      </collision>

      <visual name='bottom_left_visual'>
        <pose frame=''>-0.295 0 0.04 0 -0 0</pose>
        <geometry>
          <box>
            <size>0.01 0.43 0.07</size>
          </box>
        </geometry>
        <material>
          <lighting>1</lighting>
          <script>
            <uri>file://media/materials/scripts/gazebo.material</uri>
            <name>Gazebo/Black</name>
          </script>
        </material>
        <cast_shadows>1</cast_shadows>
        <transparency>0</transparency>
      </visual>
      <collision name='bottom_left_collision'>
        <laser_retro>0</laser_retro>
        <max_contacts>10</max_contacts>
        <pose frame=''>-0.295 0 0.04 0 -0 0</pose>
        <geometry>
          <box>
            <size>0.01 0.43 0.07</size>
          </box>
        </geometry>
        <surface>
          <friction>
            <ode>
              <mu>1</mu>
              <mu2>1</mu2>
              <fdir1>0 0 0</fdir1>
              <slip1>0</slip1>
              <slip2>0</slip2>
            </ode>
            <torsional>
              <coefficient>1</coefficient>
              <patch_radius>0</patch_radius>
              <surface_radius>0</surface_radius>
              <use_patch_radius>1</use_patch_radius>
              <ode>
                <slip>0</slip>
              </ode>
            </torsional>
          </friction>
          <bounce>
            <restitution_coefficient>0</restitution_coefficient>
            <threshold>1e+06</threshold>
          </bounce>
        </surface>
      </collision>

      <visual name='top_front_visual'>
        <pose frame=''>0 0.22 0.43 0 -0 0</pose>
        <geometry>
          <box>
            <size>0.6 0.01 0.07</size>
          </box>
        </geometry>
        <material>
          <lighting>1</lighting>
          <script>
            <uri>file://media/materials/scripts/gazebo.material</uri>
            <name>Gazebo/Black</name>
          </script>
        </material>
        <cast_shadows>1</cast_shadows>
        <transparency>0</transparency>
      </visual>
      <collision name='top_front_collision'>
        <laser_retro>0</laser_retro>
        <max_contacts>10</max_contacts>
        <pose frame=''>0 0.22 0.43 0 -0 0</pose>
        <geometry>
          <box>
            <size>0.6 0.01 0.07</size>
          </box>
        </geometry>
        <surface>
          <friction>
            <ode>
              <mu>1</mu>
              <mu2>1</mu2>
              <fdir1>0 0 0</fdir1>
              <slip1>0</slip1>
              <slip2>0</slip2>
            </ode>
            <torsional>
              <coefficient>1</coefficient>
              <patch_radius>0</patch_radius>
              <surface_radius>0</surface_radius>
              <use_patch_radius>1</use_patch_radius>
              <ode>
                <slip>0</slip>
              </ode>
            </torsional>
          </friction>
          <bounce>
            <restitution_coefficient>0</restitution_coefficient>
            <threshold>1e+06</threshold>
          </bounce>
        </surface>
      </collision>

      <visual name='top_back_visual'>
        <pose frame=''>0 -0.22 0.43 0 -0 0</pose>
        <geometry>
          <box>
            <size>0.6 0.01 0.07</size>
          </box>
        </geometry>
        <material>
          <lighting>1</lighting>
          <script>
            <uri>file://media/materials/scripts/gazebo.material</uri>
            <name>Gazebo/Black</name>
          </script>
        </material>
        <cast_shadows>1</cast_shadows>
        <transparency>0</transparency>
      </visual>
      <collision name='top_back_collision'>
        <laser_retro>0</laser_retro>
        <max_contacts>10</max_contacts>
        <pose frame=''>0 -0.22 0.43 0 -0 0</pose>
        <geometry>
          <box>
            <size>0.6 0.01 0.07</size>
          </box>
        </geometry>
        <surface>
          <friction>
            <ode>
              <mu>1</mu>
              <mu2>1</mu2>
              <fdir1>0 0 0</fdir1>
              <slip1>0</slip1>
              <slip2>0</slip2>
            </ode>
            <torsional>
              <coefficient>1</coefficient>
              <patch_radius>0</patch_radius>
              <surface_radius>0</surface_radius>
              <use_patch_radius>1</use_patch_radius>
              <ode>
                <slip>0</slip>
              </ode>
            </torsional>
          </friction>
          <bounce>
            <restitution_coefficient>0</restitution_coefficient>
            <threshold>1e+06</threshold>
          </bounce>
        </surface>
      </collision>

      <visual name='top_right_visual'>
        <pose frame=''>0.295 0 0.43 0 -0 0</pose>
        <geometry>
          <box>
            <size>0.01 0.43 0.07</size>
          </box>
        </geometry>
        <material>
          <lighting>1</lighting>
          <script>
            <uri>file://media/materials/scripts/gazebo.material</uri>
            <name>Gazebo/Black</name>
          </script>
        </material>
        <cast_shadows>1</cast_shadows>
        <transparency>0</transparency>
      </visual>
      <collision name='top_right_collision'>
        <laser_retro>0</laser_retro>
        <max_contacts>10</max_contacts>
        <pose frame=''>0.295 0 0.43 0 -0 0</pose>
        <geometry>
          <box>
            <size>0.01 0.43 0.07</size>
          </box>
        </geometry>
        <surface>
          <friction>
            <ode>
              <mu>1</mu>
              <mu2>1</mu2>
              <fdir1>0 0 0</fdir1>
              <slip1>0</slip1>
              <slip2>0</slip2>
            </ode>
            <torsional>
              <coefficient>1</coefficient>
              <patch_radius>0</patch_radius>
              <surface_radius>0</surface_radius>
              <use_patch_radius>1</use_patch_radius>
              <ode>
                <slip>0</slip>
              </ode>
            </torsional>
          </friction>
          <bounce>
            <restitution_coefficient>0</restitution_coefficient>
            <threshold>1e+06</threshold>
          </bounce>
        </surface>
      </collision>

      <visual name='top_left_visual'>
        <pose frame=''>-0.295 0 0.43 0 -0 0</pose>
        <geometry>
          <box>
            <size>0.01 0.43 0.07</size>
          </box>
        </geometry>
        <material>
          <lighting>1</lighting>
          <script>
            <uri>file://media/materials/scripts/gazebo.material</uri>
            <name>Gazebo/Black</name>
          </script>
        </material>
        <cast_shadows>1</cast_shadows>
        <transparency>0</transparency>
      </visual>
      <collision name='top_left_collision'>
        <laser_retro>0</laser_retro>
        <max_contacts>10</max_contacts>
        <pose frame=''>-0.295 0 0.43 0 -0 0</pose>
        <geometry>
          <box>
            <size>0.01 0.43 0.07</size>
          </box>
        </geometry>
        <surface>
          <friction>
            <ode>
              <mu>1</mu>
              <mu2>1</mu2>
              <fdir1>0 0 0</fdir1>
              <slip1>0</slip1>
              <slip2>0</slip2>
            </ode>
            <torsional>
              <coefficient>1</coefficient>
              <patch_radius>0</patch_radius>
              <surface_radius>0</surface_radius>
              <use_patch_radius>1</use_patch_radius>
              <ode>
                <slip>0</slip>
              </ode>
            </torsional>
          </friction>
          <bounce>
            <restitution_coefficient>0</restitution_coefficient>
            <threshold>1e+06</threshold>
          </bounce>
        </surface>
      </collision>

      <visual name='cylinder_front_right_visual'>
        <pose frame=''>0.269 0.194 0.23 0 -0 0</pose>
        <geometry>
          <cylinder>
            <radius>0.021</radius>
            <length>0.38</length>
          </cylinder>
        </geometry>
        <material>
          <lighting>1</lighting>
          <script>
            <uri>file://media/materials/scripts/gazebo.material</uri>
            <name>Gazebo/Black</name>
          </script>
        </material>
        <cast_shadows>1</cast_shadows>
        <transparency>0</transparency>
      </visual>
      <collision name='cylinder_front_right_collision'>
        <laser_retro>0</laser_retro>
        <max_contacts>10</max_contacts>
        <pose frame=''>0.269 0.194 0.23 0 -0 0</pose>
        <geometry>
          <cylinder>
            <radius>0.021</radius>
            <length>0.38</length>
          </cylinder>
        </geometry>
        <surface>
          <friction>
            <ode>
              <mu>1</mu>
              <mu2>1</mu2>
              <fdir1>0 0 0</fdir1>
              <slip1>0</slip1>
              <slip2>0</slip2>
            </ode>
            <torsional>
              <coefficient>1</coefficient>
              <patch_radius>0</patch_radius>
              <surface_radius>0</surface_radius>
              <use_patch_radius>1</use_patch_radius>
              <ode>
                <slip>0</slip>
              </ode>
            </torsional>
          </friction>
          <bounce>
            <restitution_coefficient>0</restitution_coefficient>
            <threshold>1e+06</threshold>
          </bounce>
        </surface>
      </collision>

      <visual name='cylinder_front_left_visual'>
        <pose frame=''>-0.269 0.194 0.23 0 -0 0</pose>
        <geometry>
          <cylinder>
            <radius>0.021</radius>
            <length>0.38</length>
          </cylinder>
        </geometry>
        <material>
          <lighting>1</lighting>
          <script>
            <uri>file://media/materials/scripts/gazebo.material</uri>
            <name>Gazebo/Black</name>
          </script>
        </material>
        <cast_shadows>1</cast_shadows>
        <transparency>0</transparency>
      </visual>
      <collision name='cylinder_front_left_collision'>
        <laser_retro>0</laser_retro>
        <max_contacts>10</max_contacts>
        <pose frame=''>-0.269 0.194 0.23 0 -0 0</pose>
        <geometry>
          <cylinder>
            <radius>0.021</radius>
            <length>0.38</length>
          </cylinder>
        </geometry>
        <surface>
          <friction>
            <ode>
              <mu>1</mu>
              <mu2>1</mu2>
              <fdir1>0 0 0</fdir1>
              <slip1>0</slip1>
              <slip2>0</slip2>
            </ode>
            <torsional>
              <coefficient>1</coefficient>
              <patch_radius>0</patch_radius>
              <surface_radius>0</surface_radius>
              <use_patch_radius>1</use_patch_radius>
              <ode>
                <slip>0</slip>
              </ode>
            </torsional>
          </friction>
          <bounce>
            <restitution_coefficient>0</restitution_coefficient>
            <threshold>1e+06</threshold>
          </bounce>
        </surface>
      </collision>

      <visual name='cylinder_back_left_visual'>
        <pose frame=''>-0.269 -0.194 0.23 0 -0 0</pose>
        <geometry>
          <cylinder>
            <radius>0.021</radius>
            <length>0.38</length>
          </cylinder>
        </geometry>
        <material>
          <lighting>1</lighting>
          <script>
            <uri>file://media/materials/scripts/gazebo.material</uri>
            <name>Gazebo/Black</name>
          </script>
        </material>
        <cast_shadows>1</cast_shadows>
        <transparency>0</transparency>
      </visual>
      <collision name='cylinder_back_left_collision'>
        <laser_retro>0</laser_retro>
        <max_contacts>10</max_contacts>
        <pose frame=''>-0.269 -0.194 0.23 0 -0 0</pose>
        <geometry>
          <cylinder>
            <radius>0.021</radius>
            <length>0.38</length>
          </cylinder>
        </geometry>
        <surface>
          <friction>
            <ode>
              <mu>1</mu>
              <mu2>1</mu2>
              <fdir1>0 0 0</fdir1>
              <slip1>0</slip1>
              <slip2>0</slip2>
            </ode>
            <torsional>
              <coefficient>1</coefficient>
              <patch_radius>0</patch_radius>
              <surface_radius>0</surface_radius>
              <use_patch_radius>1</use_patch_radius>
              <ode>
                <slip>0</slip>
              </ode>
            </torsional>
          </friction>
          <bounce>
            <restitution_coefficient>0</restitution_coefficient>
            <threshold>1e+06</threshold>
          </bounce>
        </surface>
      </collision>

      <visual name='cylinder_back_right_visual'>
        <pose frame=''>0.269 -0.194 0.23 0 -0 0</pose>
        <geometry>
          <cylinder>
            <radius>0.021</radius>
            <length>0.38</length>
          </cylinder>
        </geometry>
        <material>
          <lighting>1</lighting>
          <script>
            <uri>file://media/materials/scripts/gazebo.material</uri>
            <name>Gazebo/Black</name>
          </script>
        </material>
        <cast_shadows>1</cast_shadows>
        <transparency>0</transparency>
      </visual>
      <collision name='cylinder_back_right_collision'>
        <laser_retro>0</laser_retro>
        <max_contacts>10</max_contacts>
        <pose frame=''>0.269 -0.194 0.23 0 -0 0</pose>
        <geometry>
          <cylinder>
            <radius>0.021</radius>
            <length>0.38</length>
          </cylinder>
        </geometry>
        <surface>
          <friction>
            <ode>
              <mu>1</mu>
              <mu2>1</mu2>
              <fdir1>0 0 0</fdir1>
              <slip1>0</slip1>
              <slip2>0</slip2>
            </ode>
            <torsional>
              <coefficient>1</coefficient>
              <patch_radius>0</patch_radius>
              <surface_radius>0</surface_radius>
              <use_patch_radius>1</use_patch_radius>
              <ode>
                <slip>0</slip>
              </ode>
            </torsional>
          </friction>
          <bounce>
            <restitution_coefficient>0</restitution_coefficient>
            <threshold>1e+06</threshold>
          </bounce>
        </surface>
      </collision>
    </link>

    <include>
      <name>tag_length_front</name>
      <uri>model://tag36_11_00003</uri>
      <pose>0 0.232 0.12 0 0 1.57</pose>
      <static>false</static>
    </include>
    <joint name="tag_length_front_joint" type="fixed">
      <child>tag_length_front::link</child>
      <parent>cart_main</parent>
    </joint>

    <include>
      <name>tag_length_back</name>
      <uri>model://tag36_11_00003</uri>
      <pose>0 -0.232 0.12 0 0 -1.57</pose>
      <static>false</static>
    </include>
    <joint name="tag_length_back_joint" type="fixed">
      <child>tag_length_back::link</child>
      <parent>cart_main</parent>
    </joint>

    <include>
      <name>tag_width_right</name>
      <uri>model://tag36_11_00001</uri>
      <pose>0.307 0 0.12 0 0 0</pose>
      <static>false</static>
    </include>
    <joint name="tag_width_right_joint" type="fixed">
      <child>tag_width_right::link</child>
      <parent>cart_main</parent>
    </joint>

    <include>
      <name>tag_width_left</name>
      <uri>model://tag36_11_00001</uri>
      <pose>-0.307 0 0.12 0 0 3.14</pose>
      <static>false</static>
    </include>
    <joint name="tag_width_left_joint" type="fixed">
      <child>tag_width_left::link</child>
      <parent>cart_main</parent>
    </joint>

    <include>
      <name>caster_front_left</name>
      <uri>model://caster_cart</uri>
      <pose>-0.269 0.194 0.12 0 0 3.14</pose>
    </include>
    <joint name="caster_front_left_joint" type="revolute">
      <child>caster_front_left::caster_top</child>
      <parent>cart_main</parent>
      <axis>
        <xyz>0 0 1</xyz>
        <dynamics>
          <damping>0.01</damping>
        </dynamics>
      </axis>
    </joint>

    <include>
      <name>caster_front_right</name>
      <uri>model://caster_cart</uri>
      <pose>0.269 0.194 0.12 0 0 3.14</pose>
    </include>
    <joint name="caster_front_right_joint" type="revolute">
      <child>caster_front_right::caster_top</child>
      <parent>cart_main</parent>
      <axis>
        <xyz>0 0 1</xyz>
        <dynamics>
          <damping>0.01</damping>
        </dynamics>
      </axis>
    </joint>

    <include>
      <name>caster_back_right</name>
      <uri>model://caster_cart</uri>
      <pose>0.269 -0.194 0.12 0 0 3.14</pose>
    </include>
    <joint name="caster_back_right_joint" type="revolute">
      <child>caster_back_right::caster_top</child>
      <parent>cart_main</parent>
      <axis>
        <xyz>0 0 1</xyz>
        <dynamics>
          <damping>0.01</damping>
        </dynamics>
      </axis>
    </joint>

    <include>
      <name>caster_back_left</name>
      <uri>model://caster_cart</uri>
      <pose>-0.269 -0.194 0.12 0 0 3.14</pose>
    </include>
    <joint name="caster_back_left_joint" type="revolute">
      <child>caster_back_left::caster_top</child>
      <parent>cart_main</parent>
      <axis>
        <xyz>0 0 1</xyz>
        <dynamics>
          <damping>0.01</damping>
        </dynamics>
      </axis>
    </joint>

    <static>0</static>
    <allow_auto_disable>1</allow_auto_disable>
  </model>
</sdf>
