<?xml version="1.0" ?>
<!-- =================================================================================== -->
<!-- |    This document was autogenerated by xacro from /home/ylo2/catkin_ws/src/quad-sdk/quad_simulator/ylo2_description/xacro/robot.xacro | -->
<!-- |    EDITING THIS FILE BY HAND IS NOT RECOMMENDED                                 | -->
<!-- =================================================================================== -->
<robot name="ylo2">
  <!-- Constants for robot dimensions -->
  <!-- simplified collision value for ylo2 -->
  <!-- body -->
  <!-- adjust center of robot -->
  <!-- leg params. -->
  <!-- kinematic value -->
  <!-- lower leg size, from lower leg axis to end foot -->
  <!-- leg offset from trunk center value -->
  <!-- joint limits -->
  <!-- dynamics inertial value 
            | ixx ixy ixz |
            | ixy iyy iyz |
            | ixz iyz izz | -->
  <!-- trunk -->
  <!-- 0.000194 -->
  <!-- hip (left front) -->
  <!-- upperleg -->
  <!-- lowerleg -->
  <!-- foot -->
  <link name="world"/>
  <joint name="floating_base_joint" type="floating">
    <origin rpy="0 0 0" xyz="0 0 0"/>
    <parent link="world"/>
    <child link="trunk"/>
  </joint>
  <link name="trunk">
    <visual>
      <origin rpy="0 0 0" xyz="0.0 0 0.0"/>
      <geometry>
        <mesh filename="package://ylo2_description/meshes/body/textured/ylo2_textured_body.dae" scale="1 1 1"/>
      </geometry>
      <material name="grey"/>
    </visual>
    <collision>
      <origin rpy="0 0 0" xyz="0.0 0 0.0"/>
      <geometry>
        <mesh filename="package://ylo2_description/meshes/body/covers_collision.stl" scale="1 1 1"/>
      </geometry>
    </collision>
    <inertial>
      <origin rpy="0 0 0" xyz="0.02 0.00194 0.0"/>
      <mass value="3.128"/>
      <inertia ixx="0.01585" ixy="-0.0001332" ixz="-0.0002403" iyy="0.04168" iyz="1.5299e-05" izz="0.04742"/>
    </inertial>
  </link>
  <link name="abad_motors">
    <visual>
      <origin rpy="0 0 0" xyz="0.0 0.0 0.0"/>
      <geometry>
        <mesh filename="package://ylo2_description/meshes/body/textured/ylo2_textured_abad_motors.dae" scale="1 1 1"/>
      </geometry>
      <material name="white"/>
    </visual>
  </link>
  <joint name="abad_motors_joint" type="fixed">
    <parent link="trunk"/>
    <child link="abad_motors"/>
    <origin rpy="0 0 0" xyz="0 0 0"/>
  </joint>
  <link name="battery">
    <visual>
      <origin rpy="0 0 0" xyz="0.0 0.0 0.0"/>
      <geometry>
        <mesh filename="package://ylo2_description/meshes/body/battery.stl" scale="1 1 1"/>
      </geometry>
      <material name="blue"/>
    </visual>
  </link>
  <joint name="battery_joint" type="fixed">
    <parent link="trunk"/>
    <child link="battery"/>
    <origin rpy="0 0 0" xyz="0 0 0"/>
  </joint>
  <link name="covers">
    <visual>
      <origin rpy="0 0 0" xyz="0.0 0.0 0.0"/>
      <geometry>
        <mesh filename="package://ylo2_description/meshes/body/textured/ylo2_textured_cover.dae" scale="1 1 1"/>
      </geometry>
      <material name="orange"/>
    </visual>
  </link>
  <joint name="covers_joint" type="fixed">
    <parent link="trunk"/>
    <child link="covers"/>
    <origin rpy="0 0 0" xyz="0 0 0"/>
  </joint>
  <link name="accessories">
    <visual>
      <origin rpy="0 0 0" xyz="0.0 0.0 0.0"/>
      <geometry>
        <mesh filename="package://ylo2_description/meshes/body/textured/accessories.dae" scale="1 1 1"/>
      </geometry>
      <material name="blue"/>
    </visual>
  </link>
  <joint name="accessories_joint" type="fixed">
    <parent link="trunk"/>
    <child link="accessories"/>
    <origin rpy="0 0 0" xyz="0 0 0"/>
  </joint>
  <link name="D435">
    <visual>
      <origin rpy="0 0 0" xyz="0.0 0.004 0.0"/>
      <geometry>
        <mesh filename="package://ylo2_description/meshes/body/textured/ylo2_d435_textured.dae" scale="1 1 1"/>
      </geometry>
      <material name="black"/>
    </visual>
  </link>
  <joint name="D435_joint" type="fixed">
    <parent link="trunk"/>
    <child link="D435"/>
    <origin rpy="0 0 0" xyz="0 0 0"/>
  </joint>
  <link name="T265">
    <visual>
      <origin rpy="0 0 0" xyz="0.001 0.0025 0.0"/>
      <geometry>
        <mesh filename="package://ylo2_description/meshes/body/textured/ylo2_t265_textured.dae" scale="1 1.06 1.04"/>
      </geometry>
      <material name="black"/>
    </visual>
  </link>
  <joint name="T265_joint" type="fixed">
    <parent link="trunk"/>
    <child link="T265"/>
    <origin rpy="0 0 0" xyz="0 0 0"/>
  </joint>
  <joint name="imu_joint" type="fixed">
    <parent link="trunk"/>
    <child link="trunk_imu"/>
    <origin rpy="0 0 0" xyz="0 0 0"/>
  </joint>
  <link name="trunk_imu">
    <inertial>
      <mass value="0.001"/>
      <origin rpy="0 0 0" xyz="0 0 0"/>
      <inertia ixx="0.0001" ixy="0" ixz="0" iyy="0.000001" iyz="0" izz="0.0001"/>
    </inertial>
    <visual>
      <origin rpy="0 0 0" xyz="0 0 0"/>
      <geometry>
        <box size="0.001 0.001 0.001"/>
      </geometry>
      <material name="red"/>
    </visual>
    <collision>
      <origin rpy="0 0 0" xyz="0 0 0"/>
      <geometry>
        <box size=".001 .001 .001"/>
      </geometry>
    </collision>
  </link>
  <joint name="rf_haa_joint" type="revolute">
    <origin rpy="0 0 0" xyz="0.17450000000000002 -0.0512 0.023"/>
    <parent link="trunk"/>
    <child link="rf_hip"/>
    <axis xyz="1 0 0"/>
    <dynamics damping="0" friction="0"/>
    <limit effort="14" lower="-1.2217304763960306" upper="1.2217304763960306" velocity="20"/>
  </joint>
  <link name="rf_hip">
    <!-- AB AD -->
    <visual>
      <origin rpy="3.141592653589793 0 0" xyz="-0.06 0 0"/>
      <geometry>
        <mesh filename="package://ylo2_description/meshes/leg/textured/ylo2texturedhip.dae" scale="1 1 1"/>
      </geometry>
      <material name="white"/>
    </visual>
    <inertial>
      <origin rpy="0 0 0" xyz="-0.011957 -0.000306 0.000366"/>
      <mass value="0.599"/>
      <inertia ixx="0.0004159" ixy="-4.253e-06" ixz="3.68e-07" iyy="0.0007108" iyz="-2.15e-07" izz="0.0004707"/>
    </inertial>
  </link>
  <joint name="rf_hfe_joint" type="continuous">
    <origin rpy="0 0 0" xyz="0.0 -0.092 0"/>
    <parent link="rf_hip"/>
    <child link="rf_upperleg"/>
    <axis xyz="0 1 0"/>
    <dynamics damping="0" friction="0"/>
    <limit effort="14" velocity="20"/>
  </joint>
  <link name="rf_upperleg">
    <visual>
      <origin rpy="0 0 0" xyz="0 0.0732 0"/>
      <!-- positionnement des 4 axes en meme temps -->
      <geometry>
        <mesh filename="package://ylo2_description/meshes/leg/textured/ylo2_textured_upper_leg.dae" scale="1 -1 1"/>
      </geometry>
      <material name="grey"/>
    </visual>
    <collision>
      <origin rpy="0 0 0" xyz="0 0.0732 0"/>
      <!-- positionnement des 4 axes en meme temps -->
      <geometry>
        <mesh filename="package://ylo2_description/meshes/leg/fl_upper_leg_collision.stl" scale="1 -1 1"/>
      </geometry>
      <material name="red"/>
    </collision>
    <inertial>
      <origin rpy="0 0 0" xyz="-0.000684 0.010999 -0.035487"/>
      <mass value="1.08"/>
      <inertia ixx="0.005666803" ixy="-3.597e-06" ixz="0.000491446" iyy="0.005847229" iyz="-1.0086e-05" izz="0.000369811"/>
    </inertial>
  </link>
  <joint name="rf_kfe_joint" type="revolute">
    <origin rpy="0 0 0" xyz="0 -0.001 -0.215427"/>
    <parent link="rf_upperleg"/>
    <child link="rf_lowerleg"/>
    <axis xyz="0 1 0"/>
    <dynamics damping="0" friction="0"/>
    <limit effort="14" lower="-2.775073510670984" upper="-0.6457718232379019" velocity="15"/>
  </joint>
  <link name="rf_lowerleg">
    <visual>
      <origin rpy="0 0 0" xyz="0 -0.001 0"/>
      <geometry>
        <mesh filename="package://ylo2_description/meshes/leg/textured/lower_leg.dae" scale="1 1 1"/>
      </geometry>
      <material name="white"/>
    </visual>
    <collision>
      <origin rpy="0 0 0" xyz="0 -0.001 0"/>
      <geometry>
        <mesh filename="package://ylo2_description/meshes/leg/fl_lower_leg_collision.stl" scale="1 -1 1"/>
      </geometry>
      <material name="red"/>
    </collision>
    <inertial>
      <origin rpy="0 0 0" xyz="0.000252 0.000194 -0.05192"/>
      <mass value="0.175"/>
      <inertia ixx="0.0004583" ixy="-9.5e-08" ixz="2.6512e-05" iyy="0.0004675" iyz="2.77e-07" izz="2.9145e-05"/>
    </inertial>
  </link>
  <joint name="rf_foot_fixed" type="fixed">
    <origin rpy="0 0 0" xyz="0 0 -0.229819"/>
    <parent link="rf_lowerleg"/>
    <child link="rf_foot"/>
  </joint>
  <link name="rf_foot">
    <inertial>
      <origin rpy="0 0 0" xyz="-0.007246 9.2e-05 -0.038267"/>
      <mass value="0.078"/>
      <inertia ixx="2.9902e-05" ixy="-2.2e-08" ixz="-4.427e-06" iyy="3.0583e-05" iyz="-9.9e-08" izz="1.4025e-05"/>
    </inertial>
    <visual>
      <origin rpy="0 0 0" xyz="0.009 0.0 0.069"/>
      <geometry>
        <mesh filename="package://ylo2_description/meshes/leg/fl_foot.dae" scale="1.0 1.0 1.0"/>
      </geometry>
      <material name="orange"/>
    </visual>
    <collision>
      <origin rpy="0 0 0" xyz="0.009 0.0 0.069"/>
      <geometry>
        <mesh filename="package://ylo2_description/meshes/leg/fl_foot_collision.stl" scale="1.0 1.0 1.0"/>
      </geometry>
      <material name="red"/>
    </collision>
  </link>
  <joint name="lf_haa_joint" type="revolute">
    <origin rpy="0 0 0" xyz="0.17450000000000002 0.0632 0.023"/>
    <parent link="trunk"/>
    <child link="lf_hip"/>
    <axis xyz="1 0 0"/>
    <dynamics damping="0" friction="0"/>
    <limit effort="14" lower="-1.2217304763960306" upper="1.2217304763960306" velocity="20"/>
  </joint>
  <link name="lf_hip">
    <!-- AB AD -->
    <visual>
      <origin rpy="0 0 0" xyz="-0.06 0 0"/>
      <geometry>
        <mesh filename="package://ylo2_description/meshes/leg/textured/ylo2texturedhip.dae" scale="1 1 1"/>
      </geometry>
      <material name="white"/>
    </visual>
    <inertial>
      <origin rpy="0 0 0" xyz="-0.011957 0.000306 0.000366"/>
      <mass value="0.599"/>
      <inertia ixx="0.0004159" ixy="4.253e-06" ixz="3.68e-07" iyy="0.0007108" iyz="2.15e-07" izz="0.0004707"/>
    </inertial>
  </link>
  <joint name="lf_hfe_joint" type="continuous">
    <origin rpy="0 0 0" xyz="0.0 0.092 0"/>
    <parent link="lf_hip"/>
    <child link="lf_upperleg"/>
    <axis xyz="0 1 0"/>
    <dynamics damping="0" friction="0"/>
    <limit effort="14" velocity="20"/>
  </joint>
  <link name="lf_upperleg">
    <visual>
      <origin rpy="0 0 0" xyz="0 -0.0732 0"/>
      <!-- positionnement des 4 axes en meme temps -->
      <geometry>
        <mesh filename="package://ylo2_description/meshes/leg/textured/ylo2_textured_upper_leg.dae" scale="1 1 1"/>
      </geometry>
      <material name="grey"/>
    </visual>
    <collision>
      <origin rpy="0 0 0" xyz="0 -0.0732 0"/>
      <!-- positionnement des 4 axes en meme temps -->
      <geometry>
        <mesh filename="package://ylo2_description/meshes/leg/fl_upper_leg_collision.stl" scale="1 1 1"/>
      </geometry>
      <material name="red"/>
    </collision>
    <inertial>
      <origin rpy="0 0 0" xyz="-0.000684 -0.010999 -0.035487"/>
      <mass value="1.08"/>
      <inertia ixx="0.005666803" ixy="3.597e-06" ixz="0.000491446" iyy="0.005847229" iyz="1.0086e-05" izz="0.000369811"/>
    </inertial>
  </link>
  <joint name="lf_kfe_joint" type="revolute">
    <origin rpy="0 0 0" xyz="0 -0.001 -0.215427"/>
    <parent link="lf_upperleg"/>
    <child link="lf_lowerleg"/>
    <axis xyz="0 1 0"/>
    <dynamics damping="0" friction="0"/>
    <limit effort="14" lower="-2.775073510670984" upper="-0.6457718232379019" velocity="15"/>
  </joint>
  <link name="lf_lowerleg">
    <visual>
      <origin rpy="0 0 0" xyz="0 0.001 0"/>
      <geometry>
        <mesh filename="package://ylo2_description/meshes/leg/textured/lower_leg.dae" scale="1 1 1"/>
      </geometry>
      <material name="white"/>
    </visual>
    <collision>
      <origin rpy="0 0 0" xyz="0 0.001 0"/>
      <geometry>
        <mesh filename="package://ylo2_description/meshes/leg/fl_lower_leg_collision.stl" scale="1 -1 1"/>
      </geometry>
      <material name="red"/>
    </collision>
    <inertial>
      <origin rpy="0 0 0" xyz="0.000252 0.000194 -0.05192"/>
      <mass value="0.175"/>
      <inertia ixx="0.0004583" ixy="-9.5e-08" ixz="2.6512e-05" iyy="0.0004675" iyz="2.77e-07" izz="2.9145e-05"/>
    </inertial>
  </link>
  <joint name="lf_foot_fixed" type="fixed">
    <origin rpy="0 0 0" xyz="0 0 -0.229819"/>
    <parent link="lf_lowerleg"/>
    <child link="lf_foot"/>
  </joint>
  <link name="lf_foot">
    <inertial>
      <origin rpy="0 0 0" xyz="-0.007246 9.2e-05 -0.038267"/>
      <mass value="0.078"/>
      <inertia ixx="2.9902e-05" ixy="-2.2e-08" ixz="-4.427e-06" iyy="3.0583e-05" iyz="-9.9e-08" izz="1.4025e-05"/>
    </inertial>
    <visual>
      <origin rpy="0 0 0" xyz="0.009 0.002 0.069"/>
      <geometry>
        <mesh filename="package://ylo2_description/meshes/leg/fl_foot.dae" scale="1.0 1.0 1.0"/>
      </geometry>
      <material name="orange"/>
    </visual>
    <collision>
      <origin rpy="0 0 0" xyz="0.009 0.002 0.069"/>
      <geometry>
        <mesh filename="package://ylo2_description/meshes/leg/fl_foot_collision.stl" scale="1.0 1.0 1.0"/>
      </geometry>
      <material name="red"/>
    </collision>
  </link>
  <joint name="rh_haa_joint" type="revolute">
    <origin rpy="0 0 0" xyz="-0.2125 -0.0512 0.023"/>
    <parent link="trunk"/>
    <child link="rh_hip"/>
    <axis xyz="1 0 0"/>
    <dynamics damping="0" friction="0"/>
    <limit effort="14" lower="-1.2217304763960306" upper="1.2217304763960306" velocity="20"/>
  </joint>
  <link name="rh_hip">
    <!-- AB AD -->
    <visual>
      <origin rpy="3.141592653589793 3.141592653589793 0" xyz="0.06 0 0"/>
      <geometry>
        <mesh filename="package://ylo2_description/meshes/leg/textured/ylo2texturedhip.dae" scale="1 1 1"/>
      </geometry>
      <material name="white"/>
    </visual>
    <inertial>
      <origin rpy="0 0 0" xyz="0.011957 -0.000306 0.000366"/>
      <mass value="0.599"/>
      <inertia ixx="0.0004159" ixy="4.253e-06" ixz="-3.68e-07" iyy="0.0007108" iyz="-2.15e-07" izz="0.0004707"/>
    </inertial>
  </link>
  <joint name="rh_hfe_joint" type="continuous">
    <origin rpy="0 0 0" xyz="0.0 -0.092 0"/>
    <parent link="rh_hip"/>
    <child link="rh_upperleg"/>
    <axis xyz="0 1 0"/>
    <dynamics damping="0" friction="0"/>
    <limit effort="14" velocity="20"/>
  </joint>
  <link name="rh_upperleg">
    <visual>
      <origin rpy="0 0 0" xyz="0 0.0732 0"/>
      <!-- positionnement des 4 axes en meme temps -->
      <geometry>
        <mesh filename="package://ylo2_description/meshes/leg/textured/ylo2_textured_upper_leg.dae" scale="1 -1 1"/>
      </geometry>
      <material name="grey"/>
    </visual>
    <collision>
      <origin rpy="0 0 0" xyz="0 0.0732 0"/>
      <!-- positionnement des 4 axes en meme temps -->
      <geometry>
        <mesh filename="package://ylo2_description/meshes/leg/fl_upper_leg_collision.stl" scale="1 -1 1"/>
      </geometry>
      <material name="red"/>
    </collision>
    <inertial>
      <origin rpy="0 0 0" xyz="-0.000684 0.010999 -0.035487"/>
      <mass value="1.08"/>
      <inertia ixx="0.005666803" ixy="-3.597e-06" ixz="0.000491446" iyy="0.005847229" iyz="-1.0086e-05" izz="0.000369811"/>
    </inertial>
  </link>
  <joint name="rh_kfe_joint" type="revolute">
    <origin rpy="0 0 0" xyz="0 -0.001 -0.215427"/>
    <parent link="rh_upperleg"/>
    <child link="rh_lowerleg"/>
    <axis xyz="0 1 0"/>
    <dynamics damping="0" friction="0"/>
    <limit effort="14" lower="-2.775073510670984" upper="-0.6457718232379019" velocity="15"/>
  </joint>
  <link name="rh_lowerleg">
    <visual>
      <origin rpy="0 0 0" xyz="0 -0.001 0"/>
      <geometry>
        <mesh filename="package://ylo2_description/meshes/leg/textured/lower_leg.dae" scale="1 1 1"/>
      </geometry>
      <material name="white"/>
    </visual>
    <collision>
      <origin rpy="0 0 0" xyz="0 -0.001 0"/>
      <geometry>
        <mesh filename="package://ylo2_description/meshes/leg/fl_lower_leg_collision.stl" scale="1 -1 1"/>
      </geometry>
      <material name="red"/>
    </collision>
    <inertial>
      <origin rpy="0 0 0" xyz="0.000252 0.000194 -0.05192"/>
      <mass value="0.175"/>
      <inertia ixx="0.0004583" ixy="-9.5e-08" ixz="2.6512e-05" iyy="0.0004675" iyz="2.77e-07" izz="2.9145e-05"/>
    </inertial>
  </link>
  <joint name="rh_foot_fixed" type="fixed">
    <origin rpy="0 0 0" xyz="0 0 -0.229819"/>
    <parent link="rh_lowerleg"/>
    <child link="rh_foot"/>
  </joint>
  <link name="rh_foot">
    <inertial>
      <origin rpy="0 0 0" xyz="-0.007246 9.2e-05 -0.038267"/>
      <mass value="0.078"/>
      <inertia ixx="2.9902e-05" ixy="-2.2e-08" ixz="-4.427e-06" iyy="3.0583e-05" iyz="-9.9e-08" izz="1.4025e-05"/>
    </inertial>
    <visual>
      <origin rpy="0 0 0" xyz="0.009 0.0 0.069"/>
      <geometry>
        <mesh filename="package://ylo2_description/meshes/leg/fl_foot.dae" scale="1.0 1.0 1.0"/>
      </geometry>
      <material name="orange"/>
    </visual>
    <collision>
      <origin rpy="0 0 0" xyz="0.009 0.0 0.069"/>
      <geometry>
        <mesh filename="package://ylo2_description/meshes/leg/fl_foot_collision.stl" scale="1.0 1.0 1.0"/>
      </geometry>
      <material name="red"/>
    </collision>
  </link>
  <joint name="lh_haa_joint" type="revolute">
    <origin rpy="0 0 0" xyz="-0.2125 0.0632 0.023"/>
    <parent link="trunk"/>
    <child link="lh_hip"/>
    <axis xyz="1 0 0"/>
    <dynamics damping="0" friction="0"/>
    <limit effort="14" lower="-1.2217304763960306" upper="1.2217304763960306" velocity="20"/>
  </joint>
  <link name="lh_hip">
    <!-- AB AD -->
    <visual>
      <origin rpy="0 3.141592653589793 0" xyz="0.06 0 0"/>
      <geometry>
        <mesh filename="package://ylo2_description/meshes/leg/textured/ylo2texturedhip.dae" scale="1 1 1"/>
      </geometry>
      <material name="white"/>
    </visual>
    <inertial>
      <origin rpy="0 0 0" xyz="0.011957 0.000306 0.000366"/>
      <mass value="0.599"/>
      <inertia ixx="0.0004159" ixy="-4.253e-06" ixz="-3.68e-07" iyy="0.0007108" iyz="2.15e-07" izz="0.0004707"/>
    </inertial>
  </link>
  <joint name="lh_hfe_joint" type="continuous">
    <origin rpy="0 0 0" xyz="0.0 0.092 0"/>
    <parent link="lh_hip"/>
    <child link="lh_upperleg"/>
    <axis xyz="0 1 0"/>
    <dynamics damping="0" friction="0"/>
    <limit effort="14" velocity="20"/>
  </joint>
  <link name="lh_upperleg">
    <visual>
      <origin rpy="0 0 0" xyz="0 -0.0732 0"/>
      <!-- positionnement des 4 axes en meme temps -->
      <geometry>
        <mesh filename="package://ylo2_description/meshes/leg/textured/ylo2_textured_upper_leg.dae" scale="1 1 1"/>
      </geometry>
      <material name="grey"/>
    </visual>
    <collision>
      <origin rpy="0 0 0" xyz="0 -0.0732 0"/>
      <!-- positionnement des 4 axes en meme temps -->
      <geometry>
        <mesh filename="package://ylo2_description/meshes/leg/fl_upper_leg_collision.stl" scale="1 1 1"/>
      </geometry>
      <material name="red"/>
    </collision>
    <inertial>
      <origin rpy="0 0 0" xyz="-0.000684 -0.010999 -0.035487"/>
      <mass value="1.08"/>
      <inertia ixx="0.005666803" ixy="3.597e-06" ixz="0.000491446" iyy="0.005847229" iyz="1.0086e-05" izz="0.000369811"/>
    </inertial>
  </link>
  <joint name="lh_kfe_joint" type="revolute">
    <origin rpy="0 0 0" xyz="0 -0.001 -0.215427"/>
    <parent link="lh_upperleg"/>
    <child link="lh_lowerleg"/>
    <axis xyz="0 1 0"/>
    <dynamics damping="0" friction="0"/>
    <limit effort="14" lower="-2.775073510670984" upper="-0.6457718232379019" velocity="15"/>
  </joint>
  <link name="lh_lowerleg">
    <visual>
      <origin rpy="0 0 0" xyz="0 0.001 0"/>
      <geometry>
        <mesh filename="package://ylo2_description/meshes/leg/textured/lower_leg.dae" scale="1 1 1"/>
      </geometry>
      <material name="white"/>
    </visual>
    <collision>
      <origin rpy="0 0 0" xyz="0 0.001 0"/>
      <geometry>
        <mesh filename="package://ylo2_description/meshes/leg/fl_lower_leg_collision.stl" scale="1 -1 1"/>
      </geometry>
      <material name="red"/>
    </collision>
    <inertial>
      <origin rpy="0 0 0" xyz="0.000252 0.000194 -0.05192"/>
      <mass value="0.175"/>
      <inertia ixx="0.0004583" ixy="-9.5e-08" ixz="2.6512e-05" iyy="0.0004675" iyz="2.77e-07" izz="2.9145e-05"/>
    </inertial>
  </link>
  <joint name="lh_foot_fixed" type="fixed">
    <origin rpy="0 0 0" xyz="0 0 -0.229819"/>
    <parent link="lh_lowerleg"/>
    <child link="lh_foot"/>
  </joint>
  <link name="lh_foot">
    <inertial>
      <origin rpy="0 0 0" xyz="-0.007246 9.2e-05 -0.038267"/>
      <mass value="0.078"/>
      <inertia ixx="2.9902e-05" ixy="-2.2e-08" ixz="-4.427e-06" iyy="3.0583e-05" iyz="-9.9e-08" izz="1.4025e-05"/>
    </inertial>
    <visual>
      <origin rpy="0 0 0" xyz="0.009 0.002 0.069"/>
      <geometry>
        <mesh filename="package://ylo2_description/meshes/leg/fl_foot.dae" scale="1.0 1.0 1.0"/>
      </geometry>
      <material name="orange"/>
    </visual>
    <collision>
      <origin rpy="0 0 0" xyz="0.009 0.002 0.069"/>
      <geometry>
        <mesh filename="package://ylo2_description/meshes/leg/fl_foot_collision.stl" scale="1.0 1.0 1.0"/>
      </geometry>
      <material name="red"/>
    </collision>
  </link>
</robot>
