<?xml version="1.0" ?>
<!-- =================================================================================== -->
<!-- |    This document was autogenerated by xacro from /home/ylo2/catkin_ws/src/quad-sdk/quad_simulator/ylo2_description/xacro/robot.xacro | -->
<!-- |    EDITING THIS FILE BY HAND IS NOT RECOMMENDED                                 | -->
<!-- =================================================================================== -->
<!-- file for use with quadruped-sdk ylo2 -->
<robot name="ylo2_description">
  <!-- lower leg size, from lower leg axis to end foot -->
  <material name="black">
    <color rgba="0.0 0.0 0.0 1.0"/>
  </material>
  <material name="blue">
    <color rgba="0.0 0.0 0.8 1.0"/>
  </material>
  <material name="green">
    <color rgba="0.0 0.8 0.0 1.0"/>
  </material>
  <material name="grey">
    <color rgba="0.2 0.2 0.2 1.0"/>
  </material>
  <material name="silver">
    <color rgba="0.9137254901960784 0.9137254901960784 0.8470588235294118 1.0"/>
  </material>
  <material name="orange">
    <color rgba="1.0 0.4235294117647059 0.0392156862745098 1.0"/>
  </material>
  <material name="brown">
    <color rgba="0.8705882352941177 0.8117647058823529 0.7647058823529411 1.0"/>
  </material>
  <material name="red">
    <color rgba="0.8 0.0 0.0 1.0"/>
  </material>
  <material name="white">
    <color rgba="1.0 1.0 1.0 1.0"/>
  </material>
  <!-- ros_control plugin -->
  <gazebo>
    <plugin filename="libgazebo_ros_control.so" name="gazebo_ros_control">
      <robotNamespace>/ylo2</robotNamespace>
      <robotSimType>gazebo_ros_control/DefaultRobotHWSim</robotSimType>
    </plugin>
    <plugin filename="libground_truth_estimator.so" name="ground_truth_estimator">
      <updateRateHZ>500.0</updateRateHZ>
    </plugin>
  </gazebo>
  <!-- Show the trajectory of trunk center. -->
  <!-- <gazebo>
        <plugin name="3dplot" filename="libLinkPlot3DPlugin.so">
            <frequency>10</frequency>
            <plot>
                <link>body</link>
                <pose>0 0 0 0 0 0</pose>
                <material>Gazebo/Yellow</material>
            </plot>
        </plugin>
    </gazebo> -->
  <!-- Show the trajectory of foot. You can add another trajectory about another foot. -->
  <!-- <gazebo>
        <plugin name="3dplot" filename="libLinkPlot3DPlugin.so">
            <frequency>100</frequency>
            <plot>
                <link>FL_foot</link>
                <pose>0 0 0 0 0 0</pose>
                <material>Gazebo/Green</material>
            </plot>
        </plugin>
    </gazebo> -->
  <gazebo>
    <plugin filename="libgazebo_ros_force.so" name="gazebo_ros_force">
      <bodyName>trunk</bodyName>
      <topicName>/apply_force/trunk</topicName>
    </plugin>
  </gazebo>
  <gazebo reference="imu_link">
    <gravity>true</gravity>
    <sensor name="imu_sensor" type="imu">
      <always_on>true</always_on>
      <update_rate>1000</update_rate>
      <visualize>true</visualize>
      <topic>__default_topic__</topic>
      <plugin filename="libgazebo_ros_imu_sensor.so" name="imu_plugin">
        <topicName>trunk_imu</topicName>
        <bodyName>imu_link</bodyName>
        <updateRateHZ>1000.0</updateRateHZ>
        <gaussianNoise>0.0</gaussianNoise>
        <xyzOffset>0 0 0</xyzOffset>
        <rpyOffset>0 0 0</rpyOffset>
        <frameName>imu_link</frameName>
      </plugin>
      <pose>0 0 0 0 0 0</pose>
    </sensor>
  </gazebo>
  <!-- Foot contacts. -->
  <!-- <gazebo reference="lower0">
        <sensor name="FR_foot_contact" type="contact">
        <update_rate>100</update_rate>
        <plugin name="contactPlugin" filename="libunitreeFootContactPlugin.so"/>
        <contact>
            <collision>FR_calf_fixed_joint_lump__FR_foot_collision_1</collision>
        </contact>
        </sensor>
    </gazebo>
    <gazebo reference="lower1">
        <sensor name="FL_foot_contact" type="contact">
        <update_rate>100</update_rate>
        <plugin name="contactPlugin" filename="libunitreeFootContactPlugin.so"/>
        <contact>
            <collision>FL_calf_fixed_joint_lump__FL_foot_collision_1</collision>
        </contact>
        </sensor>
    </gazebo>
    <gazebo reference="lower2">
        <sensor name="RR_foot_contact" type="contact">
        <update_rate>100</update_rate>
        <plugin name="contactPlugin" filename="libunitreeFootContactPlugin.so"/>
        <contact>
            <collision>RR_calf_fixed_joint_lump__RR_foot_collision_1</collision>
        </contact>
        </sensor>
    </gazebo>
    <gazebo reference="lower3">
        <sensor name="RL_foot_contact" type="contact">
        <update_rate>100</update_rate>
        <plugin name="contactPlugin" filename="libunitreeFootContactPlugin.so"/>
        <contact>
            <collision>RL_calf_fixed_joint_lump__RL_foot_collision_1</collision>
        </contact>
        </sensor>
    </gazebo> -->
  <gazebo reference="toe0">
    <sensor name="toe0_contact" type="contact">
      <plugin filename="libgazebo_ros_bumper.so" name="toe0_plugin">
        <alwaysOn>true</alwaysOn>
        <updateRate>500</updateRate>
        <bumperTopicName>gazebo/toe0_contact_state</bumperTopicName>
        <frameName>world</frameName>
      </plugin>
      <contact>
        <collision>toe0_collision</collision>
      </contact>
      <update_rate>500</update_rate>
    </sensor>
  </gazebo>
  <gazebo reference="toe1">
    <sensor name="toe1_contact" type="contact">
      <plugin filename="libgazebo_ros_bumper.so" name="toe1_plugin">
        <alwaysOn>true</alwaysOn>
        <updateRate>500</updateRate>
        <bumperTopicName>gazebo/toe1_contact_state</bumperTopicName>
        <frameName>world</frameName>
      </plugin>
      <contact>
        <collision>toe1_collision</collision>
      </contact>
      <update_rate>500</update_rate>
    </sensor>
  </gazebo>
  <gazebo reference="toe2">
    <sensor name="toe2_contact" type="contact">
      <plugin filename="libgazebo_ros_bumper.so" name="toe2_plugin">
        <alwaysOn>true</alwaysOn>
        <updateRate>500</updateRate>
        <bumperTopicName>gazebo/toe2_contact_state</bumperTopicName>
        <frameName>world</frameName>
      </plugin>
      <contact>
        <collision>toe2_collision</collision>
      </contact>
      <update_rate>500</update_rate>
    </sensor>
  </gazebo>
  <gazebo reference="toe3">
    <sensor name="toe3_contact" type="contact">
      <plugin filename="libgazebo_ros_bumper.so" name="toe3_plugin">
        <alwaysOn>true</alwaysOn>
        <updateRate>500</updateRate>
        <bumperTopicName>gazebo/toe3_contact_state</bumperTopicName>
        <frameName>world</frameName>
      </plugin>
      <contact>
        <collision>toe3_collision</collision>
      </contact>
      <update_rate>500</update_rate>
    </sensor>
  </gazebo>
  <!-- Visualization of Foot contacts. -->
  <!-- <gazebo reference="toe0">
        <visual>
            <plugin name="drawForcePlugin" filename="libunitreeDrawForcePlugin.so">
                <topicName>FR_foot_contact</topicName>
            </plugin>
        </visual>
    </gazebo>
    <gazebo reference="toe1">
        <visual>
            <plugin name="drawForcePlugin" filename="libunitreeDrawForcePlugin.so">
                <topicName>FL_foot_contact</topicName>
            </plugin>
        </visual>
    </gazebo>
    <gazebo reference="toe2">
        <visual>
            <plugin name="drawForcePlugin" filename="libunitreeDrawForcePlugin.so">
                <topicName>RR_foot_contact</topicName>
            </plugin>
        </visual>
    </gazebo>
    <gazebo reference="toe3">
        <visual>
            <plugin name="drawForcePlugin" filename="libunitreeDrawForcePlugin.so">
                <topicName>RL_foot_contact</topicName>
            </plugin>
        </visual>
    </gazebo> -->
  <gazebo reference="body">
    <material>Gazebo/Green</material>
    <turnGravityOff>false</turnGravityOff>
  </gazebo>
  <gazebo reference="trunk">
    <mu1>0.2</mu1>
    <mu2>0.2</mu2>
    <kp value="1000000.0"/>
    <kd value="1.0"/>
  </gazebo>
  <gazebo reference="stick_link">
    <mu1>0.2</mu1>
    <mu2>0.2</mu2>
    <material>Gazebo/White</material>
  </gazebo>
  <gazebo reference="imu_link">
    <mu1>0.2</mu1>
    <mu2>0.2</mu2>
    <material>Gazebo/Red</material>
  </gazebo>
  <!-- FL leg -->
  <gazebo reference="hip0">
    <mu1>0.2</mu1>
    <mu2>0.2</mu2>
    <material>Gazebo/DarkGrey</material>
  </gazebo>
  <gazebo reference="upper0">
    <mu1>0.2</mu1>
    <mu2>0.2</mu2>
    <self_collide>0</self_collide>
    <material>Gazebo/DarkGrey</material>
    <kp value="1000000.0"/>
    <kd value="1.0"/>
  </gazebo>
  <gazebo reference="lower0">
    <mu1>0.2</mu1>
    <mu2>0.2</mu2>
    <self_collide>0</self_collide>
  </gazebo>
  <gazebo reference="toe0">
    <mu1>0.6</mu1>
    <mu2>0.6</mu2>
    <self_collide>0</self_collide>
    <material>Gazebo/DarkGrey</material>
    <kp value="1000000.0"/>
    <kd value="1.0"/>
  </gazebo>
  <!-- RL leg -->
  <gazebo reference="hip1">
    <mu1>0.2</mu1>
    <mu2>0.2</mu2>
    <material>Gazebo/DarkGrey</material>
  </gazebo>
  <gazebo reference="upper1">
    <mu1>0.2</mu1>
    <mu2>0.2</mu2>
    <self_collide>0</self_collide>
    <material>Gazebo/DarkGrey</material>
    <kp value="1000000.0"/>
    <kd value="1.0"/>
  </gazebo>
  <gazebo reference="lower1">
    <mu1>0.2</mu1>
    <mu2>0.2</mu2>
    <self_collide>0</self_collide>
  </gazebo>
  <gazebo reference="toe1">
    <mu1>0.6</mu1>
    <mu2>0.6</mu2>
    <self_collide>0</self_collide>
    <material>Gazebo/DarkGrey</material>
    <kp value="1000000.0"/>
    <kd value="1.0"/>
  </gazebo>
  <!-- FR leg -->
  <gazebo reference="hip2">
    <mu1>0.2</mu1>
    <mu2>0.2</mu2>
    <material>Gazebo/DarkGrey</material>
  </gazebo>
  <gazebo reference="upper2">
    <mu1>0.2</mu1>
    <mu2>0.2</mu2>
    <self_collide>0</self_collide>
    <material>Gazebo/DarkGrey</material>
    <kp value="1000000.0"/>
    <kd value="1.0"/>
  </gazebo>
  <gazebo reference="lower2">
    <mu1>0.2</mu1>
    <mu2>0.2</mu2>
    <self_collide>0</self_collide>
  </gazebo>
  <gazebo reference="toe2">
    <mu1>0.6</mu1>
    <mu2>0.6</mu2>
    <self_collide>0</self_collide>
    <material>Gazebo/DarkGrey</material>
    <kp value="1000000.0"/>
    <kd value="1.0"/>
  </gazebo>
  <!-- RR leg -->
  <gazebo reference="hip3">
    <mu1>0.2</mu1>
    <mu2>0.2</mu2>
    <material>Gazebo/DarkGrey</material>
  </gazebo>
  <gazebo reference="upper3">
    <mu1>0.2</mu1>
    <mu2>0.2</mu2>
    <self_collide>0</self_collide>
    <material>Gazebo/DarkGrey</material>
    <kp value="1000000.0"/>
    <kd value="1.0"/>
  </gazebo>
  <gazebo reference="lower3">
    <mu1>0.2</mu1>
    <mu2>0.2</mu2>
    <self_collide>0</self_collide>
  </gazebo>
  <gazebo reference="toe3">
    <mu1>0.6</mu1>
    <mu2>0.6</mu2>
    <self_collide>0</self_collide>
    <material>Gazebo/DarkGrey</material>
    <kp value="1000000.0"/>
    <kd value="1.0"/>
  </gazebo>
  <link name="body">
    <visual>
      <origin rpy="0 0 0" xyz="0 0 0"/>
      <geometry>
        <box size="0.001 0.001 0.001"/>
      </geometry>
    </visual>
  </link>
  <joint name="floating_base" type="fixed">
    <origin rpy="0 0 0" xyz="0 0 0"/>
    <parent link="body"/>
    <child link="trunk"/>
  </joint>
  <link name="trunk">
    <visual name="body_visual">
      <origin rpy="0 0 0" xyz="0.0 0.0 0.0"/>
      <geometry>
        <mesh filename="package://ylo2_description/meshes/body/textured/ylo2_textured_body.dae" scale="1 1 1"/>
      </geometry>
      <material name="orange"/>
    </visual>
    <collision name="body_collision">
      <origin rpy="0 0 0" xyz="0 0 0"/>
      <geometry>
        <box size="0.57 0.35 0.149"/>
      </geometry>
    </collision>
    <inertial>
      <origin rpy="0 0 0" xyz="0.02 0.00194 0.0"/>
      <mass value="6.0"/>
      <inertia ixx="0.0158533" ixy="-0.0001332" ixz="-0.0002403" iyy="0.04168" iyz="1.5299e-05" izz="0.04742"/>
    </inertial>
  </link>
  <link name="abad_motors">
    <visual>
      <origin rpy="0 0 0" xyz="0.0 0.0 0.0"/>
      <geometry>
        <mesh filename="package://ylo2_description/meshes/body/textured/ylo2_textured_abad_motors.dae" scale="1 1 1"/>
      </geometry>
      <material name="white"/>
    </visual>
  </link>
  <joint name="abad_motors_joint" type="fixed">
    <parent link="trunk"/>
    <child link="abad_motors"/>
    <origin rpy="0 0 0" xyz="0 0 0"/>
  </joint>
  <link name="battery">
    <visual>
      <origin rpy="0 0 0" xyz="0.0 0.0 0.0"/>
      <geometry>
        <mesh filename="package://ylo2_description/meshes/body/battery.stl" scale="1 1 1"/>
      </geometry>
      <material name="blue"/>
    </visual>
  </link>
  <joint name="battery_joint" type="fixed">
    <parent link="trunk"/>
    <child link="battery"/>
    <origin rpy="0 0 0" xyz="0 0 0"/>
  </joint>
  <link name="covers">
    <visual>
      <origin rpy="0 0 0" xyz="0.0 0.0 0.0"/>
      <geometry>
        <mesh filename="package://ylo2_description/meshes/body/textured/ylo2_textured_cover.dae" scale="1 1 1"/>
      </geometry>
      <material name="orange"/>
    </visual>
  </link>
  <joint name="covers_joint" type="fixed">
    <parent link="trunk"/>
    <child link="covers"/>
    <origin rpy="0 0 0" xyz="0 0 0"/>
  </joint>
  <link name="accessories">
    <visual>
      <origin rpy="0 0 0" xyz="0.0 0.0 0.0"/>
      <geometry>
        <mesh filename="package://ylo2_description/meshes/body/textured/accessories.dae" scale="1 1 1"/>
      </geometry>
      <material name="blue"/>
    </visual>
  </link>
  <joint name="accessories_joint" type="fixed">
    <parent link="trunk"/>
    <child link="accessories"/>
    <origin rpy="0 0 0" xyz="0 0 0"/>
  </joint>
  <link name="D435">
    <visual>
      <origin rpy="0 0 0" xyz="0.0 0.0 0.0"/>
      <geometry>
        <mesh filename="package://ylo2_description/meshes/body/textured/ylo2_d435_textured.dae" scale="1 1 1"/>
      </geometry>
      <material name="black"/>
    </visual>
  </link>
  <joint name="D435_joint" type="fixed">
    <parent link="trunk"/>
    <child link="D435"/>
    <origin rpy="0 0 0" xyz="0 0 0"/>
  </joint>
  <link name="T265">
    <visual>
      <origin rpy="0 0 0" xyz="0.0 0.0 0.0"/>
      <geometry>
        <mesh filename="package://ylo2_description/meshes/body/textured/ylo2_t265_textured.dae" scale="1 1.06 1.04"/>
      </geometry>
      <material name="black"/>
    </visual>
  </link>
  <joint name="T265_joint" type="fixed">
    <parent link="trunk"/>
    <child link="T265"/>
    <origin rpy="0 0 0" xyz="0 0 0"/>
  </joint>
  <joint name="imu_joint" type="fixed">
    <parent link="trunk"/>
    <child link="imu_link"/>
    <origin rpy="0 0 0" xyz="0 0 0"/>
  </joint>
  <link name="imu_link">
    <inertial>
      <mass value="0.001"/>
      <origin rpy="0 0 0" xyz="0 0 0"/>
      <inertia ixx="0.0001" ixy="0" ixz="0" iyy="0.0001" iyz="0" izz="0.0001"/>
    </inertial>
    <visual>
      <origin rpy="0 0 0" xyz="0 0 0"/>
      <geometry>
        <box size="0.001 0.001 0.001"/>
      </geometry>
      <material name="red"/>
    </visual>
    <collision>
      <origin rpy="0 0 0" xyz="0 0 0"/>
      <geometry>
        <box size=".001 .001 .001"/>
      </geometry>
    </collision>
  </link>
  <link name="hip0">
    <visual name="hip0_visual">
      <origin rpy="0 0 0" xyz="-0.055 0 0"/>
      <geometry>
        <mesh filename="package://ylo2_description/meshes/leg/textured/ylo2texturedhip.dae" scale="1 1 1"/>
      </geometry>
      <material name="orange"/>
    </visual>
    <collision name="hip0_collision">
      <origin rpy="1.5707963267948966 0 0" xyz="0 0 0"/>
      <geometry>
        <cylinder length="0.06" radius="0.05"/>
      </geometry>
    </collision>
    <inertial>
      <origin rpy="0 0 0" xyz="-0.011957 0.000306 0.000366"/>
      <mass value="0.599"/>
      <inertia ixx="0.0004159" ixy="4.253e-06" ixz="3.68e-07" iyy="0.0007108" iyz="2.15e-07" izz="0.0004707"/>
    </inertial>
  </link>
  <joint name="8" type="revolute">
    <origin rpy="0 0 0" xyz="0.1695 0.063 0.024"/>
    <parent link="trunk"/>
    <child link="hip0"/>
    <axis xyz="1 0 0"/>
    <dynamics damping="0" friction="0"/>
    <limit effort="33.5" lower="-0.8028514559173915" upper="0.8028514559173915" velocity="21"/>
  </joint>
  <!-- this link is only for collision -->
  <link name="thigh_shoulder0">
    <collision>
      <origin rpy="1.5707963267948966 0 0" xyz="0 0 0"/>
      <geometry>
        <cylinder length="0.08" radius="0.044"/>
      </geometry>
    </collision>
  </link>
  <joint name="hip0_fixed" type="fixed">
    <origin rpy="0 0 0" xyz="0 0.096 0"/>
    <parent link="hip0"/>
    <child link="thigh_shoulder0"/>
  </joint>
  <link name="upper0">
    <visual name="upper0_visual">
      <origin rpy="0 0 0" xyz="0 0 0.0"/>
      <geometry>
        <mesh filename="package://ylo2_description/meshes/leg/textured/ylo2_textured_upper_leg.dae" scale="1 1 1"/>
        --&gt;
                    
      </geometry>
      <material name="orange"/>
    </visual>
    <collision name="upper0_collision">
      <origin rpy="0 1.5707963267948966 0" xyz="0 0 -0.1005"/>
      <geometry>
        <box size="0.201 0.0374 0.043"/>
      </geometry>
    </collision>
    <inertial>
      <origin rpy="0 0 0" xyz="-0.000684 -0.010999 -0.035487"/>
      <mass value="1.08"/>
      <inertia ixx="0.005666803" ixy="3.597e-06" ixz="0.000491446" iyy="0.005847229" iyz="1.0086e-05" izz="0.000369811"/>
    </inertial>
  </link>
  <joint name="0" type="revolute">
    <origin rpy="0 1.5707963267948966 0" xyz="0.0 0.02 0"/>
    <parent link="hip0"/>
    <child link="upper0"/>
    <axis xyz="0 -1 0"/>
    <dynamics damping="0" friction="0"/>
    <limit effort="33.5" lower="-6.283185307179586" upper="6.283185307179586" velocity="21"/>
  </joint>
  <link name="lower0">
    <visual name="lower0_visual">
      <origin rpy="0 0 0" xyz="0 0 0"/>
      <geometry>
        <mesh filename="package://ylo2_description/meshes/leg/textured/lower_leg.dae" scale="1 1 1"/>
        --&gt;
                
      </geometry>
      <material name="orange"/>
    </visual>
    <collision name="lower0_collision">
      <origin rpy="0 1.5707963267948966 0" xyz="0 0 -0.115"/>
      <geometry>
        <mesh filename="package://ylo2_description/meshes/leg/fl_lower_leg_collision.stl" scale="1 -1 1"/>
        --&gt;
                
      </geometry>
    </collision>
    <inertial>
      <origin rpy="0 0 0" xyz="0.000252 0.000194 -0.05192"/>
      <mass value="0.265"/>
      <inertia ixx="0.0004583" ixy="-9.5e-08" ixz="2.6512e-05" iyy="0.0004675" iyz="2.77e-07" izz="2.9145e-05"/>
    </inertial>
  </link>
  <joint name="1" type="revolute">
    <origin rpy="0 -3.141592653589793 0" xyz="-0.001 0.075 -0.201"/>
    <parent link="upper0"/>
    <child link="lower0"/>
    <axis xyz="0 1 0"/>
    <dynamics damping="0" friction="0"/>
    <limit effort="33.5" lower="-6.283185307179586" upper="6.283185307179586" velocity="21"/>
  </joint>
  <link name="toe0">
    <visual name="toe0_visual">
      <origin rpy="0 0 0" xyz="0.009 0.002 0.069"/>
      <geometry>
        <mesh filename="package://ylo2_description/meshes/leg/fl_foot.dae" scale="1.0 1.0 1.0"/>
        --&gt;
                
      </geometry>
      <material name="orange"/>
    </visual>
    <collision name="toe0_collision">
      <origin rpy="0 0 0" xyz="0.009 0.002 0.069"/>
      <geometry>
        <mesh filename="package://ylo2_description/meshes/leg/fl_foot.dae" scale="1.0 1.0 1.0"/>
        --&gt;
                
      </geometry>
      <surface>
        <bounce>
          <restitution_coefficient>0</restitution_coefficient>
          <threshold>1e+06</threshold>
        </bounce>
        <friction>
          <ode>
            <mu>0.2</mu>
            <mu2>0.2</mu2>
          </ode>
          <bullet>
            <rolling_friction>0.3</rolling_friction>
            <friction2>50</friction2>
          </bullet>
        </friction>
        <contact>
          <ode>
            <kp>30000.0</kp>
            <kd>1000.0</kd>
          </ode>
          <bullet>
            <kp>30000.0</kp>
            <kd>1000.0</kd>
            <split_impulse>1</split_impulse>
            <split_impulse_penetration_threshold>-0.01</split_impulse_penetration_threshold>
          </bullet>
        </contact>
      </surface>
    </collision>
    <inertial>
      <mass value="0.078"/>
      <inertia ixx="2.19102e-05" ixy="0.0" ixz="0.0" iyy="2.19102e-05" iyz="0.0" izz="2.19102e-05"/>
    </inertial>
  </link>
  <joint name="jtoe0" type="fixed">
    <origin rpy="0 0 0" xyz="0 0 -0.23"/>
    <parent link="lower0"/>
    <child link="toe0"/>
  </joint>
  <transmission name="transmission_8">
    <type>transmission_interface/SimpleTransmission</type>
    <joint name="8">
      <hardwareInterface>hardware_interface/EffortJointInterface</hardwareInterface>
    </joint>
    <actuator name="motor_8">
      <hardwareInterface>EffortJointInterface</hardwareInterface>
      <mechanicalReduction>1</mechanicalReduction>
    </actuator>
  </transmission>
  <transmission name="transmission_0">
    <type>transmission_interface/SimpleTransmission</type>
    <joint name="0">
      <hardwareInterface>hardware_interface/EffortJointInterface</hardwareInterface>
    </joint>
    <actuator name="motor_0">
      <hardwareInterface>EffortJointInterface</hardwareInterface>
      <mechanicalReduction>1</mechanicalReduction>
    </actuator>
  </transmission>
  <transmission name="transmission_1">
    <type>transmission_interface/SimpleTransmission</type>
    <joint name="1">
      <hardwareInterface>hardware_interface/EffortJointInterface</hardwareInterface>
    </joint>
    <actuator name="motor_1">
      <hardwareInterface>EffortJointInterface</hardwareInterface>
      <mechanicalReduction>1</mechanicalReduction>
    </actuator>
  </transmission>
  <link name="hip1">
    <visual name="hip1_visual">
      <origin rpy="0 3.141592653589793 0" xyz="0.055 0 0"/>
      <geometry>
        <mesh filename="package://ylo2_description/meshes/leg/textured/ylo2texturedhip.dae" scale="1 1 1"/>
      </geometry>
      <material name="orange"/>
    </visual>
    <collision name="hip1_collision">
      <origin rpy="1.5707963267948966 0 0" xyz="0 0 0"/>
      <geometry>
        <cylinder length="0.06" radius="0.05"/>
      </geometry>
    </collision>
    <inertial>
      <origin rpy="0 0 0" xyz="0.011957 0.000306 0.000366"/>
      <mass value="0.599"/>
      <inertia ixx="0.0004159" ixy="-4.253e-06" ixz="-3.68e-07" iyy="0.0007108" iyz="2.15e-07" izz="0.0004707"/>
    </inertial>
  </link>
  <joint name="9" type="revolute">
    <origin rpy="0 0 0" xyz="-0.20950000000000002 0.063 0.024"/>
    <parent link="trunk"/>
    <child link="hip1"/>
    <axis xyz="1 0 0"/>
    <dynamics damping="0" friction="0"/>
    <limit effort="33.5" lower="-0.8028514559173915" upper="0.8028514559173915" velocity="21"/>
  </joint>
  <!-- this link is only for collision -->
  <link name="thigh_shoulder1">
    <collision>
      <origin rpy="1.5707963267948966 0 0" xyz="0 0 0"/>
      <geometry>
        <cylinder length="0.08" radius="0.044"/>
      </geometry>
    </collision>
  </link>
  <joint name="hip1_fixed" type="fixed">
    <origin rpy="0 0 0" xyz="0 0.096 0"/>
    <parent link="hip1"/>
    <child link="thigh_shoulder1"/>
  </joint>
  <link name="upper1">
    <visual name="upper1_visual">
      <origin rpy="0 0 0" xyz="0 0 0.0"/>
      <geometry>
        <mesh filename="package://ylo2_description/meshes/leg/textured/ylo2_textured_upper_leg.dae" scale="1 1 1"/>
        --&gt;
                    
      </geometry>
      <material name="orange"/>
    </visual>
    <collision name="upper1_collision">
      <origin rpy="0 1.5707963267948966 0" xyz="0 0 -0.1005"/>
      <geometry>
        <box size="0.201 0.0374 0.043"/>
      </geometry>
    </collision>
    <inertial>
      <origin rpy="0 0 0" xyz="-0.000684 -0.010999 -0.035487"/>
      <mass value="1.08"/>
      <inertia ixx="0.005666803" ixy="3.597e-06" ixz="0.000491446" iyy="0.005847229" iyz="1.0086e-05" izz="0.000369811"/>
    </inertial>
  </link>
  <joint name="2" type="revolute">
    <origin rpy="0 1.5707963267948966 0" xyz="0.0 0.02 0"/>
    <parent link="hip1"/>
    <child link="upper1"/>
    <axis xyz="0 -1 0"/>
    <dynamics damping="0" friction="0"/>
    <limit effort="33.5" lower="-6.283185307179586" upper="6.283185307179586" velocity="21"/>
  </joint>
  <link name="lower1">
    <visual name="lower1_visual">
      <origin rpy="0 0 0" xyz="0 0 0"/>
      <geometry>
        <mesh filename="package://ylo2_description/meshes/leg/textured/lower_leg.dae" scale="1 1 1"/>
        --&gt;
                
      </geometry>
      <material name="orange"/>
    </visual>
    <collision name="lower1_collision">
      <origin rpy="0 1.5707963267948966 0" xyz="0 0 -0.115"/>
      <geometry>
        <mesh filename="package://ylo2_description/meshes/leg/fl_lower_leg_collision.stl" scale="1 -1 1"/>
        --&gt;
                
      </geometry>
    </collision>
    <inertial>
      <origin rpy="0 0 0" xyz="0.000252 0.000194 -0.05192"/>
      <mass value="0.265"/>
      <inertia ixx="0.0004583" ixy="-9.5e-08" ixz="2.6512e-05" iyy="0.0004675" iyz="2.77e-07" izz="2.9145e-05"/>
    </inertial>
  </link>
  <joint name="3" type="revolute">
    <origin rpy="0 -3.141592653589793 0" xyz="-0.001 0.075 -0.201"/>
    <parent link="upper1"/>
    <child link="lower1"/>
    <axis xyz="0 1 0"/>
    <dynamics damping="0" friction="0"/>
    <limit effort="33.5" lower="-6.283185307179586" upper="6.283185307179586" velocity="21"/>
  </joint>
  <link name="toe1">
    <visual name="toe1_visual">
      <origin rpy="0 0 0" xyz="0.009 0.002 0.069"/>
      <geometry>
        <mesh filename="package://ylo2_description/meshes/leg/fl_foot.dae" scale="1.0 1.0 1.0"/>
        --&gt;
                
      </geometry>
      <material name="orange"/>
    </visual>
    <collision name="toe1_collision">
      <origin rpy="0 0 0" xyz="0.009 0.002 0.069"/>
      <geometry>
        <mesh filename="package://ylo2_description/meshes/leg/fl_foot.dae" scale="1.0 1.0 1.0"/>
        --&gt;
                
      </geometry>
      <surface>
        <bounce>
          <restitution_coefficient>0</restitution_coefficient>
          <threshold>1e+06</threshold>
        </bounce>
        <friction>
          <ode>
            <mu>0.2</mu>
            <mu2>0.2</mu2>
          </ode>
          <bullet>
            <rolling_friction>0.3</rolling_friction>
            <friction2>50</friction2>
          </bullet>
        </friction>
        <contact>
          <ode>
            <kp>30000.0</kp>
            <kd>1000.0</kd>
          </ode>
          <bullet>
            <kp>30000.0</kp>
            <kd>1000.0</kd>
            <split_impulse>1</split_impulse>
            <split_impulse_penetration_threshold>-0.01</split_impulse_penetration_threshold>
          </bullet>
        </contact>
      </surface>
    </collision>
    <inertial>
      <mass value="0.078"/>
      <inertia ixx="2.19102e-05" ixy="0.0" ixz="0.0" iyy="2.19102e-05" iyz="0.0" izz="2.19102e-05"/>
    </inertial>
  </link>
  <joint name="jtoe1" type="fixed">
    <origin rpy="0 0 0" xyz="0 0 -0.23"/>
    <parent link="lower1"/>
    <child link="toe1"/>
  </joint>
  <transmission name="transmission_9">
    <type>transmission_interface/SimpleTransmission</type>
    <joint name="9">
      <hardwareInterface>hardware_interface/EffortJointInterface</hardwareInterface>
    </joint>
    <actuator name="motor_9">
      <hardwareInterface>EffortJointInterface</hardwareInterface>
      <mechanicalReduction>1</mechanicalReduction>
    </actuator>
  </transmission>
  <transmission name="transmission_2">
    <type>transmission_interface/SimpleTransmission</type>
    <joint name="2">
      <hardwareInterface>hardware_interface/EffortJointInterface</hardwareInterface>
    </joint>
    <actuator name="motor_2">
      <hardwareInterface>EffortJointInterface</hardwareInterface>
      <mechanicalReduction>1</mechanicalReduction>
    </actuator>
  </transmission>
  <transmission name="transmission_3">
    <type>transmission_interface/SimpleTransmission</type>
    <joint name="3">
      <hardwareInterface>hardware_interface/EffortJointInterface</hardwareInterface>
    </joint>
    <actuator name="motor_3">
      <hardwareInterface>EffortJointInterface</hardwareInterface>
      <mechanicalReduction>1</mechanicalReduction>
    </actuator>
  </transmission>
  <link name="hip2">
    <visual name="hip2_visual">
      <origin rpy="3.141592653589793 0 0" xyz="-0.055 0 0"/>
      <geometry>
        <mesh filename="package://ylo2_description/meshes/leg/textured/ylo2texturedhip.dae" scale="1 1 1"/>
      </geometry>
      <material name="orange"/>
    </visual>
    <collision name="hip2_collision">
      <origin rpy="1.5707963267948966 0 0" xyz="0 0 0"/>
      <geometry>
        <cylinder length="0.06" radius="0.05"/>
      </geometry>
    </collision>
    <inertial>
      <origin rpy="0 0 0" xyz="-0.011957 -0.000306 0.000366"/>
      <mass value="0.599"/>
      <inertia ixx="0.0004159" ixy="-4.253e-06" ixz="3.68e-07" iyy="0.0007108" iyz="-2.15e-07" izz="0.0004707"/>
    </inertial>
  </link>
  <joint name="10" type="revolute">
    <origin rpy="0 0 0" xyz="0.1695 -0.052000000000000005 0.024"/>
    <parent link="trunk"/>
    <child link="hip2"/>
    <axis xyz="1 0 0"/>
    <dynamics damping="0" friction="0"/>
    <limit effort="33.5" lower="-0.8028514559173915" upper="0.8028514559173915" velocity="21"/>
  </joint>
  <!-- this link is only for collision -->
  <link name="thigh_shoulder2">
    <collision>
      <origin rpy="1.5707963267948966 0 0" xyz="0 0 0"/>
      <geometry>
        <cylinder length="0.08" radius="0.044"/>
      </geometry>
    </collision>
  </link>
  <joint name="hip2_fixed" type="fixed">
    <origin rpy="0 0 0" xyz="0 -0.096 0"/>
    <parent link="hip2"/>
    <child link="thigh_shoulder2"/>
  </joint>
  <link name="upper2">
    <visual name="upper2_visual">
      <origin rpy="0 0 0" xyz="0 0 0.0"/>
      <geometry>
        <mesh filename="package://ylo2_description/meshes/leg/textured/ylo2_textured_upper_leg.dae" scale="1 -1 1"/>
        --&gt;
                    
      </geometry>
      <material name="orange"/>
    </visual>
    <collision name="upper2_collision">
      <origin rpy="0 1.5707963267948966 0" xyz="0 0 -0.1005"/>
      <geometry>
        <box size="0.201 0.0374 0.043"/>
      </geometry>
    </collision>
    <inertial>
      <origin rpy="0 0 0" xyz="-0.000684 0.010999 -0.035487"/>
      <mass value="1.08"/>
      <inertia ixx="0.005666803" ixy="-3.597e-06" ixz="0.000491446" iyy="0.005847229" iyz="-1.0086e-05" izz="0.000369811"/>
    </inertial>
  </link>
  <joint name="4" type="revolute">
    <origin rpy="0 1.5707963267948966 0" xyz="0.0 -0.02 0"/>
    <parent link="hip2"/>
    <child link="upper2"/>
    <axis xyz="0 -1 0"/>
    <dynamics damping="0" friction="0"/>
    <limit effort="33.5" lower="-6.283185307179586" upper="6.283185307179586" velocity="21"/>
  </joint>
  <link name="lower2">
    <visual name="lower2_visual">
      <origin rpy="0 0 0" xyz="0 0 0"/>
      <geometry>
        <mesh filename="package://ylo2_description/meshes/leg/textured/lower_leg.dae" scale="1 1 1"/>
        --&gt;
                
      </geometry>
      <material name="orange"/>
    </visual>
    <collision name="lower2_collision">
      <origin rpy="0 1.5707963267948966 0" xyz="0 0 -0.115"/>
      <geometry>
        <mesh filename="package://ylo2_description/meshes/leg/fl_lower_leg_collision.stl" scale="1 -1 1"/>
        --&gt;
                
      </geometry>
    </collision>
    <inertial>
      <origin rpy="0 0 0" xyz="0.000252 0.000194 -0.05192"/>
      <mass value="0.265"/>
      <inertia ixx="0.0004583" ixy="-9.5e-08" ixz="2.6512e-05" iyy="0.0004675" iyz="2.77e-07" izz="2.9145e-05"/>
    </inertial>
  </link>
  <joint name="5" type="revolute">
    <origin rpy="0 -3.141592653589793 0" xyz="-0.001 -0.075 -0.201"/>
    <parent link="upper2"/>
    <child link="lower2"/>
    <axis xyz="0 1 0"/>
    <dynamics damping="0" friction="0"/>
    <limit effort="33.5" lower="-6.283185307179586" upper="6.283185307179586" velocity="21"/>
  </joint>
  <link name="toe2">
    <visual name="toe2_visual">
      <origin rpy="0 0 0" xyz="0.009 0.0 0.069"/>
      <geometry>
        <mesh filename="package://ylo2_description/meshes/leg/fl_foot.dae" scale="1.0 1.0 1.0"/>
        --&gt;
                
      </geometry>
      <material name="orange"/>
    </visual>
    <collision name="toe2_collision">
      <origin rpy="0 0 0" xyz="0.009 0.0 0.069"/>
      <geometry>
        <mesh filename="package://ylo2_description/meshes/leg/fl_foot.dae" scale="1.0 1.0 1.0"/>
        --&gt;
                
      </geometry>
      <surface>
        <bounce>
          <restitution_coefficient>0</restitution_coefficient>
          <threshold>1e+06</threshold>
        </bounce>
        <friction>
          <ode>
            <mu>0.2</mu>
            <mu2>0.2</mu2>
          </ode>
          <bullet>
            <rolling_friction>0.3</rolling_friction>
            <friction2>50</friction2>
          </bullet>
        </friction>
        <contact>
          <ode>
            <kp>30000.0</kp>
            <kd>1000.0</kd>
          </ode>
          <bullet>
            <kp>30000.0</kp>
            <kd>1000.0</kd>
            <split_impulse>1</split_impulse>
            <split_impulse_penetration_threshold>-0.01</split_impulse_penetration_threshold>
          </bullet>
        </contact>
      </surface>
    </collision>
    <inertial>
      <mass value="0.078"/>
      <inertia ixx="2.19102e-05" ixy="0.0" ixz="0.0" iyy="2.19102e-05" iyz="0.0" izz="2.19102e-05"/>
    </inertial>
  </link>
  <joint name="jtoe2" type="fixed">
    <origin rpy="0 0 0" xyz="0 0 -0.23"/>
    <parent link="lower2"/>
    <child link="toe2"/>
  </joint>
  <transmission name="transmission_10">
    <type>transmission_interface/SimpleTransmission</type>
    <joint name="10">
      <hardwareInterface>hardware_interface/EffortJointInterface</hardwareInterface>
    </joint>
    <actuator name="motor_10">
      <hardwareInterface>EffortJointInterface</hardwareInterface>
      <mechanicalReduction>1</mechanicalReduction>
    </actuator>
  </transmission>
  <transmission name="transmission_4">
    <type>transmission_interface/SimpleTransmission</type>
    <joint name="4">
      <hardwareInterface>hardware_interface/EffortJointInterface</hardwareInterface>
    </joint>
    <actuator name="motor_4">
      <hardwareInterface>EffortJointInterface</hardwareInterface>
      <mechanicalReduction>1</mechanicalReduction>
    </actuator>
  </transmission>
  <transmission name="transmission_5">
    <type>transmission_interface/SimpleTransmission</type>
    <joint name="5">
      <hardwareInterface>hardware_interface/EffortJointInterface</hardwareInterface>
    </joint>
    <actuator name="motor_5">
      <hardwareInterface>EffortJointInterface</hardwareInterface>
      <mechanicalReduction>1</mechanicalReduction>
    </actuator>
  </transmission>
  <link name="hip3">
    <visual name="hip3_visual">
      <origin rpy="3.141592653589793 3.141592653589793 0" xyz="0.055 0 0"/>
      <geometry>
        <mesh filename="package://ylo2_description/meshes/leg/textured/ylo2texturedhip.dae" scale="1 1 1"/>
      </geometry>
      <material name="orange"/>
    </visual>
    <collision name="hip3_collision">
      <origin rpy="1.5707963267948966 0 0" xyz="0 0 0"/>
      <geometry>
        <cylinder length="0.06" radius="0.05"/>
      </geometry>
    </collision>
    <inertial>
      <origin rpy="0 0 0" xyz="0.011957 -0.000306 0.000366"/>
      <mass value="0.599"/>
      <inertia ixx="0.0004159" ixy="4.253e-06" ixz="-3.68e-07" iyy="0.0007108" iyz="-2.15e-07" izz="0.0004707"/>
    </inertial>
  </link>
  <joint name="11" type="revolute">
    <origin rpy="0 0 0" xyz="-0.20950000000000002 -0.052000000000000005 0.024"/>
    <parent link="trunk"/>
    <child link="hip3"/>
    <axis xyz="1 0 0"/>
    <dynamics damping="0" friction="0"/>
    <limit effort="33.5" lower="-0.8028514559173915" upper="0.8028514559173915" velocity="21"/>
  </joint>
  <!-- this link is only for collision -->
  <link name="thigh_shoulder3">
    <collision>
      <origin rpy="1.5707963267948966 0 0" xyz="0 0 0"/>
      <geometry>
        <cylinder length="0.08" radius="0.044"/>
      </geometry>
    </collision>
  </link>
  <joint name="hip3_fixed" type="fixed">
    <origin rpy="0 0 0" xyz="0 -0.096 0"/>
    <parent link="hip3"/>
    <child link="thigh_shoulder3"/>
  </joint>
  <link name="upper3">
    <visual name="upper3_visual">
      <origin rpy="0 0 0" xyz="0 0 0.0"/>
      <geometry>
        <mesh filename="package://ylo2_description/meshes/leg/textured/ylo2_textured_upper_leg.dae" scale="1 -1 1"/>
        --&gt;
                    
      </geometry>
      <material name="orange"/>
    </visual>
    <collision name="upper3_collision">
      <origin rpy="0 1.5707963267948966 0" xyz="0 0 -0.1005"/>
      <geometry>
        <box size="0.201 0.0374 0.043"/>
      </geometry>
    </collision>
    <inertial>
      <origin rpy="0 0 0" xyz="-0.000684 0.010999 -0.035487"/>
      <mass value="1.08"/>
      <inertia ixx="0.005666803" ixy="-3.597e-06" ixz="0.000491446" iyy="0.005847229" iyz="-1.0086e-05" izz="0.000369811"/>
    </inertial>
  </link>
  <joint name="6" type="revolute">
    <origin rpy="0 1.5707963267948966 0" xyz="0.0 -0.02 0"/>
    <parent link="hip3"/>
    <child link="upper3"/>
    <axis xyz="0 -1 0"/>
    <dynamics damping="0" friction="0"/>
    <limit effort="33.5" lower="-6.283185307179586" upper="6.283185307179586" velocity="21"/>
  </joint>
  <link name="lower3">
    <visual name="lower3_visual">
      <origin rpy="0 0 0" xyz="0 0 0"/>
      <geometry>
        <mesh filename="package://ylo2_description/meshes/leg/textured/lower_leg.dae" scale="1 1 1"/>
        --&gt;
                
      </geometry>
      <material name="orange"/>
    </visual>
    <collision name="lower3_collision">
      <origin rpy="0 1.5707963267948966 0" xyz="0 0 -0.115"/>
      <geometry>
        <mesh filename="package://ylo2_description/meshes/leg/fl_lower_leg_collision.stl" scale="1 -1 1"/>
        --&gt;
                
      </geometry>
    </collision>
    <inertial>
      <origin rpy="0 0 0" xyz="0.000252 0.000194 -0.05192"/>
      <mass value="0.265"/>
      <inertia ixx="0.0004583" ixy="-9.5e-08" ixz="2.6512e-05" iyy="0.0004675" iyz="2.77e-07" izz="2.9145e-05"/>
    </inertial>
  </link>
  <joint name="7" type="revolute">
    <origin rpy="0 -3.141592653589793 0" xyz="-0.001 -0.075 -0.201"/>
    <parent link="upper3"/>
    <child link="lower3"/>
    <axis xyz="0 1 0"/>
    <dynamics damping="0" friction="0"/>
    <limit effort="33.5" lower="-6.283185307179586" upper="6.283185307179586" velocity="21"/>
  </joint>
  <link name="toe3">
    <visual name="toe3_visual">
      <origin rpy="0 0 0" xyz="0.009 0.0 0.069"/>
      <geometry>
        <mesh filename="package://ylo2_description/meshes/leg/fl_foot.dae" scale="1.0 1.0 1.0"/>
        --&gt;
                
      </geometry>
      <material name="orange"/>
    </visual>
    <collision name="toe3_collision">
      <origin rpy="0 0 0" xyz="0.009 0.0 0.069"/>
      <geometry>
        <mesh filename="package://ylo2_description/meshes/leg/fl_foot.dae" scale="1.0 1.0 1.0"/>
        --&gt;
                
      </geometry>
      <surface>
        <bounce>
          <restitution_coefficient>0</restitution_coefficient>
          <threshold>1e+06</threshold>
        </bounce>
        <friction>
          <ode>
            <mu>0.2</mu>
            <mu2>0.2</mu2>
          </ode>
          <bullet>
            <rolling_friction>0.3</rolling_friction>
            <friction2>50</friction2>
          </bullet>
        </friction>
        <contact>
          <ode>
            <kp>30000.0</kp>
            <kd>1000.0</kd>
          </ode>
          <bullet>
            <kp>30000.0</kp>
            <kd>1000.0</kd>
            <split_impulse>1</split_impulse>
            <split_impulse_penetration_threshold>-0.01</split_impulse_penetration_threshold>
          </bullet>
        </contact>
      </surface>
    </collision>
    <inertial>
      <mass value="0.078"/>
      <inertia ixx="2.19102e-05" ixy="0.0" ixz="0.0" iyy="2.19102e-05" iyz="0.0" izz="2.19102e-05"/>
    </inertial>
  </link>
  <joint name="jtoe3" type="fixed">
    <origin rpy="0 0 0" xyz="0 0 -0.23"/>
    <parent link="lower3"/>
    <child link="toe3"/>
  </joint>
  <transmission name="transmission_11">
    <type>transmission_interface/SimpleTransmission</type>
    <joint name="11">
      <hardwareInterface>hardware_interface/EffortJointInterface</hardwareInterface>
    </joint>
    <actuator name="motor_11">
      <hardwareInterface>EffortJointInterface</hardwareInterface>
      <mechanicalReduction>1</mechanicalReduction>
    </actuator>
  </transmission>
  <transmission name="transmission_6">
    <type>transmission_interface/SimpleTransmission</type>
    <joint name="6">
      <hardwareInterface>hardware_interface/EffortJointInterface</hardwareInterface>
    </joint>
    <actuator name="motor_6">
      <hardwareInterface>EffortJointInterface</hardwareInterface>
      <mechanicalReduction>1</mechanicalReduction>
    </actuator>
  </transmission>
  <transmission name="transmission_7">
    <type>transmission_interface/SimpleTransmission</type>
    <joint name="7">
      <hardwareInterface>hardware_interface/EffortJointInterface</hardwareInterface>
    </joint>
    <actuator name="motor_7">
      <hardwareInterface>EffortJointInterface</hardwareInterface>
      <mechanicalReduction>1</mechanicalReduction>
    </actuator>
  </transmission>
</robot>
