<?xml version="1.0" encoding="utf-8"?>
<!-- =================================================================================== -->
<!-- |    This document was autogenerated by xacro from spirit40_gaz.urdf.xacro        | -->
<!-- |    EDITING THIS FILE BY HAND IS NOT RECOMMENDED                                 | -->
<!-- =================================================================================== -->
<!--
 * Copyright (C) Ghost Robotics - All Rights Reserved
 * Unauthorized copying of this file, via any medium is strictly prohibited
 * Proprietary and confidential
 * Written by Avik De <avik@ghostrobotics.io> and Tom Jacobs <tom.jacobs@ghostrobotics.io>
-->
<robot name="spirit">
  <!-- Define materials -->
  <material name="gray">
    <color rgba="0.2 0.2 0.2 1.0"/>
  </material>
  <material name="darkgray">
    <color rgba="0.1 0.1 0.1 1.0"/>
  </material>
  <material name="silver">
    <color rgba="0.3 0.3 0.3 1.0"/>
  </material>
  <material name="red">
    <color rgba="0.8 0.0 0.2 1.0"/>
  </material>
  <!-- Body -->
  <link name="dummy">
   </link>
  <link name="body">
    <!--		<visual>-->
    <!--			<origin rpy="0 0 0" xyz="0 0 0"/>-->
    <!--			<geometry>-->
    <!--				<box size="${bodyLength} ${bodyWidth} ${bodyHeight}"/>-->
    <!--			</geometry>-->
    <!--			<material name="darkgray"/>-->
    <!--		</visual>-->
    <visual>
      <origin rpy="0 0 0" xyz="0.03 0 0"/>
      <geometry>
        <mesh filename="package://spirit_description/meshes/Spirit40_Body_Mesh_transformed.stl" scale="1 1 1"/>
      </geometry>
      <material name="gray"/>
    </visual>
    <inertial>
      <mass value="5.75"/>
      <!-- Uniform box -->
      <!-- <inertia ixx="1/12*${bodyMass}*(${bodyWidth}*${bodyWidth} + ${bodyHeight}*${bodyHeight})"  ixy="0"  ixz="0" iyy="1/12*${bodyMass}*(${bodyLength}*${bodyLength} + ${bodyHeight}*${bodyHeight})" iyz="0" izz="1/12*${bodyMass}*(${bodyLength}*${bodyLength} + ${bodyWidth}*${bodyWidth})"/> -->
      <inertia ixx="0.05" ixy="0" ixz="0" iyy="0.1" iyz="0" izz="0.1"/>
    </inertial>
    <!-- Just copy geometry for collision -->
    <collision>
      <origin rpy="0 0 0" xyz="0 0 0"/>
      <geometry>
        <box size="0.335 0.24 0.104"/>
      </geometry>
    </collision>
  </link>
  <joint name="dummy_joint" type="fixed">
     <parent link="dummy"/>
     <child link="body"/>
   </joint>
  <gazebo reference="body">
    <material>Gazebo/Gray</material>
  </gazebo>
  <!-- this way planner can run unchanged-->
  <link name="t265_pose_frame"/>
  <joint name="body_to_t265" type="fixed">
    <parent link="body"/>
    <child link="t265_pose_frame"/>
    <origin rpy="0 0 0" xyz="0.0 0.0 0.0"/>
    <axis xyz="1 0 0"/>
  </joint>
  <gazebo reference="body">
    <gravity>true</gravity>
    <sensor name="imu_sensor" type="imu">
      <always_on>true</always_on>
      <visualize>true</visualize>
      <topic>__default_topic_</topic>
      <plugin filename="libgazebo_ros_imu_sensor.so" name="imu_plugin">
        <topicName>imu</topicName>
        <bodyName>body</bodyName>
        <updateRateHZ>500.0</updateRateHZ>
        <gaussianNoise>0.0</gaussianNoise>
        <xyzOffset>0 0 0</xyzOffset>
        <rpyOffset>0 0 0</rpyOffset>
        <frameName>body</frameName>
        <initialOrientationAsReference>true</initialOrientationAsReference>
      </plugin>
      <pose>0 0 0 0 0 0</pose>
    </sensor>
  </gazebo>
  <!-- Hip motor -->
  <link name="hip0">
    <!--			<visual>-->
    <!--				<origin rpy="${pi/2} 0 0" xyz="${front * 0} ${left * (dPodAxisToEdge)} 0"/>-->
    <!--				<geometry>-->
    <!--					<cylinder length="${podLength}" radius="${podRadius}"/>-->
    <!--				</geometry>-->
    <!--				<material name="${color}"/>-->
    <!--			</visual>-->
    <visual>
      <origin rpy="0 0 0" xyz="0 0.0 0"/>
      <geometry>
        <mesh filename="package://spirit_description/meshes/Spirit40_Hip_Module_transformed.stl" scale="1 1 1"/>
      </geometry>
      <material name="gray"/>
    </visual>
    <collision>
      <origin rpy="1.5707963268 0 0" xyz="0 0.028 0"/>
      <geometry>
        <cylinder length="0.08" radius="0.055"/>
      </geometry>
    </collision>
    <inertial>
      <mass value="0.575"/>
      <!-- <inertia ixx="1/12*${podMass}*${podLength}*${podLength} + 1/4*${podMass}*${podRadius}*${podRadius}"  ixy="0"  ixz="0" iyy="1/12*${podMass}*${podLength}*${podLength} + 1/4*${podMass}*${podRadius}*${podRadius}" iyz="0" izz="1/2*${podMass}*${podRadius}*$
				{podRadius}" /> -->
      <inertia ixx="0.00066963541" ixy="0" ixz="0" iyy="0.00066963541" iyz="0" izz="0.0008696875"/>
    </inertial>
  </link>
  <gazebo reference="hip0">
    <material>Gazebo/Gray</material>
  </gazebo>
  <!-- Abduction joint. Joint names are: 8 9 10 11 -->
  <joint name="8" type="revolute">
    <parent link="body"/>
    <child link="hip0"/>
    <axis xyz="1 0 0"/>
    <origin xyz="0.2263 0.07 0"/>
    <limit effort="40" lower="-0.707" upper="0.707" velocity="30"/>
    <dynamics damping="0.0" friction="0.0"/>
  </joint>
  <!-- Transmission elements required for Gazebo -->
  <transmission name="transmission_8">
    <type>transmission_interface/SimpleTransmission</type>
    <joint name="8">
      <hardwareInterface>hardware_interface/EffortJointInterface</hardwareInterface>
    </joint>
    <actuator name="motor_8">
      <hardwareInterface>EffortJointInterface</hardwareInterface>
      <mechanicalReduction>1</mechanicalReduction>
    </actuator>
  </transmission>
  <!-- Upper leg -->
  <link name="upper0">
    <!--			<visual>-->
    <!--				<origin rpy="0 0 0" xyz="-${upperLegLength/2} ${-left*upperLegWidth} 0"/>-->
    <!--				<geometry>-->
    <!--					<box size="${upperLegLength} ${upperLegWidth} ${upperLegHeight}"/>-->
    <!--				</geometry>-->
    <!--				<material name="silver"/>-->
    <!--			</visual>-->
    <visual>
      <origin rpy="0 0  0" xyz="0 -0.02 0"/>
      <geometry>
        <mesh filename="package://spirit_description/meshes/Spirit40_Upper_leg_transformed.stl" scale="1 1 1"/>
      </geometry>
      <material name="gray"/>
    </visual>
    <collision>
      <origin rpy="0 0 0" xyz="-0.103 -0.022 0"/>
      <geometry>
        <box size="0.206 0.022 0.055"/>
      </geometry>
    </collision>
    <inertial>
      <mass value="0.775"/>
      <inertia ixx="5e-05" ixy="0" ixz="0" iyy="0.001" iyz="0" izz="0.001"/>
    </inertial>
  </link>
  <gazebo reference="upper0">
    <material>Gazebo/Gray</material>
  </gazebo>
  <!-- Hip joint. (Motor to upper leg). Joint names are: 0 2 4 6 -->
  <joint name="0" type="revolute">
    <parent link="hip0"/>
    <child link="upper0"/>
    <axis xyz="0 -1 0"/>
    <origin xyz="0 0.10098 0"/>
    <!--  rpy="0 -0.3 0" -->
    <limit effort="40" lower="-6.28318530718" upper="6.28318530718" velocity="30"/>
    <dynamics damping="0.0" friction="0.0"/>
  </joint>
  <!-- Transmission elements required for Gazebo -->
  <transmission name="transmission_0">
    <type>transmission_interface/SimpleTransmission</type>
    <joint name="0">
      <hardwareInterface>hardware_interface/EffortJointInterface</hardwareInterface>
    </joint>
    <actuator name="motor_0">
      <hardwareInterface>EffortJointInterface</hardwareInterface>
      <mechanicalReduction>1</mechanicalReduction>
    </actuator>
  </transmission>
  <!-- Lower leg -->
  <link name="lower0">
    <!--			<visual>-->
    <!--				<origin rpy="0 ${pi/2} 0" xyz="${lowerLegLength/2} 0 0"/>-->
    <!--				<geometry>-->
    <!--					<cylinder length="${lowerLegLength}" radius="${lowerLegRadius}"/>-->
    <!--				</geometry>-->
    <!--				<material name="darkgray"/>-->
    <!--			</visual>-->
    <visual>
      <origin rpy="0 0  0" xyz="0 0 0"/>
      <geometry>
        <mesh filename="package://spirit_description/meshes/Spirit40_Lower_Leg_transformed.stl" scale="1 1 1"/>
      </geometry>
      <material name="gray"/>
    </visual>
    <collision>
      <origin rpy="0 1.5707963268 0" xyz="0.103 0 0"/>
      <geometry>
        <cylinder length="0.206" radius="0.013"/>
      </geometry>
    </collision>
    <inertial>
      <mass value="0.075"/>
      <inertia ixx="5e-06" ixy="0" ixz="0" iyy="0.0001" iyz="0" izz="0.0001"/>
    </inertial>
  </link>
  <gazebo reference="lower0">
    <material>Gazebo/Black</material>
  </gazebo>
  <!-- Knee joint. Joint names are: 1 3 5 7 -->
  <joint name="1" type="revolute">
    <parent link="upper0"/>
    <child link="lower0"/>
    <axis xyz="0 1 0"/>
    <origin xyz="-0.206 0 0"/>
    <!--rpy="0 0.5 0"-->
    <limit effort="40" lower="0" upper="3.14159265359" velocity="30"/>
    <dynamics damping="0.0" friction="0.0"/>
  </joint>
  <!-- Transmission elements required for Gazebo -->
  <transmission name="transmission_1">
    <type>transmission_interface/SimpleTransmission</type>
    <joint name="1">
      <hardwareInterface>hardware_interface/EffortJointInterface</hardwareInterface>
    </joint>
    <actuator name="motor_1">
      <hardwareInterface>EffortJointInterface</hardwareInterface>
      <mechanicalReduction>1</mechanicalReduction>
    </actuator>
  </transmission>
  <!-- Toe -->
  <link name="toe0">
    <contact>
      <friction_anchor/>
      <stiffness value="30000.0"/>
      <damping value="1000.0"/>
      <spinning_friction value="0.3"/>
      <lateral_friction value="50.0"/>
    </contact>
    <visual>
      <origin rpy="0 0 0" xyz="0 0 0"/>
      <geometry>
        <!--					<sphere radius="${toeRadius}"/>-->
        <sphere radius="0.001"/>
      </geometry>
      <material name="darkgray"/>
    </visual>
    <collision>
      <origin rpy="0 0 0" xyz="0 0 0"/>
      <geometry>
        <sphere radius="0.02"/>
      </geometry>
      <surface>
        <friction>
          <ode>
            <mu>100000</mu>
            <mu2>100000</mu2>
          </ode>
        </friction>
        <contact>
          <ode>
            <kp>30000.0</kp>
            <kd>1000.0</kd>
          </ode>
        </contact>
      </surface>
    </collision>
    <inertial>
      <mass value="0.015"/>
      <inertia ixx="0.000025" ixy="0" ixz="0" iyy="0.000025" iyz="0" izz="0.000025"/>
      <!-- <inertia ixx="2/5*${toeMass}*${toeRadius}*${toeRadius}"  ixy="0"  ixz="0" iyy="2/5*${toeMass}*${toeRadius}*${toeRadius}" iyz="0" izz="2/5*${toeMass}*${toeRadius}*${toeRadius}" /> -->
    </inertial>
  </link>
  <gazebo reference="toe0">
    <material>Gazebo/DarkGray</material>
    <collision>
      <surface>
        <bounce>
          <restitution_coefficient>0</restitution_coefficient>
          <threshold>1e+06</threshold>
        </bounce>
        <friction>
          <torsional>
            <coefficient>0.3</coefficient>
          </torsional>
          <ode>
            <mu>100.0</mu>
            <mu2>50.0</mu2>
          </ode>
          <bullet>
            <rolling_friction>0.3</rolling_friction>
            <friction2>50.0</friction2>
          </bullet>
        </friction>
        <contact>
          <bullet>
            <kp>30000.0</kp>
            <kd>1000.0</kd>
          </bullet>
          <ode>
            <kp>30000.0</kp>
            <kd>1000.0</kd>
          </ode>
        </contact>
      </surface>
    </collision>
  </gazebo>
  <joint name="jtoe0" type="fixed">
    <parent link="lower0"/>
    <child link="toe0"/>
    <origin xyz="0.206 0 -0.0"/>
    <dynamics damping="0.0" friction="0.0"/>
  </joint>
  <!-- Hip motor -->
  <link name="hip1">
    <!--			<visual>-->
    <!--				<origin rpy="${pi/2} 0 0" xyz="${front * 0} ${left * (dPodAxisToEdge)} 0"/>-->
    <!--				<geometry>-->
    <!--					<cylinder length="${podLength}" radius="${podRadius}"/>-->
    <!--				</geometry>-->
    <!--				<material name="${color}"/>-->
    <!--			</visual>-->
    <visual>
      <origin rpy="0 3.14159265359 0" xyz="0.0 0.0 0"/>
      <geometry>
        <mesh filename="package://spirit_description/meshes/Spirit40_Hip_Module_transformed.stl" scale="1 1 1"/>
      </geometry>
      <material name="gray"/>
    </visual>
    <collision>
      <origin rpy="1.5707963268 0 0" xyz="0 0.028 0"/>
      <geometry>
        <cylinder length="0.08" radius="0.055"/>
      </geometry>
    </collision>
    <inertial>
      <mass value="0.575"/>
      <!-- <inertia ixx="1/12*${podMass}*${podLength}*${podLength} + 1/4*${podMass}*${podRadius}*${podRadius}"  ixy="0"  ixz="0" iyy="1/12*${podMass}*${podLength}*${podLength} + 1/4*${podMass}*${podRadius}*${podRadius}" iyz="0" izz="1/2*${podMass}*${podRadius}*$
				{podRadius}" /> -->
      <inertia ixx="0.00066963541" ixy="0" ixz="0" iyy="0.00066963541" iyz="0" izz="0.0008696875"/>
    </inertial>
  </link>
  <gazebo reference="hip1">
    <material>Gazebo/Gray</material>
  </gazebo>
  <!-- Abduction joint. Joint names are: 8 9 10 11 -->
  <joint name="9" type="revolute">
    <parent link="body"/>
    <child link="hip1"/>
    <axis xyz="1 0 0"/>
    <origin xyz="-0.2263 0.07 0"/>
    <limit effort="40" lower="-0.707" upper="0.707" velocity="30"/>
    <dynamics damping="0.0" friction="0.0"/>
  </joint>
  <!-- Transmission elements required for Gazebo -->
  <transmission name="transmission_9">
    <type>transmission_interface/SimpleTransmission</type>
    <joint name="9">
      <hardwareInterface>hardware_interface/EffortJointInterface</hardwareInterface>
    </joint>
    <actuator name="motor_9">
      <hardwareInterface>EffortJointInterface</hardwareInterface>
      <mechanicalReduction>1</mechanicalReduction>
    </actuator>
  </transmission>
  <!-- Upper leg -->
  <link name="upper1">
    <!--			<visual>-->
    <!--				<origin rpy="0 0 0" xyz="-${upperLegLength/2} ${-left*upperLegWidth} 0"/>-->
    <!--				<geometry>-->
    <!--					<box size="${upperLegLength} ${upperLegWidth} ${upperLegHeight}"/>-->
    <!--				</geometry>-->
    <!--				<material name="silver"/>-->
    <!--			</visual>-->
    <visual>
      <origin rpy="0 0  0" xyz="0 -0.02 0"/>
      <geometry>
        <mesh filename="package://spirit_description/meshes/Spirit40_Upper_leg_transformed.stl" scale="1 1 1"/>
      </geometry>
      <material name="gray"/>
    </visual>
    <collision>
      <origin rpy="0 0 0" xyz="-0.103 -0.022 0"/>
      <geometry>
        <box size="0.206 0.022 0.055"/>
      </geometry>
    </collision>
    <inertial>
      <mass value="0.775"/>
      <inertia ixx="5e-05" ixy="0" ixz="0" iyy="0.001" iyz="0" izz="0.001"/>
    </inertial>
  </link>
  <gazebo reference="upper1">
    <material>Gazebo/Gray</material>
  </gazebo>
  <!-- Hip joint. (Motor to upper leg). Joint names are: 0 2 4 6 -->
  <joint name="2" type="revolute">
    <parent link="hip1"/>
    <child link="upper1"/>
    <axis xyz="0 -1 0"/>
    <origin xyz="0 0.10098 0"/>
    <!--  rpy="0 -0.3 0" -->
    <limit effort="40" lower="-6.28318530718" upper="6.28318530718" velocity="30"/>
    <dynamics damping="0.0" friction="0.0"/>
  </joint>
  <!-- Transmission elements required for Gazebo -->
  <transmission name="transmission_2">
    <type>transmission_interface/SimpleTransmission</type>
    <joint name="2">
      <hardwareInterface>hardware_interface/EffortJointInterface</hardwareInterface>
    </joint>
    <actuator name="motor_2">
      <hardwareInterface>EffortJointInterface</hardwareInterface>
      <mechanicalReduction>1</mechanicalReduction>
    </actuator>
  </transmission>
  <!-- Lower leg -->
  <link name="lower1">
    <!--			<visual>-->
    <!--				<origin rpy="0 ${pi/2} 0" xyz="${lowerLegLength/2} 0 0"/>-->
    <!--				<geometry>-->
    <!--					<cylinder length="${lowerLegLength}" radius="${lowerLegRadius}"/>-->
    <!--				</geometry>-->
    <!--				<material name="darkgray"/>-->
    <!--			</visual>-->
    <visual>
      <origin rpy="0 0  0" xyz="0 0 0"/>
      <geometry>
        <mesh filename="package://spirit_description/meshes/Spirit40_Lower_Leg_transformed.stl" scale="1 1 1"/>
      </geometry>
      <material name="gray"/>
    </visual>
    <collision>
      <origin rpy="0 1.5707963268 0" xyz="0.103 0 0"/>
      <geometry>
        <cylinder length="0.206" radius="0.013"/>
      </geometry>
    </collision>
    <inertial>
      <mass value="0.075"/>
      <inertia ixx="5e-06" ixy="0" ixz="0" iyy="0.0001" iyz="0" izz="0.0001"/>
    </inertial>
  </link>
  <gazebo reference="lower1">
    <material>Gazebo/Black</material>
  </gazebo>
  <!-- Knee joint. Joint names are: 1 3 5 7 -->
  <joint name="3" type="revolute">
    <parent link="upper1"/>
    <child link="lower1"/>
    <axis xyz="0 1 0"/>
    <origin xyz="-0.206 0 0"/>
    <!--rpy="0 0.5 0"-->
    <limit effort="40" lower="0" upper="3.14159265359" velocity="30"/>
    <dynamics damping="0.0" friction="0.0"/>
  </joint>
  <!-- Transmission elements required for Gazebo -->
  <transmission name="transmission_3">
    <type>transmission_interface/SimpleTransmission</type>
    <joint name="3">
      <hardwareInterface>hardware_interface/EffortJointInterface</hardwareInterface>
    </joint>
    <actuator name="motor_3">
      <hardwareInterface>EffortJointInterface</hardwareInterface>
      <mechanicalReduction>1</mechanicalReduction>
    </actuator>
  </transmission>
  <!-- Toe -->
  <link name="toe1">
    <contact>
      <friction_anchor/>
      <stiffness value="30000.0"/>
      <damping value="1000.0"/>
      <spinning_friction value="0.3"/>
      <lateral_friction value="50.0"/>
    </contact>
    <visual>
      <origin rpy="0 0 0" xyz="0 0 0"/>
      <geometry>
        <!--					<sphere radius="${toeRadius}"/>-->
        <sphere radius="0.001"/>
      </geometry>
      <material name="darkgray"/>
    </visual>
    <collision>
      <origin rpy="0 0 0" xyz="0 0 0"/>
      <geometry>
        <sphere radius="0.02"/>
      </geometry>
      <surface>
        <friction>
          <ode>
            <mu>100000</mu>
            <mu2>100000</mu2>
          </ode>
        </friction>
        <contact>
          <ode>
            <kp>30000.0</kp>
            <kd>1000.0</kd>
          </ode>
        </contact>
      </surface>
    </collision>
    <inertial>
      <mass value="0.015"/>
      <inertia ixx="0.000025" ixy="0" ixz="0" iyy="0.000025" iyz="0" izz="0.000025"/>
      <!-- <inertia ixx="2/5*${toeMass}*${toeRadius}*${toeRadius}"  ixy="0"  ixz="0" iyy="2/5*${toeMass}*${toeRadius}*${toeRadius}" iyz="0" izz="2/5*${toeMass}*${toeRadius}*${toeRadius}" /> -->
    </inertial>
  </link>
  <gazebo reference="toe1">
    <material>Gazebo/DarkGray</material>
    <collision>
      <surface>
        <bounce>
          <restitution_coefficient>0</restitution_coefficient>
          <threshold>1e+06</threshold>
        </bounce>
        <friction>
          <torsional>
            <coefficient>0.3</coefficient>
          </torsional>
          <ode>
            <mu>100.0</mu>
            <mu2>50.0</mu2>
          </ode>
          <bullet>
            <rolling_friction>0.3</rolling_friction>
            <friction2>50.0</friction2>
          </bullet>
        </friction>
        <contact>
          <bullet>
            <kp>30000.0</kp>
            <kd>1000.0</kd>
          </bullet>
          <ode>
            <kp>30000.0</kp>
            <kd>1000.0</kd>
          </ode>
        </contact>
      </surface>
    </collision>
  </gazebo>
  <joint name="jtoe1" type="fixed">
    <parent link="lower1"/>
    <child link="toe1"/>
    <origin xyz="0.206 0 -0.0"/>
    <dynamics damping="0.0" friction="0.0"/>
  </joint>
  <!-- Hip motor -->
  <link name="hip2">
    <!--			<visual>-->
    <!--				<origin rpy="${pi/2} 0 0" xyz="${front * 0} ${left * (dPodAxisToEdge)} 0"/>-->
    <!--				<geometry>-->
    <!--					<cylinder length="${podLength}" radius="${podRadius}"/>-->
    <!--				</geometry>-->
    <!--				<material name="${color}"/>-->
    <!--			</visual>-->
    <visual>
      <origin rpy="3.14159265359 0 0" xyz="0.0 0 0.0"/>
      <geometry>
        <mesh filename="package://spirit_description/meshes/Spirit40_Hip_Module_transformed.stl" scale="1 1 1"/>
      </geometry>
      <material name="gray"/>
    </visual>
    <collision>
      <origin rpy="1.5707963268 0 0" xyz="0 -0.028 0"/>
      <geometry>
        <cylinder length="0.08" radius="0.055"/>
      </geometry>
    </collision>
    <inertial>
      <mass value="0.575"/>
      <!-- <inertia ixx="1/12*${podMass}*${podLength}*${podLength} + 1/4*${podMass}*${podRadius}*${podRadius}"  ixy="0"  ixz="0" iyy="1/12*${podMass}*${podLength}*${podLength} + 1/4*${podMass}*${podRadius}*${podRadius}" iyz="0" izz="1/2*${podMass}*${podRadius}*$
				{podRadius}" /> -->
      <inertia ixx="0.00066963541" ixy="0" ixz="0" iyy="0.00066963541" iyz="0" izz="0.0008696875"/>
    </inertial>
  </link>
  <gazebo reference="hip2">
    <material>Gazebo/Gray</material>
  </gazebo>
  <!-- Abduction joint. Joint names are: 8 9 10 11 -->
  <joint name="10" type="revolute">
    <parent link="body"/>
    <child link="hip2"/>
    <axis xyz="1 0 0"/>
    <origin xyz="0.2263 -0.07 0"/>
    <limit effort="40" lower="-0.707" upper="0.707" velocity="30"/>
    <dynamics damping="0.0" friction="0.0"/>
  </joint>
  <!-- Transmission elements required for Gazebo -->
  <transmission name="transmission_10">
    <type>transmission_interface/SimpleTransmission</type>
    <joint name="10">
      <hardwareInterface>hardware_interface/EffortJointInterface</hardwareInterface>
    </joint>
    <actuator name="motor_10">
      <hardwareInterface>EffortJointInterface</hardwareInterface>
      <mechanicalReduction>1</mechanicalReduction>
    </actuator>
  </transmission>
  <!-- Upper leg -->
  <link name="upper2">
    <!--			<visual>-->
    <!--				<origin rpy="0 0 0" xyz="-${upperLegLength/2} ${-left*upperLegWidth} 0"/>-->
    <!--				<geometry>-->
    <!--					<box size="${upperLegLength} ${upperLegWidth} ${upperLegHeight}"/>-->
    <!--				</geometry>-->
    <!--				<material name="silver"/>-->
    <!--			</visual>-->
    <visual>
      <origin rpy="3.14159265359 0  0" xyz="0 0.02 0"/>
      <geometry>
        <mesh filename="package://spirit_description/meshes/Spirit40_Upper_leg_transformed.stl" scale="1 1 1"/>
      </geometry>
      <material name="gray"/>
    </visual>
    <collision>
      <origin rpy="0 0 0" xyz="-0.103 0.022 0"/>
      <geometry>
        <box size="0.206 0.022 0.055"/>
      </geometry>
    </collision>
    <inertial>
      <mass value="0.775"/>
      <inertia ixx="5e-05" ixy="0" ixz="0" iyy="0.001" iyz="0" izz="0.001"/>
    </inertial>
  </link>
  <gazebo reference="upper2">
    <material>Gazebo/Gray</material>
  </gazebo>
  <!-- Hip joint. (Motor to upper leg). Joint names are: 0 2 4 6 -->
  <joint name="4" type="revolute">
    <parent link="hip2"/>
    <child link="upper2"/>
    <axis xyz="0 -1 0"/>
    <origin xyz="0 -0.10098 0"/>
    <!--  rpy="0 -0.3 0" -->
    <limit effort="40" lower="-6.28318530718" upper="6.28318530718" velocity="30"/>
    <dynamics damping="0.0" friction="0.0"/>
  </joint>
  <!-- Transmission elements required for Gazebo -->
  <transmission name="transmission_4">
    <type>transmission_interface/SimpleTransmission</type>
    <joint name="4">
      <hardwareInterface>hardware_interface/EffortJointInterface</hardwareInterface>
    </joint>
    <actuator name="motor_4">
      <hardwareInterface>EffortJointInterface</hardwareInterface>
      <mechanicalReduction>1</mechanicalReduction>
    </actuator>
  </transmission>
  <!-- Lower leg -->
  <link name="lower2">
    <!--			<visual>-->
    <!--				<origin rpy="0 ${pi/2} 0" xyz="${lowerLegLength/2} 0 0"/>-->
    <!--				<geometry>-->
    <!--					<cylinder length="${lowerLegLength}" radius="${lowerLegRadius}"/>-->
    <!--				</geometry>-->
    <!--				<material name="darkgray"/>-->
    <!--			</visual>-->
    <visual>
      <origin rpy="3.14159265359 0  0" xyz="0 0 0"/>
      <geometry>
        <mesh filename="package://spirit_description/meshes/Spirit40_Lower_Leg_transformed.stl" scale="1 1 1"/>
      </geometry>
      <material name="gray"/>
    </visual>
    <collision>
      <origin rpy="0 1.5707963268 0" xyz="0.103 0 0"/>
      <geometry>
        <cylinder length="0.206" radius="0.013"/>
      </geometry>
    </collision>
    <inertial>
      <mass value="0.075"/>
      <inertia ixx="5e-06" ixy="0" ixz="0" iyy="0.0001" iyz="0" izz="0.0001"/>
    </inertial>
  </link>
  <gazebo reference="lower2">
    <material>Gazebo/Black</material>
  </gazebo>
  <!-- Knee joint. Joint names are: 1 3 5 7 -->
  <joint name="5" type="revolute">
    <parent link="upper2"/>
    <child link="lower2"/>
    <axis xyz="0 1 0"/>
    <origin xyz="-0.206 0 0"/>
    <!--rpy="0 0.5 0"-->
    <limit effort="40" lower="0" upper="3.14159265359" velocity="30"/>
    <dynamics damping="0.0" friction="0.0"/>
  </joint>
  <!-- Transmission elements required for Gazebo -->
  <transmission name="transmission_5">
    <type>transmission_interface/SimpleTransmission</type>
    <joint name="5">
      <hardwareInterface>hardware_interface/EffortJointInterface</hardwareInterface>
    </joint>
    <actuator name="motor_5">
      <hardwareInterface>EffortJointInterface</hardwareInterface>
      <mechanicalReduction>1</mechanicalReduction>
    </actuator>
  </transmission>
  <!-- Toe -->
  <link name="toe2">
    <contact>
      <friction_anchor/>
      <stiffness value="30000.0"/>
      <damping value="1000.0"/>
      <spinning_friction value="0.3"/>
      <lateral_friction value="50.0"/>
    </contact>
    <visual>
      <origin rpy="0 0 0" xyz="0 0 0"/>
      <geometry>
        <!--					<sphere radius="${toeRadius}"/>-->
        <sphere radius="0.001"/>
      </geometry>
      <material name="darkgray"/>
    </visual>
    <collision>
      <origin rpy="0 0 0" xyz="0 0 0"/>
      <geometry>
        <sphere radius="0.02"/>
      </geometry>
      <surface>
        <friction>
          <ode>
            <mu>100000</mu>
            <mu2>100000</mu2>
          </ode>
        </friction>
        <contact>
          <ode>
            <kp>30000.0</kp>
            <kd>1000.0</kd>
          </ode>
        </contact>
      </surface>
    </collision>
    <inertial>
      <mass value="0.015"/>
      <inertia ixx="0.000025" ixy="0" ixz="0" iyy="0.000025" iyz="0" izz="0.000025"/>
      <!-- <inertia ixx="2/5*${toeMass}*${toeRadius}*${toeRadius}"  ixy="0"  ixz="0" iyy="2/5*${toeMass}*${toeRadius}*${toeRadius}" iyz="0" izz="2/5*${toeMass}*${toeRadius}*${toeRadius}" /> -->
    </inertial>
  </link>
  <gazebo reference="toe2">
    <material>Gazebo/DarkGray</material>
    <collision>
      <surface>
        <bounce>
          <restitution_coefficient>0</restitution_coefficient>
          <threshold>1e+06</threshold>
        </bounce>
        <friction>
          <torsional>
            <coefficient>0.3</coefficient>
          </torsional>
          <ode>
            <mu>100.0</mu>
            <mu2>50.0</mu2>
          </ode>
          <bullet>
            <rolling_friction>0.3</rolling_friction>
            <friction2>50.0</friction2>
          </bullet>
        </friction>
        <contact>
          <bullet>
            <kp>30000.0</kp>
            <kd>1000.0</kd>
          </bullet>
          <ode>
            <kp>30000.0</kp>
            <kd>1000.0</kd>
          </ode>
        </contact>
      </surface>
    </collision>
  </gazebo>
  <joint name="jtoe2" type="fixed">
    <parent link="lower2"/>
    <child link="toe2"/>
    <origin xyz="0.206 0 -0.0"/>
    <dynamics damping="0.0" friction="0.0"/>
  </joint>
  <!-- Hip motor -->
  <link name="hip3">
    <!--			<visual>-->
    <!--				<origin rpy="${pi/2} 0 0" xyz="${front * 0} ${left * (dPodAxisToEdge)} 0"/>-->
    <!--				<geometry>-->
    <!--					<cylinder length="${podLength}" radius="${podRadius}"/>-->
    <!--				</geometry>-->
    <!--				<material name="${color}"/>-->
    <!--			</visual>-->
    <visual>
      <origin rpy="3.14159265359 3.14159265359 0" xyz="0.0 0.0 0.0"/>
      <geometry>
        <mesh filename="package://spirit_description/meshes/Spirit40_Hip_Module_transformed.stl" scale="1 1 1"/>
      </geometry>
      <material name="gray"/>
    </visual>
    <collision>
      <origin rpy="1.5707963268 0 0" xyz="0 -0.028 0"/>
      <geometry>
        <cylinder length="0.08" radius="0.055"/>
      </geometry>
    </collision>
    <inertial>
      <mass value="0.575"/>
      <!-- <inertia ixx="1/12*${podMass}*${podLength}*${podLength} + 1/4*${podMass}*${podRadius}*${podRadius}"  ixy="0"  ixz="0" iyy="1/12*${podMass}*${podLength}*${podLength} + 1/4*${podMass}*${podRadius}*${podRadius}" iyz="0" izz="1/2*${podMass}*${podRadius}*$
				{podRadius}" /> -->
      <inertia ixx="0.00066963541" ixy="0" ixz="0" iyy="0.00066963541" iyz="0" izz="0.0008696875"/>
    </inertial>
  </link>
  <gazebo reference="hip3">
    <material>Gazebo/Gray</material>
  </gazebo>
  <!-- Abduction joint. Joint names are: 8 9 10 11 -->
  <joint name="11" type="revolute">
    <parent link="body"/>
    <child link="hip3"/>
    <axis xyz="1 0 0"/>
    <origin xyz="-0.2263 -0.07 0"/>
    <limit effort="40" lower="-0.707" upper="0.707" velocity="30"/>
    <dynamics damping="0.0" friction="0.0"/>
  </joint>
  <!-- Transmission elements required for Gazebo -->
  <transmission name="transmission_11">
    <type>transmission_interface/SimpleTransmission</type>
    <joint name="11">
      <hardwareInterface>hardware_interface/EffortJointInterface</hardwareInterface>
    </joint>
    <actuator name="motor_11">
      <hardwareInterface>EffortJointInterface</hardwareInterface>
      <mechanicalReduction>1</mechanicalReduction>
    </actuator>
  </transmission>
  <!-- Upper leg -->
  <link name="upper3">
    <!--			<visual>-->
    <!--				<origin rpy="0 0 0" xyz="-${upperLegLength/2} ${-left*upperLegWidth} 0"/>-->
    <!--				<geometry>-->
    <!--					<box size="${upperLegLength} ${upperLegWidth} ${upperLegHeight}"/>-->
    <!--				</geometry>-->
    <!--				<material name="silver"/>-->
    <!--			</visual>-->
    <visual>
      <origin rpy="3.14159265359 0  0" xyz="0 0.02 0"/>
      <geometry>
        <mesh filename="package://spirit_description/meshes/Spirit40_Upper_leg_transformed.stl" scale="1 1 1"/>
      </geometry>
      <material name="gray"/>
    </visual>
    <collision>
      <origin rpy="0 0 0" xyz="-0.103 0.022 0"/>
      <geometry>
        <box size="0.206 0.022 0.055"/>
      </geometry>
    </collision>
    <inertial>
      <mass value="0.775"/>
      <inertia ixx="5e-05" ixy="0" ixz="0" iyy="0.001" iyz="0" izz="0.001"/>
    </inertial>
  </link>
  <gazebo reference="upper3">
    <material>Gazebo/Gray</material>
  </gazebo>
  <!-- Hip joint. (Motor to upper leg). Joint names are: 0 2 4 6 -->
  <joint name="6" type="revolute">
    <parent link="hip3"/>
    <child link="upper3"/>
    <axis xyz="0 -1 0"/>
    <origin xyz="0 -0.10098 0"/>
    <!--  rpy="0 -0.3 0" -->
    <limit effort="40" lower="-6.28318530718" upper="6.28318530718" velocity="30"/>
    <dynamics damping="0.0" friction="0.0"/>
  </joint>
  <!-- Transmission elements required for Gazebo -->
  <transmission name="transmission_6">
    <type>transmission_interface/SimpleTransmission</type>
    <joint name="6">
      <hardwareInterface>hardware_interface/EffortJointInterface</hardwareInterface>
    </joint>
    <actuator name="motor_6">
      <hardwareInterface>EffortJointInterface</hardwareInterface>
      <mechanicalReduction>1</mechanicalReduction>
    </actuator>
  </transmission>
  <!-- Lower leg -->
  <link name="lower3">
    <!--			<visual>-->
    <!--				<origin rpy="0 ${pi/2} 0" xyz="${lowerLegLength/2} 0 0"/>-->
    <!--				<geometry>-->
    <!--					<cylinder length="${lowerLegLength}" radius="${lowerLegRadius}"/>-->
    <!--				</geometry>-->
    <!--				<material name="darkgray"/>-->
    <!--			</visual>-->
    <visual>
      <origin rpy="3.14159265359 0  0" xyz="0 0 0"/>
      <geometry>
        <mesh filename="package://spirit_description/meshes/Spirit40_Lower_Leg_transformed.stl" scale="1 1 1"/>
      </geometry>
      <material name="gray"/>
    </visual>
    <collision>
      <origin rpy="0 1.5707963268 0" xyz="0.103 0 0"/>
      <geometry>
        <cylinder length="0.206" radius="0.013"/>
      </geometry>
    </collision>
    <inertial>
      <mass value="0.075"/>
      <inertia ixx="5e-06" ixy="0" ixz="0" iyy="0.0001" iyz="0" izz="0.0001"/>
    </inertial>
  </link>
  <gazebo reference="lower3">
    <material>Gazebo/Black</material>
  </gazebo>
  <!-- Knee joint. Joint names are: 1 3 5 7 -->
  <joint name="7" type="revolute">
    <parent link="upper3"/>
    <child link="lower3"/>
    <axis xyz="0 1 0"/>
    <origin xyz="-0.206 0 0"/>
    <!--rpy="0 0.5 0"-->
    <limit effort="40" lower="0" upper="3.14159265359" velocity="30"/>
    <dynamics damping="0.0" friction="0.0"/>
  </joint>
  <!-- Transmission elements required for Gazebo -->
  <transmission name="transmission_7">
    <type>transmission_interface/SimpleTransmission</type>
    <joint name="7">
      <hardwareInterface>hardware_interface/EffortJointInterface</hardwareInterface>
    </joint>
    <actuator name="motor_7">
      <hardwareInterface>EffortJointInterface</hardwareInterface>
      <mechanicalReduction>1</mechanicalReduction>
    </actuator>
  </transmission>
  <!-- Toe -->
  <link name="toe3">
    <contact>
      <friction_anchor/>
      <stiffness value="30000.0"/>
      <damping value="1000.0"/>
      <spinning_friction value="0.3"/>
      <lateral_friction value="50.0"/>
    </contact>
    <visual>
      <origin rpy="0 0 0" xyz="0 0 0"/>
      <geometry>
        <!--					<sphere radius="${toeRadius}"/>-->
        <sphere radius="0.001"/>
      </geometry>
      <material name="darkgray"/>
    </visual>
    <collision>
      <origin rpy="0 0 0" xyz="0 0 0"/>
      <geometry>
        <sphere radius="0.02"/>
      </geometry>
      <surface>
        <friction>
          <ode>
            <mu>100000</mu>
            <mu2>100000</mu2>
          </ode>
        </friction>
        <contact>
          <ode>
            <kp>30000.0</kp>
            <kd>1000.0</kd>
          </ode>
        </contact>
      </surface>
    </collision>
    <inertial>
      <mass value="0.015"/>
      <inertia ixx="0.000025" ixy="0" ixz="0" iyy="0.000025" iyz="0" izz="0.000025"/>
      <!-- <inertia ixx="2/5*${toeMass}*${toeRadius}*${toeRadius}"  ixy="0"  ixz="0" iyy="2/5*${toeMass}*${toeRadius}*${toeRadius}" iyz="0" izz="2/5*${toeMass}*${toeRadius}*${toeRadius}" /> -->
    </inertial>
  </link>
  <gazebo reference="toe3">
    <material>Gazebo/DarkGray</material>
    <collision>
      <surface>
        <bounce>
          <restitution_coefficient>0</restitution_coefficient>
          <threshold>1e+06</threshold>
        </bounce>
        <friction>
          <torsional>
            <coefficient>0.3</coefficient>
          </torsional>
          <ode>
            <mu>100.0</mu>
            <mu2>50.0</mu2>
          </ode>
          <bullet>
            <rolling_friction>0.3</rolling_friction>
            <friction2>50.0</friction2>
          </bullet>
        </friction>
        <contact>
          <bullet>
            <kp>30000.0</kp>
            <kd>1000.0</kd>
          </bullet>
          <ode>
            <kp>30000.0</kp>
            <kd>1000.0</kd>
          </ode>
        </contact>
      </surface>
    </collision>
  </gazebo>
  <joint name="jtoe3" type="fixed">
    <parent link="lower3"/>
    <child link="toe3"/>
    <origin xyz="0.206 0 -0.0"/>
    <dynamics damping="0.0" friction="0.0"/>
  </joint>
</robot>

