<?xml version="1.0" ?>
<!-- =================================================================================== -->
<!-- |    This document was autogenerated by xacro from vision60.urdf.xacro            | -->
<!-- |    EDITING THIS FILE BY HAND IS NOT RECOMMENDED                                 | -->
<!-- =================================================================================== -->
<!--
 * Copyright (C) Ghost Robotics - All Rights Reserved
 * Unauthorized copying of this file, via any medium is strictly prohibited
 * Proprietary and confidential
 * Written by Avik De <avik@ghostrobotics.io> and Tom Jacobs <tom.jacobs@ghostrobotics.io>
-->
<robot name="ngr" xmlns:xacro="http://www.ros.org/wiki/xacro">
  <!-- Define parameters -->
  <!-- Change here v3 or v4 -->
  <!-- body geometric properties xacro:if does not appear to work with this version of xacro.py -->
  <!-- body dynamic properties -->
  <!-- Simulation-specific dynamics properties (mostly guessing) -->
  <!-- Joint limits -->
  <!-- Define materials -->
  <material name="gray">
    <color rgba="0.5 0.5 0.5 1.0"/>
  </material>
  <material name="darkgray">
    <color rgba="0.3 0.3 0.3 1.0"/>
  </material>
  <material name="blue">
    <color rgba="0 0 0.8 1"/>
  </material>
  <material name="black">
    <color rgba="0 0 0 1"/>
  </material>
  <material name="purple">
    <color rgba="0.5 0.0 0.5 1.0"/>
  </material>
  <material name="red">
    <color rgba="0.8 0.0 0.2 1.0"/>
  </material>
  <!-- Body -->
  <link name="body">
    <visual>
      <origin rpy="0 0 0" xyz="0 0 0"/>
      <geometry>
        <box size="0.83 0.25 0.19"/>
      </geometry>
      <material name="gray"/>
    </visual>
    <inertial>
      <mass value="17.9"/>
      <inertia ixx="0.0986" ixy="0" ixz="0" iyy="0.8105" iyz="0" izz="0.8369"/>
    </inertial>
    <!-- Just copy geometry for collision -->
    <collision>
      <origin rpy="0 0 0" xyz="0 0 0"/>
      <geometry>
        <box size="0.83 0.25 0.19"/>
      </geometry>
    </collision>
  </link>
  <gazebo reference="body">
    <material>Gazebo/BlackTransparent</material>
  </gazebo>
  <gazebo reference="body">
    <gravity>true</gravity>
    <sensor name="imu_sensor" type="imu">
      <always_on>true</always_on>
      <update_rate>100</update_rate>
      <visualize>true</visualize>
      <topic>__default_topic_</topic>
      <plugin filename="libgazebo_ros_imu_sensor.so" name="imu_plugin">
        <topicName>imu</topicName>
        <bodyName>body</bodyName>
        <updateRateHZ>100.0</updateRateHZ>
        <gaussianNoise>0.0</gaussianNoise>
        <xyzOffset>0 0 0</xyzOffset>
        <rpyOffset>0 0 0</rpyOffset>
        <frameName>body</frameName>
        <initialOrientationAsReference>false</initialOrientationAsReference>
      </plugin>
      <pose>0 0 0 0 0 0</pose>
    </sensor>
  </gazebo>
  <!-- Define our leg macro -->
  <!-- Our four legs -->
  <!-- Hip motor -->
  <link name="hip0">
    <visual>
      <origin rpy="1.5707963268 0 0" xyz="-0.01 -0.005 0"/>
      <geometry>
        <box size="0.15 0.09 0.15"/>
      </geometry>
      <material name="red"/>
    </visual>
    <collision>
      <origin rpy="1.5707963268 0 0" xyz="-0.01 -0.005 0"/>
      <geometry>
        <box size="0.15 0.09 0.15"/>
      </geometry>
    </collision>
    <inertial>
      <mass value="1.975"/>
      <inertia ixx="0.00891458" ixy="0" ixz="0" iyy="0.0100573" iyz="0" izz="0.01533698"/>
    </inertial>
  </link>
  <gazebo reference="hip0">
    <material>Gazebo/Purple</material>
  </gazebo>
  <!-- Abduction joint. Joint names are: 8 9 10 11 -->
  <joint name="8" type="revolute">
    <parent link="body"/>
    <child link="hip0"/>
    <axis xyz="1 0 0"/>
    <origin xyz="0.34385 0.092865 0"/>
    <limit effort="375" lower="-0.43" upper="0.43" velocity="8.6"/>
    <dynamics damping="0.0" friction="0.0"/>
  </joint>
  <!-- Transmission elements required for Gazebo -->
  <transmission name="transmission_8">
    <type>transmission_interface/SimpleTransmission</type>
    <joint name="8">
      <hardwareInterface>hardware_interface/EffortJointInterface</hardwareInterface>
    </joint>
    <actuator name="motor_8">
      <hardwareInterface>EffortJointInterface</hardwareInterface>
      <mechanicalReduction>1</mechanicalReduction>
    </actuator>
  </transmission>
  <!-- Upper leg -->
  <link name="upper0">
    <visual>
      <origin rpy="0 0 0" xyz="-0.17 0.0 0"/>
      <geometry>
        <box size="0.34 0.055 0.075"/>
      </geometry>
      <material name="blue"/>
    </visual>
    <collision>
      <origin rpy="0 0 0" xyz="-0.17 0.0 0"/>
      <geometry>
        <box size="0.34 0.055 0.075"/>
      </geometry>
    </collision>
    <inertial>
      <mass value="2.525"/>
      <inertia ixx="0.0003125" ixy="0" ixz="0" iyy="0.0040625" iyz="0" izz="0.0040625"/>
    </inertial>
  </link>
  <gazebo reference="upper0">
    <material>Gazebo/Blue</material>
  </gazebo>
  <!-- Hip joint. (Motor to upper leg). Joint names are: 0 2 4 6 -->
  <joint name="0" type="revolute">
    <parent link="hip0"/>
    <child link="upper0"/>
    <axis xyz="0 -1 0"/>
    <origin xyz="0 0.0975 0"/>
    <!--  rpy="0 -0.3 0" -->
    <limit effort="87.5" lower="-6.28318530718" upper="6.28318530718" velocity="30"/>
    <dynamics damping="0.0" friction="0.0"/>
  </joint>
  <!-- Transmission elements required for Gazebo -->
  <transmission name="transmission_0">
    <type>transmission_interface/SimpleTransmission</type>
    <joint name="0">
      <hardwareInterface>hardware_interface/EffortJointInterface</hardwareInterface>
    </joint>
    <actuator name="motor_0">
      <hardwareInterface>EffortJointInterface</hardwareInterface>
      <mechanicalReduction>1</mechanicalReduction>
    </actuator>
  </transmission>
  <!-- Lower leg -->
  <link name="lower0">
    <visual>
      <origin rpy="0 1.5707963268 0" xyz="0.17035 0 0"/>
      <geometry>
        <cylinder length="0.3407" radius="0.02"/>
      </geometry>
      <material name="black"/>
    </visual>
    <collision>
      <origin rpy="0 1.5707963268 0" xyz="0.17035 0 0"/>
      <geometry>
        <cylinder length="0.3407" radius="0.02"/>
      </geometry>
    </collision>
    <inertial>
      <mass value="0.375"/>
      <inertia ixx="0.00131075" ixy="0" ixz="0" iyy="0.00131075" iyz="0" izz="0.0001"/>
    </inertial>
  </link>
  <gazebo reference="lower0">
    <material>Gazebo/Black</material>
  </gazebo>
  <!-- Knee joint. Joint names are: 1 3 5 7 -->
  <joint name="1" type="revolute">
    <parent link="upper0"/>
    <child link="lower0"/>
    <axis xyz="0 1 0"/>
    <origin xyz="-0.34 0 0"/>
    <!--rpy="0 0.5 0"-->
    <limit effort="87.5" lower="0" upper="3.14159265359" velocity="30"/>
    <dynamics damping="0.0" friction="0.0"/>
  </joint>
  <!-- Transmission elements required for Gazebo -->
  <transmission name="transmission_1">
    <type>transmission_interface/SimpleTransmission</type>
    <joint name="1">
      <hardwareInterface>hardware_interface/EffortJointInterface</hardwareInterface>
    </joint>
    <actuator name="motor_1">
      <hardwareInterface>EffortJointInterface</hardwareInterface>
      <mechanicalReduction>1</mechanicalReduction>
    </actuator>
  </transmission>
  <!-- Toe -->
  <link name="toe0">
    <contact>
      <friction_anchor/>
      <stiffness value="30000.0"/>
      <damping value="1000.0"/>
      <spinning_friction value="0.3"/>
      <lateral_friction value="3.0"/>
    </contact>
    <visual>
      <origin rpy="0 0 0" xyz="0 0 0"/>
      <geometry>
        <sphere radius="0.0325"/>
      </geometry>
      <material name="darkgray"/>
    </visual>
    <collision>
      <origin rpy="0 0 0" xyz="0 0 0"/>
      <geometry>
        <sphere radius="0.0325"/>
      </geometry>
    </collision>
    <inertial>
      <mass value="0.15"/>
      <inertia ixx="0.000025" ixy="0" ixz="0" iyy="0.000025" iyz="0" izz="0.000025"/>
    </inertial>
  </link>
  <gazebo reference="toe0">
    <material>Gazebo/DarkGray</material>
    <collision>
      <surface>
        <bounce>
          <restitution_coefficient>0</restitution_coefficient>
          <threshold>1e+06</threshold>
        </bounce>
        <friction>
          <torsional>
            <coefficient>0.3</coefficient>
          </torsional>
          <ode>
            <mu>20.0</mu>
            <mu2>3.0</mu2>
          </ode>
          <bullet>
            <rolling_friction>0.3</rolling_friction>
            <friction2>3.0</friction2>
          </bullet>
        </friction>
        <contact>
          <bullet>
            <kp>30000.0</kp>
            <kd>1000.0</kd>
          </bullet>
          <ode>
            <kp>30000.0</kp>
            <kd>1000.0</kd>
          </ode>
        </contact>
      </surface>
    </collision>
  </gazebo>
  <joint name="jtoe0" type="fixed">
    <parent link="lower0"/>
    <child link="toe0"/>
    <origin xyz="0.3407 0 -0.0"/>
    <dynamics damping="0.0" friction="0.0"/>
  </joint>
  <!-- Hip motor -->
  <link name="hip1">
    <visual>
      <origin rpy="1.5707963268 0 0" xyz="0.01 -0.005 0"/>
      <geometry>
        <box size="0.15 0.09 0.15"/>
      </geometry>
      <material name="purple"/>
    </visual>
    <collision>
      <origin rpy="1.5707963268 0 0" xyz="0.01 -0.005 0"/>
      <geometry>
        <box size="0.15 0.09 0.15"/>
      </geometry>
    </collision>
    <inertial>
      <mass value="1.975"/>
      <inertia ixx="0.00891458" ixy="0" ixz="0" iyy="0.0100573" iyz="0" izz="0.01533698"/>
    </inertial>
  </link>
  <gazebo reference="hip1">
    <material>Gazebo/Purple</material>
  </gazebo>
  <!-- Abduction joint. Joint names are: 8 9 10 11 -->
  <joint name="9" type="revolute">
    <parent link="body"/>
    <child link="hip1"/>
    <axis xyz="1 0 0"/>
    <origin xyz="-0.34385 0.092865 0"/>
    <limit effort="375" lower="-0.43" upper="0.43" velocity="8.6"/>
    <dynamics damping="0.0" friction="0.0"/>
  </joint>
  <!-- Transmission elements required for Gazebo -->
  <transmission name="transmission_9">
    <type>transmission_interface/SimpleTransmission</type>
    <joint name="9">
      <hardwareInterface>hardware_interface/EffortJointInterface</hardwareInterface>
    </joint>
    <actuator name="motor_9">
      <hardwareInterface>EffortJointInterface</hardwareInterface>
      <mechanicalReduction>1</mechanicalReduction>
    </actuator>
  </transmission>
  <!-- Upper leg -->
  <link name="upper1">
    <visual>
      <origin rpy="0 0 0" xyz="-0.17 0.0 0"/>
      <geometry>
        <box size="0.34 0.055 0.075"/>
      </geometry>
      <material name="blue"/>
    </visual>
    <collision>
      <origin rpy="0 0 0" xyz="-0.17 0.0 0"/>
      <geometry>
        <box size="0.34 0.055 0.075"/>
      </geometry>
    </collision>
    <inertial>
      <mass value="2.525"/>
      <inertia ixx="0.0003125" ixy="0" ixz="0" iyy="0.0040625" iyz="0" izz="0.0040625"/>
    </inertial>
  </link>
  <gazebo reference="upper1">
    <material>Gazebo/Blue</material>
  </gazebo>
  <!-- Hip joint. (Motor to upper leg). Joint names are: 0 2 4 6 -->
  <joint name="2" type="revolute">
    <parent link="hip1"/>
    <child link="upper1"/>
    <axis xyz="0 -1 0"/>
    <origin xyz="0 0.0975 0"/>
    <!--  rpy="0 -0.3 0" -->
    <limit effort="87.5" lower="-6.28318530718" upper="6.28318530718" velocity="30"/>
    <dynamics damping="0.0" friction="0.0"/>
  </joint>
  <!-- Transmission elements required for Gazebo -->
  <transmission name="transmission_2">
    <type>transmission_interface/SimpleTransmission</type>
    <joint name="2">
      <hardwareInterface>hardware_interface/EffortJointInterface</hardwareInterface>
    </joint>
    <actuator name="motor_2">
      <hardwareInterface>EffortJointInterface</hardwareInterface>
      <mechanicalReduction>1</mechanicalReduction>
    </actuator>
  </transmission>
  <!-- Lower leg -->
  <link name="lower1">
    <visual>
      <origin rpy="0 1.5707963268 0" xyz="0.17035 0 0"/>
      <geometry>
        <cylinder length="0.3407" radius="0.02"/>
      </geometry>
      <material name="black"/>
    </visual>
    <collision>
      <origin rpy="0 1.5707963268 0" xyz="0.17035 0 0"/>
      <geometry>
        <cylinder length="0.3407" radius="0.02"/>
      </geometry>
    </collision>
    <inertial>
      <mass value="0.375"/>
      <inertia ixx="0.00131075" ixy="0" ixz="0" iyy="0.00131075" iyz="0" izz="0.0001"/>
    </inertial>
  </link>
  <gazebo reference="lower1">
    <material>Gazebo/Black</material>
  </gazebo>
  <!-- Knee joint. Joint names are: 1 3 5 7 -->
  <joint name="3" type="revolute">
    <parent link="upper1"/>
    <child link="lower1"/>
    <axis xyz="0 1 0"/>
    <origin xyz="-0.34 0 0"/>
    <!--rpy="0 0.5 0"-->
    <limit effort="87.5" lower="0" upper="3.14159265359" velocity="30"/>
    <dynamics damping="0.0" friction="0.0"/>
  </joint>
  <!-- Transmission elements required for Gazebo -->
  <transmission name="transmission_3">
    <type>transmission_interface/SimpleTransmission</type>
    <joint name="3">
      <hardwareInterface>hardware_interface/EffortJointInterface</hardwareInterface>
    </joint>
    <actuator name="motor_3">
      <hardwareInterface>EffortJointInterface</hardwareInterface>
      <mechanicalReduction>1</mechanicalReduction>
    </actuator>
  </transmission>
  <!-- Toe -->
  <link name="toe1">
    <contact>
      <friction_anchor/>
      <stiffness value="30000.0"/>
      <damping value="1000.0"/>
      <spinning_friction value="0.3"/>
      <lateral_friction value="3.0"/>
    </contact>
    <visual>
      <origin rpy="0 0 0" xyz="0 0 0"/>
      <geometry>
        <sphere radius="0.0325"/>
      </geometry>
      <material name="darkgray"/>
    </visual>
    <collision>
      <origin rpy="0 0 0" xyz="0 0 0"/>
      <geometry>
        <sphere radius="0.0325"/>
      </geometry>
    </collision>
    <inertial>
      <mass value="0.15"/>
      <inertia ixx="0.000025" ixy="0" ixz="0" iyy="0.000025" iyz="0" izz="0.000025"/>
    </inertial>
  </link>
  <gazebo reference="toe1">
    <material>Gazebo/DarkGray</material>
    <collision>
      <surface>
        <bounce>
          <restitution_coefficient>0</restitution_coefficient>
          <threshold>1e+06</threshold>
        </bounce>
        <friction>
          <torsional>
            <coefficient>0.3</coefficient>
          </torsional>
          <ode>
            <mu>20.0</mu>
            <mu2>3.0</mu2>
          </ode>
          <bullet>
            <rolling_friction>0.3</rolling_friction>
            <friction2>3.0</friction2>
          </bullet>
        </friction>
        <contact>
          <bullet>
            <kp>30000.0</kp>
            <kd>1000.0</kd>
          </bullet>
          <ode>
            <kp>30000.0</kp>
            <kd>1000.0</kd>
          </ode>
        </contact>
      </surface>
    </collision>
  </gazebo>
  <joint name="jtoe1" type="fixed">
    <parent link="lower1"/>
    <child link="toe1"/>
    <origin xyz="0.3407 0 -0.0"/>
    <dynamics damping="0.0" friction="0.0"/>
  </joint>
  <!-- Hip motor -->
  <link name="hip2">
    <visual>
      <origin rpy="1.5707963268 0 0" xyz="-0.01 0.005 0"/>
      <geometry>
        <box size="0.15 0.09 0.15"/>
      </geometry>
      <material name="purple"/>
    </visual>
    <collision>
      <origin rpy="1.5707963268 0 0" xyz="-0.01 0.005 0"/>
      <geometry>
        <box size="0.15 0.09 0.15"/>
      </geometry>
    </collision>
    <inertial>
      <mass value="1.975"/>
      <inertia ixx="0.00891458" ixy="0" ixz="0" iyy="0.0100573" iyz="0" izz="0.01533698"/>
    </inertial>
  </link>
  <gazebo reference="hip2">
    <material>Gazebo/Purple</material>
  </gazebo>
  <!-- Abduction joint. Joint names are: 8 9 10 11 -->
  <joint name="10" type="revolute">
    <parent link="body"/>
    <child link="hip2"/>
    <axis xyz="1 0 0"/>
    <origin xyz="0.34385 -0.092865 0"/>
    <limit effort="375" lower="-0.43" upper="0.43" velocity="8.6"/>
    <dynamics damping="0.0" friction="0.0"/>
  </joint>
  <!-- Transmission elements required for Gazebo -->
  <transmission name="transmission_10">
    <type>transmission_interface/SimpleTransmission</type>
    <joint name="10">
      <hardwareInterface>hardware_interface/EffortJointInterface</hardwareInterface>
    </joint>
    <actuator name="motor_10">
      <hardwareInterface>EffortJointInterface</hardwareInterface>
      <mechanicalReduction>1</mechanicalReduction>
    </actuator>
  </transmission>
  <!-- Upper leg -->
  <link name="upper2">
    <visual>
      <origin rpy="0 0 0" xyz="-0.17 -0.0 0"/>
      <geometry>
        <box size="0.34 0.055 0.075"/>
      </geometry>
      <material name="blue"/>
    </visual>
    <collision>
      <origin rpy="0 0 0" xyz="-0.17 -0.0 0"/>
      <geometry>
        <box size="0.34 0.055 0.075"/>
      </geometry>
    </collision>
    <inertial>
      <mass value="2.525"/>
      <inertia ixx="0.0003125" ixy="0" ixz="0" iyy="0.0040625" iyz="0" izz="0.0040625"/>
    </inertial>
  </link>
  <gazebo reference="upper2">
    <material>Gazebo/Blue</material>
  </gazebo>
  <!-- Hip joint. (Motor to upper leg). Joint names are: 0 2 4 6 -->
  <joint name="4" type="revolute">
    <parent link="hip2"/>
    <child link="upper2"/>
    <axis xyz="0 -1 0"/>
    <origin xyz="0 -0.0975 0"/>
    <!--  rpy="0 -0.3 0" -->
    <limit effort="87.5" lower="-6.28318530718" upper="6.28318530718" velocity="30"/>
    <dynamics damping="0.0" friction="0.0"/>
  </joint>
  <!-- Transmission elements required for Gazebo -->
  <transmission name="transmission_4">
    <type>transmission_interface/SimpleTransmission</type>
    <joint name="4">
      <hardwareInterface>hardware_interface/EffortJointInterface</hardwareInterface>
    </joint>
    <actuator name="motor_4">
      <hardwareInterface>EffortJointInterface</hardwareInterface>
      <mechanicalReduction>1</mechanicalReduction>
    </actuator>
  </transmission>
  <!-- Lower leg -->
  <link name="lower2">
    <visual>
      <origin rpy="0 1.5707963268 0" xyz="0.17035 0 0"/>
      <geometry>
        <cylinder length="0.3407" radius="0.02"/>
      </geometry>
      <material name="black"/>
    </visual>
    <collision>
      <origin rpy="0 1.5707963268 0" xyz="0.17035 0 0"/>
      <geometry>
        <cylinder length="0.3407" radius="0.02"/>
      </geometry>
    </collision>
    <inertial>
      <mass value="0.375"/>
      <inertia ixx="0.00131075" ixy="0" ixz="0" iyy="0.00131075" iyz="0" izz="0.0001"/>
    </inertial>
  </link>
  <gazebo reference="lower2">
    <material>Gazebo/Black</material>
  </gazebo>
  <!-- Knee joint. Joint names are: 1 3 5 7 -->
  <joint name="5" type="revolute">
    <parent link="upper2"/>
    <child link="lower2"/>
    <axis xyz="0 1 0"/>
    <origin xyz="-0.34 0 0"/>
    <!--rpy="0 0.5 0"-->
    <limit effort="87.5" lower="0" upper="3.14159265359" velocity="30"/>
    <dynamics damping="0.0" friction="0.0"/>
  </joint>
  <!-- Transmission elements required for Gazebo -->
  <transmission name="transmission_5">
    <type>transmission_interface/SimpleTransmission</type>
    <joint name="5">
      <hardwareInterface>hardware_interface/EffortJointInterface</hardwareInterface>
    </joint>
    <actuator name="motor_5">
      <hardwareInterface>EffortJointInterface</hardwareInterface>
      <mechanicalReduction>1</mechanicalReduction>
    </actuator>
  </transmission>
  <!-- Toe -->
  <link name="toe2">
    <contact>
      <friction_anchor/>
      <stiffness value="30000.0"/>
      <damping value="1000.0"/>
      <spinning_friction value="0.3"/>
      <lateral_friction value="3.0"/>
    </contact>
    <visual>
      <origin rpy="0 0 0" xyz="0 0 0"/>
      <geometry>
        <sphere radius="0.0325"/>
      </geometry>
      <material name="darkgray"/>
    </visual>
    <collision>
      <origin rpy="0 0 0" xyz="0 0 0"/>
      <geometry>
        <sphere radius="0.0325"/>
      </geometry>
    </collision>
    <inertial>
      <mass value="0.15"/>
      <inertia ixx="0.000025" ixy="0" ixz="0" iyy="0.000025" iyz="0" izz="0.000025"/>
    </inertial>
  </link>
  <gazebo reference="toe2">
    <material>Gazebo/DarkGray</material>
    <collision>
      <surface>
        <bounce>
          <restitution_coefficient>0</restitution_coefficient>
          <threshold>1e+06</threshold>
        </bounce>
        <friction>
          <torsional>
            <coefficient>0.3</coefficient>
          </torsional>
          <ode>
            <mu>20.0</mu>
            <mu2>3.0</mu2>
          </ode>
          <bullet>
            <rolling_friction>0.3</rolling_friction>
            <friction2>3.0</friction2>
          </bullet>
        </friction>
        <contact>
          <bullet>
            <kp>30000.0</kp>
            <kd>1000.0</kd>
          </bullet>
          <ode>
            <kp>30000.0</kp>
            <kd>1000.0</kd>
          </ode>
        </contact>
      </surface>
    </collision>
  </gazebo>
  <joint name="jtoe2" type="fixed">
    <parent link="lower2"/>
    <child link="toe2"/>
    <origin xyz="0.3407 0 -0.0"/>
    <dynamics damping="0.0" friction="0.0"/>
  </joint>
  <!-- Hip motor -->
  <link name="hip3">
    <visual>
      <origin rpy="1.5707963268 0 0" xyz="0.01 0.005 0"/>
      <geometry>
        <box size="0.15 0.09 0.15"/>
      </geometry>
      <material name="purple"/>
    </visual>
    <collision>
      <origin rpy="1.5707963268 0 0" xyz="0.01 0.005 0"/>
      <geometry>
        <box size="0.15 0.09 0.15"/>
      </geometry>
    </collision>
    <inertial>
      <mass value="1.975"/>
      <inertia ixx="0.00891458" ixy="0" ixz="0" iyy="0.0100573" iyz="0" izz="0.01533698"/>
    </inertial>
  </link>
  <gazebo reference="hip3">
    <material>Gazebo/Purple</material>
  </gazebo>
  <!-- Abduction joint. Joint names are: 8 9 10 11 -->
  <joint name="11" type="revolute">
    <parent link="body"/>
    <child link="hip3"/>
    <axis xyz="1 0 0"/>
    <origin xyz="-0.34385 -0.092865 0"/>
    <limit effort="375" lower="-0.43" upper="0.43" velocity="8.6"/>
    <dynamics damping="0.0" friction="0.0"/>
  </joint>
  <!-- Transmission elements required for Gazebo -->
  <transmission name="transmission_11">
    <type>transmission_interface/SimpleTransmission</type>
    <joint name="11">
      <hardwareInterface>hardware_interface/EffortJointInterface</hardwareInterface>
    </joint>
    <actuator name="motor_11">
      <hardwareInterface>EffortJointInterface</hardwareInterface>
      <mechanicalReduction>1</mechanicalReduction>
    </actuator>
  </transmission>
  <!-- Upper leg -->
  <link name="upper3">
    <visual>
      <origin rpy="0 0 0" xyz="-0.17 -0.0 0"/>
      <geometry>
        <box size="0.34 0.055 0.075"/>
      </geometry>
      <material name="blue"/>
    </visual>
    <collision>
      <origin rpy="0 0 0" xyz="-0.17 -0.0 0"/>
      <geometry>
        <box size="0.34 0.055 0.075"/>
      </geometry>
    </collision>
    <inertial>
      <mass value="2.525"/>
      <inertia ixx="0.0003125" ixy="0" ixz="0" iyy="0.0040625" iyz="0" izz="0.0040625"/>
    </inertial>
  </link>
  <gazebo reference="upper3">
    <material>Gazebo/Blue</material>
  </gazebo>
  <!-- Hip joint. (Motor to upper leg). Joint names are: 0 2 4 6 -->
  <joint name="6" type="revolute">
    <parent link="hip3"/>
    <child link="upper3"/>
    <axis xyz="0 -1 0"/>
    <origin xyz="0 -0.0975 0"/>
    <!--  rpy="0 -0.3 0" -->
    <limit effort="87.5" lower="-6.28318530718" upper="6.28318530718" velocity="30"/>
    <dynamics damping="0.0" friction="0.0"/>
  </joint>
  <!-- Transmission elements required for Gazebo -->
  <transmission name="transmission_6">
    <type>transmission_interface/SimpleTransmission</type>
    <joint name="6">
      <hardwareInterface>hardware_interface/EffortJointInterface</hardwareInterface>
    </joint>
    <actuator name="motor_6">
      <hardwareInterface>EffortJointInterface</hardwareInterface>
      <mechanicalReduction>1</mechanicalReduction>
    </actuator>
  </transmission>
  <!-- Lower leg -->
  <link name="lower3">
    <visual>
      <origin rpy="0 1.5707963268 0" xyz="0.17035 0 0"/>
      <geometry>
        <cylinder length="0.3407" radius="0.02"/>
      </geometry>
      <material name="black"/>
    </visual>
    <collision>
      <origin rpy="0 1.5707963268 0" xyz="0.17035 0 0"/>
      <geometry>
        <cylinder length="0.3407" radius="0.02"/>
      </geometry>
    </collision>
    <inertial>
      <mass value="0.375"/>
      <inertia ixx="0.00131075" ixy="0" ixz="0" iyy="0.00131075" iyz="0" izz="0.0001"/>
    </inertial>
  </link>
  <gazebo reference="lower3">
    <material>Gazebo/Black</material>
  </gazebo>
  <!-- Knee joint. Joint names are: 1 3 5 7 -->
  <joint name="7" type="revolute">
    <parent link="upper3"/>
    <child link="lower3"/>
    <axis xyz="0 1 0"/>
    <origin xyz="-0.34 0 0"/>
    <!--rpy="0 0.5 0"-->
    <limit effort="87.5" lower="0" upper="3.14159265359" velocity="30"/>
    <dynamics damping="0.0" friction="0.0"/>
  </joint>
  <!-- Transmission elements required for Gazebo -->
  <transmission name="transmission_7">
    <type>transmission_interface/SimpleTransmission</type>
    <joint name="7">
      <hardwareInterface>hardware_interface/EffortJointInterface</hardwareInterface>
    </joint>
    <actuator name="motor_7">
      <hardwareInterface>EffortJointInterface</hardwareInterface>
      <mechanicalReduction>1</mechanicalReduction>
    </actuator>
  </transmission>
  <!-- Toe -->
  <link name="toe3">
    <contact>
      <friction_anchor/>
      <stiffness value="30000.0"/>
      <damping value="1000.0"/>
      <spinning_friction value="0.3"/>
      <lateral_friction value="3.0"/>
    </contact>
    <visual>
      <origin rpy="0 0 0" xyz="0 0 0"/>
      <geometry>
        <sphere radius="0.0325"/>
      </geometry>
      <material name="darkgray"/>
    </visual>
    <collision>
      <origin rpy="0 0 0" xyz="0 0 0"/>
      <geometry>
        <sphere radius="0.0325"/>
      </geometry>
    </collision>
    <inertial>
      <mass value="0.15"/>
      <inertia ixx="0.000025" ixy="0" ixz="0" iyy="0.000025" iyz="0" izz="0.000025"/>
    </inertial>
  </link>
  <gazebo reference="toe3">
    <material>Gazebo/DarkGray</material>
    <collision>
      <surface>
        <bounce>
          <restitution_coefficient>0</restitution_coefficient>
          <threshold>1e+06</threshold>
        </bounce>
        <friction>
          <torsional>
            <coefficient>0.3</coefficient>
          </torsional>
          <ode>
            <mu>20.0</mu>
            <mu2>3.0</mu2>
          </ode>
          <bullet>
            <rolling_friction>0.3</rolling_friction>
            <friction2>3.0</friction2>
          </bullet>
        </friction>
        <contact>
          <bullet>
            <kp>30000.0</kp>
            <kd>1000.0</kd>
          </bullet>
          <ode>
            <kp>30000.0</kp>
            <kd>1000.0</kd>
          </ode>
        </contact>
      </surface>
    </collision>
  </gazebo>
  <joint name="jtoe3" type="fixed">
    <parent link="lower3"/>
    <child link="toe3"/>
    <origin xyz="0.3407 0 -0.0"/>
    <dynamics damping="0.0" friction="0.0"/>
  </joint>
  <!-- Add ros_control plugin -->
  <gazebo>
    <plugin filename="libgazebo_ros_control.so" name="gazebo_ros_control">
      <robotNamespace>/vision60</robotNamespace>
    </plugin>
  </gazebo>
</robot>
