<?xml version="1.0"?>
<!--
Description of the caster module for the Innok Heros mobile platform.
Software License Agreement (BSD)
\authors Jonathan Hechtbauer
\maintainer Sabrina Heerklotz <sh@innok-robotics.de>
\copyright Copyright (c) 2015, Innok Robotics GmbH, All rights reserved
Redistribution and use in source and binary forms, with or without modification, are permitted provided that the following conditions are met:
1. Redistributions of source code must retain the above copyright notice, this list of conditions and the following disclaimer.
2. Redistributions in binary form must reproduce the above copyright notice, this list of conditions and the following disclaimer in the documentation and/or other materials provided with the distribution.
THIS SOFTWARE IS PROVIDED BY THE COPYRIGHT HOLDERS AND CONTRIBUTORS "AS IS" AND ANY EXPRESS OR IMPLIED WARRANTIES, INCLUDING, BUT NOT LIMITED TO, THE IMPLIED WARRANTIES OF MERCHANTABILITY AND FITNESS FOR A PARTICULAR PURPOSE ARE DISCLAIMED. IN NO EVENT SHALL THE COPYRIGHT HOLDER OR CONTRIBUTORS BE LIABLE FOR ANY DIRECT, INDIRECT, INCIDENTAL, SPECIAL, EXEMPLARY, OR CONSEQUENTIAL DAMAGES (INCLUDING, BUT NOT LIMITED TO, PROCUREMENT OF SUBSTITUTE GOODS OR SERVICES; LOSS OF USE, DATA, OR PROFITS; OR BUSINESS INTERRUPTION) HOWEVER CAUSED AND ON ANY THEORY OF LIABILITY, WHETHER IN CONTRACT, STRICT LIABILITY, OR TORT (INCLUDING NEGLIGENCE OR OTHERWISE) ARISING IN ANY WAY OUT OF THE USE OF THIS SOFTWARE, EVEN IF ADVISED OF THE POSSIBILITY OF SUCH DAMAGE.
-->

<robot xmlns:xacro="http://ros.org/wiki/xacro" name="caster_cart">		

  <link name="caster_top">
    <inertial>
      <origin xyz="-0.0092 0 -0.0248" rpy="0 0 0" />
      <mass value="0.1" />
      <inertia ixx="8.2e-4" ixy="0" ixz="0" iyy="8.2e-4" iyz="0" izz="5.1e-4" />
    </inertial>
    <visual>
      <origin xyz="0 0 0" rpy="0 0 0" />
      <geometry>
        <mesh filename="model://caster_cart/meshes/caster_top.STL" scale="0.4 0.4 0.4"/>
      </geometry>
      <material name="white">
        <color rgba="1 1 1 1"/>
      </material>
    </visual>
    <collision>
      <origin xyz="0 0 -0.02" rpy="0 0 0" />
      <geometry>
        <cylinder radius="0.028" length="0.036" />
      </geometry>
    </collision>
  </link>


  <link name="caster_wheel">
    <inertial>
      <origin xyz="0 0 0" rpy="0 0 0" />
      <mass value="0.05" />
      <inertia  ixx="1.7e-4" ixy="0" ixz="0" iyy="3e-4" iyz="0" izz="1.7e-4" />
    </inertial>
    <visual>
      <origin xyz="0 0 0" rpy="0 0 0" />
      <geometry>
        <mesh filename="model://caster_cart/meshes/caster_wheel.STL" scale="0.4 0.4 0.4"/>
      </geometry>
      <material name="">
        <color rgba="0.25 0.25 0.25 1" />
      </material>
    </visual>
    <collision>
      <origin xyz="0 0 0 " rpy="-1.57 0 0" />
      <geometry>
        <cylinder radius="0.05" length="0.034" />
      </geometry>
    </collision>
  </link>

  <gazebo reference="caster_wheel">
    <collision>
      <max_contacts>1000</max_contacts>
      <surface>
        <friction>
          <torsional>
            <coefficient>0.1</coefficient>
            <patch_radius>0.001</patch_radius>
            <use_patch_radius>1</use_patch_radius>
            <ode>
              <slip>0.1</slip>
            </ode>
          </torsional>
          <ode>
            <mu>10</mu>
            <mu2>10</mu2>
          </ode>
        </friction>
        <contact>
          <ode>
            <min_depth>0.005</min_depth>
          </ode>
        </contact>
      </surface>
    </collision>
    <material>Gazebo/Grey</material>
  </gazebo> 

  <joint name="caster_wheel_joint" type="continuous">
    <origin xyz="-0.032 -0.0056 -0.068" rpy="0 0 0.003" />
    <parent link="caster_top" />
    <child link="caster_wheel" />
    <axis xyz="0 1 0"/>
    <dynamics damping="0.02"/>
  </joint>


</robot>
